2025-04-28 11:46:35,522 - ERROR - \U0001f6a8 Failed to load URLs: [Errno 2] No such file or directory: 'urls.txt'
Traceback (most recent call last):
  File "C:\Users\derek\Dropbox (Personal)\Cars\Price Puller Used Cars\Price_Puller.py", line 21, in load_urls
    with open(file_path, 'r') as f:
FileNotFoundError: [Errno 2] No such file or directory: 'urls.txt'
2025-04-28 11:46:35,522 - ERROR - \U0001f6a8 No URLs to process. Exiting.
2025-04-28 11:47:25,267 - ERROR - \U0001f6a8 Failed to load URLs: [Errno 2] No such file or directory: 'urls.txt'
Traceback (most recent call last):
  File "C:\Users\derek\Dropbox (Personal)\Cars\Price Puller Used Cars\Price_Puller.py", line 21, in load_urls
    with open(file_path, 'r') as f:
FileNotFoundError: [Errno 2] No such file or directory: 'urls.txt'
2025-04-28 11:47:25,267 - ERROR - \U0001f6a8 No URLs to process. Exiting.
2025-04-28 11:47:28,626 - ERROR - \U0001f6a8 Failed to load URLs: [Errno 2] No such file or directory: 'urls.txt'
Traceback (most recent call last):
  File "C:\Users\derek\Dropbox (Personal)\Cars\Price Puller Used Cars\Price_Puller.py", line 21, in load_urls
    with open(file_path, 'r') as f:
FileNotFoundError: [Errno 2] No such file or directory: 'urls.txt'
2025-04-28 11:47:28,626 - ERROR - \U0001f6a8 No URLs to process. Exiting.
2025-04-28 11:47:57,052 - INFO - \u2705 Loaded 36 URLs from car_urls.txt
2025-04-28 11:47:57,053 - ERROR - \U0001f6a8 Error processing R8: No connection adapters were found for "'https://www.autotrader.com/rest/lsc/crawl/modelyears?searchRadius=0&sortBy=derivedpriceASC&zip=32216&allListingType=all-cars&vehicleStyleCode=COUPE&engineCode=10CLDR&makeCode=AUDI&modelCode=R8&city=Jacksonville&state=FL&location=%5Bobject+Object%5D&dma=%5Bobject+Object%5D'"
Traceback (most recent call last):
  File "C:\Users\derek\Dropbox (Personal)\Cars\Price Puller Used Cars\Price_Puller.py", line 47, in get_avg_price
    response = session.get(url, headers=headers)
  File "C:\Users\derek\AppData\Local\Programs\Python\Python39\lib\site-packages\requests\sessions.py", line 555, in get
    return self.request('GET', url, **kwargs)
  File "C:\Users\derek\AppData\Local\Programs\Python\Python39\lib\site-packages\requests\sessions.py", line 542, in request
    resp = self.send(prep, **send_kwargs)
  File "C:\Users\derek\AppData\Local\Programs\Python\Python39\lib\site-packages\requests\sessions.py", line 649, in send
    adapter = self.get_adapter(url=request.url)
  File "C:\Users\derek\AppData\Local\Programs\Python\Python39\lib\site-packages\requests\sessions.py", line 742, in get_adapter
    raise InvalidSchema("No connection adapters were found for {!r}".format(url))
requests.exceptions.InvalidSchema: No connection adapters were found for "'https://www.autotrader.com/rest/lsc/crawl/modelyears?searchRadius=0&sortBy=derivedpriceASC&zip=32216&allListingType=all-cars&vehicleStyleCode=COUPE&engineCode=10CLDR&makeCode=AUDI&modelCode=R8&city=Jacksonville&state=FL&location=%5Bobject+Object%5D&dma=%5Bobject+Object%5D'"
2025-04-28 11:47:57,064 - ERROR - \U0001f6a8 Error processing RS4: No connection adapters were found for "'https://www.autotrader.com/rest/lsc/crawl/modelyears?marketExtension=include&numRecords=24&searchRadius=0&showAccelerateBanner=false&sortBy=derivedpriceASC&zip=32216&allListingType=all-cars&makeCode=AUDI&modelCode=RS4&city=Jacksonville&state=FL&location=%5Bobject+Object%5D&dma=%5Bobject+Object%5D'"
Traceback (most recent call last):
  File "C:\Users\derek\Dropbox (Personal)\Cars\Price Puller Used Cars\Price_Puller.py", line 47, in get_avg_price
    response = session.get(url, headers=headers)
  File "C:\Users\derek\AppData\Local\Programs\Python\Python39\lib\site-packages\requests\sessions.py", line 555, in get
    return self.request('GET', url, **kwargs)
  File "C:\Users\derek\AppData\Local\Programs\Python\Python39\lib\site-packages\requests\sessions.py", line 542, in request
    resp = self.send(prep, **send_kwargs)
  File "C:\Users\derek\AppData\Local\Programs\Python\Python39\lib\site-packages\requests\sessions.py", line 649, in send
    adapter = self.get_adapter(url=request.url)
  File "C:\Users\derek\AppData\Local\Programs\Python\Python39\lib\site-packages\requests\sessions.py", line 742, in get_adapter
    raise InvalidSchema("No connection adapters were found for {!r}".format(url))
requests.exceptions.InvalidSchema: No connection adapters were found for "'https://www.autotrader.com/rest/lsc/crawl/modelyears?marketExtension=include&numRecords=24&searchRadius=0&showAccelerateBanner=false&sortBy=derivedpriceASC&zip=32216&allListingType=all-cars&makeCode=AUDI&modelCode=RS4&city=Jacksonville&state=FL&location=%5Bobject+Object%5D&dma=%5Bobject+Object%5D'"
2025-04-28 11:47:57,064 - ERROR - \U0001f6a8 Error processing S4: No connection adapters were found for "'https://www.autotrader.com/rest/lsc/crawl/modelyears?marketExtension=include&numRecords=24&searchRadius=500&showAccelerateBanner=false&sortBy=derivedpriceASC&startYear=2013&zip=32216&allListingType=all-cars&makeCode=AUDI&modelCode=S4&city=Jacksonville&state=FL&location=%5Bobject+Object%5D&dma=%5Bobject+Object%5D'"
Traceback (most recent call last):
  File "C:\Users\derek\Dropbox (Personal)\Cars\Price Puller Used Cars\Price_Puller.py", line 47, in get_avg_price
    response = session.get(url, headers=headers)
  File "C:\Users\derek\AppData\Local\Programs\Python\Python39\lib\site-packages\requests\sessions.py", line 555, in get
    return self.request('GET', url, **kwargs)
  File "C:\Users\derek\AppData\Local\Programs\Python\Python39\lib\site-packages\requests\sessions.py", line 542, in request
    resp = self.send(prep, **send_kwargs)
  File "C:\Users\derek\AppData\Local\Programs\Python\Python39\lib\site-packages\requests\sessions.py", line 649, in send
    adapter = self.get_adapter(url=request.url)
  File "C:\Users\derek\AppData\Local\Programs\Python\Python39\lib\site-packages\requests\sessions.py", line 742, in get_adapter
    raise InvalidSchema("No connection adapters were found for {!r}".format(url))
requests.exceptions.InvalidSchema: No connection adapters were found for "'https://www.autotrader.com/rest/lsc/crawl/modelyears?marketExtension=include&numRecords=24&searchRadius=500&showAccelerateBanner=false&sortBy=derivedpriceASC&startYear=2013&zip=32216&allListingType=all-cars&makeCode=AUDI&modelCode=S4&city=Jacksonville&state=FL&location=%5Bobject+Object%5D&dma=%5Bobject+Object%5D'"
2025-04-28 11:47:57,065 - ERROR - \U0001f6a8 Error processing Q5: No connection adapters were found for "'https://www.autotrader.com/rest/lsc/crawl/modelyears?mileage=75000&searchRadius=0&sortBy=derivedpriceASC&zip=32216&allListingType=all-cars&makeCode=AUDI&modelCode=Q5&city=Jacksonville&state=FL&location=%5Bobject+Object%5D&dma=%5Bobject+Object%5D'"
Traceback (most recent call last):
  File "C:\Users\derek\Dropbox (Personal)\Cars\Price Puller Used Cars\Price_Puller.py", line 47, in get_avg_price
    response = session.get(url, headers=headers)
  File "C:\Users\derek\AppData\Local\Programs\Python\Python39\lib\site-packages\requests\sessions.py", line 555, in get
    return self.request('GET', url, **kwargs)
  File "C:\Users\derek\AppData\Local\Programs\Python\Python39\lib\site-packages\requests\sessions.py", line 542, in request
    resp = self.send(prep, **send_kwargs)
  File "C:\Users\derek\AppData\Local\Programs\Python\Python39\lib\site-packages\requests\sessions.py", line 649, in send
    adapter = self.get_adapter(url=request.url)
  File "C:\Users\derek\AppData\Local\Programs\Python\Python39\lib\site-packages\requests\sessions.py", line 742, in get_adapter
    raise InvalidSchema("No connection adapters were found for {!r}".format(url))
requests.exceptions.InvalidSchema: No connection adapters were found for "'https://www.autotrader.com/rest/lsc/crawl/modelyears?mileage=75000&searchRadius=0&sortBy=derivedpriceASC&zip=32216&allListingType=all-cars&makeCode=AUDI&modelCode=Q5&city=Jacksonville&state=FL&location=%5Bobject+Object%5D&dma=%5Bobject+Object%5D'"
2025-04-28 11:47:57,065 - ERROR - \U0001f6a8 Error processing RS7: No connection adapters were found for "'https://www.autotrader.com/rest/lsc/crawl/modelyears?marketExtension=include&mileage=75000&numRecords=24&searchRadius=0&sortBy=derivedpriceASC&zip=02861&allListingType=all-cars&makeCode=AUDI&modelCode=AUDIRS7&city=Pawtucket&state=RI&location=%5Bobject+Object%5D&dma=%5Bobject+Object%5D&facetMinCount=3&channel=ATC'"
Traceback (most recent call last):
  File "C:\Users\derek\Dropbox (Personal)\Cars\Price Puller Used Cars\Price_Puller.py", line 47, in get_avg_price
    response = session.get(url, headers=headers)
  File "C:\Users\derek\AppData\Local\Programs\Python\Python39\lib\site-packages\requests\sessions.py", line 555, in get
    return self.request('GET', url, **kwargs)
  File "C:\Users\derek\AppData\Local\Programs\Python\Python39\lib\site-packages\requests\sessions.py", line 542, in request
    resp = self.send(prep, **send_kwargs)
  File "C:\Users\derek\AppData\Local\Programs\Python\Python39\lib\site-packages\requests\sessions.py", line 649, in send
    adapter = self.get_adapter(url=request.url)
  File "C:\Users\derek\AppData\Local\Programs\Python\Python39\lib\site-packages\requests\sessions.py", line 742, in get_adapter
    raise InvalidSchema("No connection adapters were found for {!r}".format(url))
requests.exceptions.InvalidSchema: No connection adapters were found for "'https://www.autotrader.com/rest/lsc/crawl/modelyears?marketExtension=include&mileage=75000&numRecords=24&searchRadius=0&sortBy=derivedpriceASC&zip=02861&allListingType=all-cars&makeCode=AUDI&modelCode=AUDIRS7&city=Pawtucket&state=RI&location=%5Bobject+Object%5D&dma=%5Bobject+Object%5D&facetMinCount=3&channel=ATC'"
2025-04-28 11:47:57,066 - ERROR - \U0001f6a8 Error processing Etron: No connection adapters were found for "'https://www.autotrader.com/rest/lsc/crawl/modelyears?searchRadius=0&sortBy=derivedpriceASC&zip=32216&allListingType=all-cars&makeCode=AUDI&modelCode=AUDRSETRON&city=Jacksonville&state=FL&location=%5Bobject+Object%5D&dma=%5Bobject+Object%5D'"
Traceback (most recent call last):
  File "C:\Users\derek\Dropbox (Personal)\Cars\Price Puller Used Cars\Price_Puller.py", line 47, in get_avg_price
    response = session.get(url, headers=headers)
  File "C:\Users\derek\AppData\Local\Programs\Python\Python39\lib\site-packages\requests\sessions.py", line 555, in get
    return self.request('GET', url, **kwargs)
  File "C:\Users\derek\AppData\Local\Programs\Python\Python39\lib\site-packages\requests\sessions.py", line 542, in request
    resp = self.send(prep, **send_kwargs)
  File "C:\Users\derek\AppData\Local\Programs\Python\Python39\lib\site-packages\requests\sessions.py", line 649, in send
    adapter = self.get_adapter(url=request.url)
  File "C:\Users\derek\AppData\Local\Programs\Python\Python39\lib\site-packages\requests\sessions.py", line 742, in get_adapter
    raise InvalidSchema("No connection adapters were found for {!r}".format(url))
requests.exceptions.InvalidSchema: No connection adapters were found for "'https://www.autotrader.com/rest/lsc/crawl/modelyears?searchRadius=0&sortBy=derivedpriceASC&zip=32216&allListingType=all-cars&makeCode=AUDI&modelCode=AUDRSETRON&city=Jacksonville&state=FL&location=%5Bobject+Object%5D&dma=%5Bobject+Object%5D'"
2025-04-28 11:47:57,066 - ERROR - \U0001f6a8 Error processing M3: No connection adapters were found for "'https://www.autotrader.com/rest/lsc/crawl/modelyears?marketExtension=include&numRecords=24&searchRadius=0&sortBy=derivedpriceASC&transmissionCode=MAN&zip=32216&allListingType=all-cars&vehicleStyleCode=COUPE&engineCode=8CLDR&makeCode=BMW&modelCode=M3&city=Jacksonville&state=FL&location=%5Bobject+Object%5D&dma=%5Bobject+Object%5D'"
Traceback (most recent call last):
  File "C:\Users\derek\Dropbox (Personal)\Cars\Price Puller Used Cars\Price_Puller.py", line 47, in get_avg_price
    response = session.get(url, headers=headers)
  File "C:\Users\derek\AppData\Local\Programs\Python\Python39\lib\site-packages\requests\sessions.py", line 555, in get
    return self.request('GET', url, **kwargs)
  File "C:\Users\derek\AppData\Local\Programs\Python\Python39\lib\site-packages\requests\sessions.py", line 542, in request
    resp = self.send(prep, **send_kwargs)
  File "C:\Users\derek\AppData\Local\Programs\Python\Python39\lib\site-packages\requests\sessions.py", line 649, in send
    adapter = self.get_adapter(url=request.url)
  File "C:\Users\derek\AppData\Local\Programs\Python\Python39\lib\site-packages\requests\sessions.py", line 742, in get_adapter
    raise InvalidSchema("No connection adapters were found for {!r}".format(url))
requests.exceptions.InvalidSchema: No connection adapters were found for "'https://www.autotrader.com/rest/lsc/crawl/modelyears?marketExtension=include&numRecords=24&searchRadius=0&sortBy=derivedpriceASC&transmissionCode=MAN&zip=32216&allListingType=all-cars&vehicleStyleCode=COUPE&engineCode=8CLDR&makeCode=BMW&modelCode=M3&city=Jacksonville&state=FL&location=%5Bobject+Object%5D&dma=%5Bobject+Object%5D'"
2025-04-28 11:47:57,067 - ERROR - \U0001f6a8 Error processing M5: No connection adapters were found for "'https://www.autotrader.com/rest/lsc/crawl/modelyears?endYear=2003&marketExtension=include&numRecords=24&searchRadius=0&sortBy=derivedpriceASC&startYear=2000&zip=32216&allListingType=all-cars&extColorSimple=SILVER&makeCode=BMW&modelCode=M5&city=Jacksonville&state=FL&location=%5Bobject+Object%5D&dma=%5Bobject+Object%5D&facetMinCount=3&channel=ATC'"
Traceback (most recent call last):
  File "C:\Users\derek\Dropbox (Personal)\Cars\Price Puller Used Cars\Price_Puller.py", line 47, in get_avg_price
    response = session.get(url, headers=headers)
  File "C:\Users\derek\AppData\Local\Programs\Python\Python39\lib\site-packages\requests\sessions.py", line 555, in get
    return self.request('GET', url, **kwargs)
  File "C:\Users\derek\AppData\Local\Programs\Python\Python39\lib\site-packages\requests\sessions.py", line 542, in request
    resp = self.send(prep, **send_kwargs)
  File "C:\Users\derek\AppData\Local\Programs\Python\Python39\lib\site-packages\requests\sessions.py", line 649, in send
    adapter = self.get_adapter(url=request.url)
  File "C:\Users\derek\AppData\Local\Programs\Python\Python39\lib\site-packages\requests\sessions.py", line 742, in get_adapter
    raise InvalidSchema("No connection adapters were found for {!r}".format(url))
requests.exceptions.InvalidSchema: No connection adapters were found for "'https://www.autotrader.com/rest/lsc/crawl/modelyears?endYear=2003&marketExtension=include&numRecords=24&searchRadius=0&sortBy=derivedpriceASC&startYear=2000&zip=32216&allListingType=all-cars&extColorSimple=SILVER&makeCode=BMW&modelCode=M5&city=Jacksonville&state=FL&location=%5Bobject+Object%5D&dma=%5Bobject+Object%5D&facetMinCount=3&channel=ATC'"
2025-04-28 11:47:57,067 - ERROR - \U0001f6a8 Error processing Corvette Z06: No connection adapters were found for "'https://www.autotrader.com/rest/lsc/crawl/modelyears?zip=32216&allListingType=all-cars&makeCode=CHEV&modelCode=CORV&city=Jacksonville&state=FL&location=%5Bobject+Object%5D&dma=%5Bobject+Object%5D&searchRadius=50'"
Traceback (most recent call last):
  File "C:\Users\derek\Dropbox (Personal)\Cars\Price Puller Used Cars\Price_Puller.py", line 47, in get_avg_price
    response = session.get(url, headers=headers)
  File "C:\Users\derek\AppData\Local\Programs\Python\Python39\lib\site-packages\requests\sessions.py", line 555, in get
    return self.request('GET', url, **kwargs)
  File "C:\Users\derek\AppData\Local\Programs\Python\Python39\lib\site-packages\requests\sessions.py", line 542, in request
    resp = self.send(prep, **send_kwargs)
  File "C:\Users\derek\AppData\Local\Programs\Python\Python39\lib\site-packages\requests\sessions.py", line 649, in send
    adapter = self.get_adapter(url=request.url)
  File "C:\Users\derek\AppData\Local\Programs\Python\Python39\lib\site-packages\requests\sessions.py", line 742, in get_adapter
    raise InvalidSchema("No connection adapters were found for {!r}".format(url))
requests.exceptions.InvalidSchema: No connection adapters were found for "'https://www.autotrader.com/rest/lsc/crawl/modelyears?zip=32216&allListingType=all-cars&makeCode=CHEV&modelCode=CORV&city=Jacksonville&state=FL&location=%5Bobject+Object%5D&dma=%5Bobject+Object%5D&searchRadius=50'"
2025-04-28 11:47:57,068 - ERROR - \U0001f6a8 Error processing Corvette ZR1: No connection adapters were found for "'https://www.autotrader.com/rest/lsc/crawl/modelyears?searchRadius=0&zip=32216&allListingType=all-cars&makeCode=CHEV&modelCode=CORV&trimCode=CORV%7CZR1&city=Jacksonville&state=FL&location=%5Bobject+Object%5D&dma=%5Bobject+Object%5D'"
Traceback (most recent call last):
  File "C:\Users\derek\Dropbox (Personal)\Cars\Price Puller Used Cars\Price_Puller.py", line 47, in get_avg_price
    response = session.get(url, headers=headers)
  File "C:\Users\derek\AppData\Local\Programs\Python\Python39\lib\site-packages\requests\sessions.py", line 555, in get
    return self.request('GET', url, **kwargs)
  File "C:\Users\derek\AppData\Local\Programs\Python\Python39\lib\site-packages\requests\sessions.py", line 542, in request
    resp = self.send(prep, **send_kwargs)
  File "C:\Users\derek\AppData\Local\Programs\Python\Python39\lib\site-packages\requests\sessions.py", line 649, in send
    adapter = self.get_adapter(url=request.url)
  File "C:\Users\derek\AppData\Local\Programs\Python\Python39\lib\site-packages\requests\sessions.py", line 742, in get_adapter
    raise InvalidSchema("No connection adapters were found for {!r}".format(url))
requests.exceptions.InvalidSchema: No connection adapters were found for "'https://www.autotrader.com/rest/lsc/crawl/modelyears?searchRadius=0&zip=32216&allListingType=all-cars&makeCode=CHEV&modelCode=CORV&trimCode=CORV%7CZR1&city=Jacksonville&state=FL&location=%5Bobject+Object%5D&dma=%5Bobject+Object%5D'"
2025-04-28 11:47:57,068 - ERROR - \U0001f6a8 Error processing 458 Italia: No connection adapters were found for "'https://www.autotrader.com/rest/lsc/crawl/modelyears?searchRadius=0&zip=32216&allListingType=all-cars&vehicleStyleCode=COUPE&makeCode=FER&modelCode=458ITALIA&city=Jacksonville&state=FL&location=%5Bobject+Object%5D&dma=%5Bobject+Object%5D'"
Traceback (most recent call last):
  File "C:\Users\derek\Dropbox (Personal)\Cars\Price Puller Used Cars\Price_Puller.py", line 47, in get_avg_price
    response = session.get(url, headers=headers)
  File "C:\Users\derek\AppData\Local\Programs\Python\Python39\lib\site-packages\requests\sessions.py", line 555, in get
    return self.request('GET', url, **kwargs)
  File "C:\Users\derek\AppData\Local\Programs\Python\Python39\lib\site-packages\requests\sessions.py", line 542, in request
    resp = self.send(prep, **send_kwargs)
  File "C:\Users\derek\AppData\Local\Programs\Python\Python39\lib\site-packages\requests\sessions.py", line 649, in send
    adapter = self.get_adapter(url=request.url)
  File "C:\Users\derek\AppData\Local\Programs\Python\Python39\lib\site-packages\requests\sessions.py", line 742, in get_adapter
    raise InvalidSchema("No connection adapters were found for {!r}".format(url))
requests.exceptions.InvalidSchema: No connection adapters were found for "'https://www.autotrader.com/rest/lsc/crawl/modelyears?searchRadius=0&zip=32216&allListingType=all-cars&vehicleStyleCode=COUPE&makeCode=FER&modelCode=458ITALIA&city=Jacksonville&state=FL&location=%5Bobject+Object%5D&dma=%5Bobject+Object%5D'"
2025-04-28 11:47:57,069 - ERROR - \U0001f6a8 Error processing F250: No connection adapters were found for "'https://www.autotrader.com/rest/lsc/crawl/modelyears?searchRadius=0&zip=32216&allListingType=all-cars&makeCode=FORD&modelCode=F250&city=Jacksonville&state=FL&location=%5Bobject+Object%5D&dma=%5Bobject+Object%5D&facetMinCount=3&channel=ATC'"
Traceback (most recent call last):
  File "C:\Users\derek\Dropbox (Personal)\Cars\Price Puller Used Cars\Price_Puller.py", line 47, in get_avg_price
    response = session.get(url, headers=headers)
  File "C:\Users\derek\AppData\Local\Programs\Python\Python39\lib\site-packages\requests\sessions.py", line 555, in get
    return self.request('GET', url, **kwargs)
  File "C:\Users\derek\AppData\Local\Programs\Python\Python39\lib\site-packages\requests\sessions.py", line 542, in request
    resp = self.send(prep, **send_kwargs)
  File "C:\Users\derek\AppData\Local\Programs\Python\Python39\lib\site-packages\requests\sessions.py", line 649, in send
    adapter = self.get_adapter(url=request.url)
  File "C:\Users\derek\AppData\Local\Programs\Python\Python39\lib\site-packages\requests\sessions.py", line 742, in get_adapter
    raise InvalidSchema("No connection adapters were found for {!r}".format(url))
requests.exceptions.InvalidSchema: No connection adapters were found for "'https://www.autotrader.com/rest/lsc/crawl/modelyears?searchRadius=0&zip=32216&allListingType=all-cars&makeCode=FORD&modelCode=F250&city=Jacksonville&state=FL&location=%5Bobject+Object%5D&dma=%5Bobject+Object%5D&facetMinCount=3&channel=ATC'"
2025-04-28 11:47:57,069 - ERROR - \U0001f6a8 Error processing GT: No connection adapters were found for "'https://www.autotrader.com/rest/lsc/crawl/modelyears?searchRadius=0&zip=32216&allListingType=all-cars&makeCode=FORD&modelCode=GT&city=Jacksonville&state=FL&location=%5Bobject+Object%5D&dma=%5Bobject+Object%5D'"
Traceback (most recent call last):
  File "C:\Users\derek\Dropbox (Personal)\Cars\Price Puller Used Cars\Price_Puller.py", line 47, in get_avg_price
    response = session.get(url, headers=headers)
  File "C:\Users\derek\AppData\Local\Programs\Python\Python39\lib\site-packages\requests\sessions.py", line 555, in get
    return self.request('GET', url, **kwargs)
  File "C:\Users\derek\AppData\Local\Programs\Python\Python39\lib\site-packages\requests\sessions.py", line 542, in request
    resp = self.send(prep, **send_kwargs)
  File "C:\Users\derek\AppData\Local\Programs\Python\Python39\lib\site-packages\requests\sessions.py", line 649, in send
    adapter = self.get_adapter(url=request.url)
  File "C:\Users\derek\AppData\Local\Programs\Python\Python39\lib\site-packages\requests\sessions.py", line 742, in get_adapter
    raise InvalidSchema("No connection adapters were found for {!r}".format(url))
requests.exceptions.InvalidSchema: No connection adapters were found for "'https://www.autotrader.com/rest/lsc/crawl/modelyears?searchRadius=0&zip=32216&allListingType=all-cars&makeCode=FORD&modelCode=GT&city=Jacksonville&state=FL&location=%5Bobject+Object%5D&dma=%5Bobject+Object%5D'"
2025-04-28 11:47:57,070 - ERROR - \U0001f6a8 Error processing S2000: No connection adapters were found for "'https://www.autotrader.com/rest/lsc/crawl/modelyears?searchRadius=0&zip=32216&allListingType=all-cars&makeCode=HONDA&modelCode=S2000&city=Jacksonville&state=FL&location=%5Bobject+Object%5D&dma=%5Bobject+Object%5D&facetMinCount=3&channel=ATC'"
Traceback (most recent call last):
  File "C:\Users\derek\Dropbox (Personal)\Cars\Price Puller Used Cars\Price_Puller.py", line 47, in get_avg_price
    response = session.get(url, headers=headers)
  File "C:\Users\derek\AppData\Local\Programs\Python\Python39\lib\site-packages\requests\sessions.py", line 555, in get
    return self.request('GET', url, **kwargs)
  File "C:\Users\derek\AppData\Local\Programs\Python\Python39\lib\site-packages\requests\sessions.py", line 542, in request
    resp = self.send(prep, **send_kwargs)
  File "C:\Users\derek\AppData\Local\Programs\Python\Python39\lib\site-packages\requests\sessions.py", line 649, in send
    adapter = self.get_adapter(url=request.url)
  File "C:\Users\derek\AppData\Local\Programs\Python\Python39\lib\site-packages\requests\sessions.py", line 742, in get_adapter
    raise InvalidSchema("No connection adapters were found for {!r}".format(url))
requests.exceptions.InvalidSchema: No connection adapters were found for "'https://www.autotrader.com/rest/lsc/crawl/modelyears?searchRadius=0&zip=32216&allListingType=all-cars&makeCode=HONDA&modelCode=S2000&city=Jacksonville&state=FL&location=%5Bobject+Object%5D&dma=%5Bobject+Object%5D&facetMinCount=3&channel=ATC'"
2025-04-28 11:47:57,070 - ERROR - \U0001f6a8 Error processing Wrangler: No connection adapters were found for "'https://www.autotrader.com/rest/lsc/crawl/modelyears?searchRadius=0&zip=32216&allListingType=all-cars&makeCode=JEEP&modelCode=WRANGLER&city=Jacksonville&state=FL&location=%5Bobject+Object%5D&dma=%5Bobject+Object%5D&facetMinCount=3&channel=ATC'"
Traceback (most recent call last):
  File "C:\Users\derek\Dropbox (Personal)\Cars\Price Puller Used Cars\Price_Puller.py", line 47, in get_avg_price
    response = session.get(url, headers=headers)
  File "C:\Users\derek\AppData\Local\Programs\Python\Python39\lib\site-packages\requests\sessions.py", line 555, in get
    return self.request('GET', url, **kwargs)
  File "C:\Users\derek\AppData\Local\Programs\Python\Python39\lib\site-packages\requests\sessions.py", line 542, in request
    resp = self.send(prep, **send_kwargs)
  File "C:\Users\derek\AppData\Local\Programs\Python\Python39\lib\site-packages\requests\sessions.py", line 649, in send
    adapter = self.get_adapter(url=request.url)
  File "C:\Users\derek\AppData\Local\Programs\Python\Python39\lib\site-packages\requests\sessions.py", line 742, in get_adapter
    raise InvalidSchema("No connection adapters were found for {!r}".format(url))
requests.exceptions.InvalidSchema: No connection adapters were found for "'https://www.autotrader.com/rest/lsc/crawl/modelyears?searchRadius=0&zip=32216&allListingType=all-cars&makeCode=JEEP&modelCode=WRANGLER&city=Jacksonville&state=FL&location=%5Bobject+Object%5D&dma=%5Bobject+Object%5D&facetMinCount=3&channel=ATC'"
2025-04-28 11:47:57,071 - ERROR - \U0001f6a8 Error processing Aventador: No connection adapters were found for "'https://www.autotrader.com/rest/lsc/crawl/modelyears?searchRadius=0&zip=32216&allListingType=all-cars&makeCode=LAM&modelCode=AVENT&city=Jacksonville&state=FL&location=%5Bobject+Object%5D&dma=%5Bobject+Object%5D'"
Traceback (most recent call last):
  File "C:\Users\derek\Dropbox (Personal)\Cars\Price Puller Used Cars\Price_Puller.py", line 47, in get_avg_price
    response = session.get(url, headers=headers)
  File "C:\Users\derek\AppData\Local\Programs\Python\Python39\lib\site-packages\requests\sessions.py", line 555, in get
    return self.request('GET', url, **kwargs)
  File "C:\Users\derek\AppData\Local\Programs\Python\Python39\lib\site-packages\requests\sessions.py", line 542, in request
    resp = self.send(prep, **send_kwargs)
  File "C:\Users\derek\AppData\Local\Programs\Python\Python39\lib\site-packages\requests\sessions.py", line 649, in send
    adapter = self.get_adapter(url=request.url)
  File "C:\Users\derek\AppData\Local\Programs\Python\Python39\lib\site-packages\requests\sessions.py", line 742, in get_adapter
    raise InvalidSchema("No connection adapters were found for {!r}".format(url))
requests.exceptions.InvalidSchema: No connection adapters were found for "'https://www.autotrader.com/rest/lsc/crawl/modelyears?searchRadius=0&zip=32216&allListingType=all-cars&makeCode=LAM&modelCode=AVENT&city=Jacksonville&state=FL&location=%5Bobject+Object%5D&dma=%5Bobject+Object%5D'"
2025-04-28 11:47:57,071 - ERROR - \U0001f6a8 Error processing Gallardo: No connection adapters were found for "'https://www.autotrader.com/rest/lsc/crawl/modelyears?searchRadius=0&sortBy=derivedpriceASC&zip=32216&allListingType=all-cars&vehicleStyleCode=COUPE&makeCode=LAM&modelCode=GALLARDO&city=Jacksonville&state=FL&location=%5Bobject+Object%5D&dma=%5Bobject+Object%5D'"
Traceback (most recent call last):
  File "C:\Users\derek\Dropbox (Personal)\Cars\Price Puller Used Cars\Price_Puller.py", line 47, in get_avg_price
    response = session.get(url, headers=headers)
  File "C:\Users\derek\AppData\Local\Programs\Python\Python39\lib\site-packages\requests\sessions.py", line 555, in get
    return self.request('GET', url, **kwargs)
  File "C:\Users\derek\AppData\Local\Programs\Python\Python39\lib\site-packages\requests\sessions.py", line 542, in request
    resp = self.send(prep, **send_kwargs)
  File "C:\Users\derek\AppData\Local\Programs\Python\Python39\lib\site-packages\requests\sessions.py", line 649, in send
    adapter = self.get_adapter(url=request.url)
  File "C:\Users\derek\AppData\Local\Programs\Python\Python39\lib\site-packages\requests\sessions.py", line 742, in get_adapter
    raise InvalidSchema("No connection adapters were found for {!r}".format(url))
requests.exceptions.InvalidSchema: No connection adapters were found for "'https://www.autotrader.com/rest/lsc/crawl/modelyears?searchRadius=0&sortBy=derivedpriceASC&zip=32216&allListingType=all-cars&vehicleStyleCode=COUPE&makeCode=LAM&modelCode=GALLARDO&city=Jacksonville&state=FL&location=%5Bobject+Object%5D&dma=%5Bobject+Object%5D'"
2025-04-28 11:47:57,071 - ERROR - \U0001f6a8 Error processing Huracan: No connection adapters were found for "'https://www.autotrader.com/rest/lsc/crawl/modelyears?searchRadius=0&zip=32216&allListingType=all-cars&makeCode=LAM&modelCode=LAMHURACAN&city=Jacksonville&state=FL&location=%5Bobject+Object%5D&dma=%5Bobject+Object%5D&facetMinCount=3&channel=ATC'"
Traceback (most recent call last):
  File "C:\Users\derek\Dropbox (Personal)\Cars\Price Puller Used Cars\Price_Puller.py", line 47, in get_avg_price
    response = session.get(url, headers=headers)
  File "C:\Users\derek\AppData\Local\Programs\Python\Python39\lib\site-packages\requests\sessions.py", line 555, in get
    return self.request('GET', url, **kwargs)
  File "C:\Users\derek\AppData\Local\Programs\Python\Python39\lib\site-packages\requests\sessions.py", line 542, in request
    resp = self.send(prep, **send_kwargs)
  File "C:\Users\derek\AppData\Local\Programs\Python\Python39\lib\site-packages\requests\sessions.py", line 649, in send
    adapter = self.get_adapter(url=request.url)
  File "C:\Users\derek\AppData\Local\Programs\Python\Python39\lib\site-packages\requests\sessions.py", line 742, in get_adapter
    raise InvalidSchema("No connection adapters were found for {!r}".format(url))
requests.exceptions.InvalidSchema: No connection adapters were found for "'https://www.autotrader.com/rest/lsc/crawl/modelyears?searchRadius=0&zip=32216&allListingType=all-cars&makeCode=LAM&modelCode=LAMHURACAN&city=Jacksonville&state=FL&location=%5Bobject+Object%5D&dma=%5Bobject+Object%5D&facetMinCount=3&channel=ATC'"
2025-04-28 11:47:57,072 - ERROR - \U0001f6a8 Error processing Murcielago: No connection adapters were found for "'https://www.autotrader.com/rest/lsc/crawl/modelyears?searchRadius=0&sortBy=derivedpriceASC&startYear=2007&zip=32216&allListingType=all-cars&makeCode=LAM&modelCode=MURCIELAGO&city=Jacksonville&state=FL&location=%5Bobject+Object%5D&dma=%5Bobject+Object%5D'"
Traceback (most recent call last):
  File "C:\Users\derek\Dropbox (Personal)\Cars\Price Puller Used Cars\Price_Puller.py", line 47, in get_avg_price
    response = session.get(url, headers=headers)
  File "C:\Users\derek\AppData\Local\Programs\Python\Python39\lib\site-packages\requests\sessions.py", line 555, in get
    return self.request('GET', url, **kwargs)
  File "C:\Users\derek\AppData\Local\Programs\Python\Python39\lib\site-packages\requests\sessions.py", line 542, in request
    resp = self.send(prep, **send_kwargs)
  File "C:\Users\derek\AppData\Local\Programs\Python\Python39\lib\site-packages\requests\sessions.py", line 649, in send
    adapter = self.get_adapter(url=request.url)
  File "C:\Users\derek\AppData\Local\Programs\Python\Python39\lib\site-packages\requests\sessions.py", line 742, in get_adapter
    raise InvalidSchema("No connection adapters were found for {!r}".format(url))
requests.exceptions.InvalidSchema: No connection adapters were found for "'https://www.autotrader.com/rest/lsc/crawl/modelyears?searchRadius=0&sortBy=derivedpriceASC&startYear=2007&zip=32216&allListingType=all-cars&makeCode=LAM&modelCode=MURCIELAGO&city=Jacksonville&state=FL&location=%5Bobject+Object%5D&dma=%5Bobject+Object%5D'"
2025-04-28 11:47:57,072 - ERROR - \U0001f6a8 Error processing Urus: No connection adapters were found for "'https://www.autotrader.com/rest/lsc/crawl/modelyears?searchRadius=0&zip=32216&allListingType=all-cars&makeCode=LAM&modelCode=LAMURUS&city=Jacksonville&state=FL&location=%5Bobject+Object%5D&dma=%5Bobject+Object%5D'"
Traceback (most recent call last):
  File "C:\Users\derek\Dropbox (Personal)\Cars\Price Puller Used Cars\Price_Puller.py", line 47, in get_avg_price
    response = session.get(url, headers=headers)
  File "C:\Users\derek\AppData\Local\Programs\Python\Python39\lib\site-packages\requests\sessions.py", line 555, in get
    return self.request('GET', url, **kwargs)
  File "C:\Users\derek\AppData\Local\Programs\Python\Python39\lib\site-packages\requests\sessions.py", line 542, in request
    resp = self.send(prep, **send_kwargs)
  File "C:\Users\derek\AppData\Local\Programs\Python\Python39\lib\site-packages\requests\sessions.py", line 649, in send
    adapter = self.get_adapter(url=request.url)
  File "C:\Users\derek\AppData\Local\Programs\Python\Python39\lib\site-packages\requests\sessions.py", line 742, in get_adapter
    raise InvalidSchema("No connection adapters were found for {!r}".format(url))
requests.exceptions.InvalidSchema: No connection adapters were found for "'https://www.autotrader.com/rest/lsc/crawl/modelyears?searchRadius=0&zip=32216&allListingType=all-cars&makeCode=LAM&modelCode=LAMURUS&city=Jacksonville&state=FL&location=%5Bobject+Object%5D&dma=%5Bobject+Object%5D'"
2025-04-28 11:47:57,073 - ERROR - \U0001f6a8 Error processing AMG: No connection adapters were found for "'https://www.autotrader.com/rest/lsc/crawl/modelyears?searchRadius=0&zip=32216&allListingType=all-cars&vehicleStyleCode=COUPE&makeCode=MB&modelCode=MBAMGGT&city=Jacksonville&state=FL&location=%5Bobject+Object%5D&dma=%5Bobject+Object%5D'"
Traceback (most recent call last):
  File "C:\Users\derek\Dropbox (Personal)\Cars\Price Puller Used Cars\Price_Puller.py", line 47, in get_avg_price
    response = session.get(url, headers=headers)
  File "C:\Users\derek\AppData\Local\Programs\Python\Python39\lib\site-packages\requests\sessions.py", line 555, in get
    return self.request('GET', url, **kwargs)
  File "C:\Users\derek\AppData\Local\Programs\Python\Python39\lib\site-packages\requests\sessions.py", line 542, in request
    resp = self.send(prep, **send_kwargs)
  File "C:\Users\derek\AppData\Local\Programs\Python\Python39\lib\site-packages\requests\sessions.py", line 649, in send
    adapter = self.get_adapter(url=request.url)
  File "C:\Users\derek\AppData\Local\Programs\Python\Python39\lib\site-packages\requests\sessions.py", line 742, in get_adapter
    raise InvalidSchema("No connection adapters were found for {!r}".format(url))
requests.exceptions.InvalidSchema: No connection adapters were found for "'https://www.autotrader.com/rest/lsc/crawl/modelyears?searchRadius=0&zip=32216&allListingType=all-cars&vehicleStyleCode=COUPE&makeCode=MB&modelCode=MBAMGGT&city=Jacksonville&state=FL&location=%5Bobject+Object%5D&dma=%5Bobject+Object%5D'"
2025-04-28 11:47:57,073 - ERROR - \U0001f6a8 Error processing C63 AMG: No connection adapters were found for "'https://www.autotrader.com/rest/lsc/crawl/modelyears?searchRadius=0&zip=32216&allListingType=all-cars&makeCode=MB&seriesCode=C_CLASS&modelCode=C63AMG&city=Jacksonville&state=FL&location=%5Bobject+Object%5D&dma=%5Bobject+Object%5D'"
Traceback (most recent call last):
  File "C:\Users\derek\Dropbox (Personal)\Cars\Price Puller Used Cars\Price_Puller.py", line 47, in get_avg_price
    response = session.get(url, headers=headers)
  File "C:\Users\derek\AppData\Local\Programs\Python\Python39\lib\site-packages\requests\sessions.py", line 555, in get
    return self.request('GET', url, **kwargs)
  File "C:\Users\derek\AppData\Local\Programs\Python\Python39\lib\site-packages\requests\sessions.py", line 542, in request
    resp = self.send(prep, **send_kwargs)
  File "C:\Users\derek\AppData\Local\Programs\Python\Python39\lib\site-packages\requests\sessions.py", line 649, in send
    adapter = self.get_adapter(url=request.url)
  File "C:\Users\derek\AppData\Local\Programs\Python\Python39\lib\site-packages\requests\sessions.py", line 742, in get_adapter
    raise InvalidSchema("No connection adapters were found for {!r}".format(url))
requests.exceptions.InvalidSchema: No connection adapters were found for "'https://www.autotrader.com/rest/lsc/crawl/modelyears?searchRadius=0&zip=32216&allListingType=all-cars&makeCode=MB&seriesCode=C_CLASS&modelCode=C63AMG&city=Jacksonville&state=FL&location=%5Bobject+Object%5D&dma=%5Bobject+Object%5D'"
2025-04-28 11:47:57,074 - ERROR - \U0001f6a8 Error processing Carrera S: No connection adapters were found for "'https://www.autotrader.com/rest/lsc/crawl/modelyears?marketExtension=include&mileage=75000&numRecords=24&searchRadius=0&sortBy=derivedpriceASC&startYear=2006&transmissionCode=MAN&zip=32216&allListingType=all-cars&vehicleStyleCode=COUPE&makeCode=POR&modelCode=911&trimCode=911%7CCarrera+S&city=Jacksonville&state=FL&location=%5Bobject+Object%5D&dma=%5Bobject+Object%5D'"
Traceback (most recent call last):
  File "C:\Users\derek\Dropbox (Personal)\Cars\Price Puller Used Cars\Price_Puller.py", line 47, in get_avg_price
    response = session.get(url, headers=headers)
  File "C:\Users\derek\AppData\Local\Programs\Python\Python39\lib\site-packages\requests\sessions.py", line 555, in get
    return self.request('GET', url, **kwargs)
  File "C:\Users\derek\AppData\Local\Programs\Python\Python39\lib\site-packages\requests\sessions.py", line 542, in request
    resp = self.send(prep, **send_kwargs)
  File "C:\Users\derek\AppData\Local\Programs\Python\Python39\lib\site-packages\requests\sessions.py", line 649, in send
    adapter = self.get_adapter(url=request.url)
  File "C:\Users\derek\AppData\Local\Programs\Python\Python39\lib\site-packages\requests\sessions.py", line 742, in get_adapter
    raise InvalidSchema("No connection adapters were found for {!r}".format(url))
requests.exceptions.InvalidSchema: No connection adapters were found for "'https://www.autotrader.com/rest/lsc/crawl/modelyears?marketExtension=include&mileage=75000&numRecords=24&searchRadius=0&sortBy=derivedpriceASC&startYear=2006&transmissionCode=MAN&zip=32216&allListingType=all-cars&vehicleStyleCode=COUPE&makeCode=POR&modelCode=911&trimCode=911%7CCarrera+S&city=Jacksonville&state=FL&location=%5Bobject+Object%5D&dma=%5Bobject+Object%5D'"
2025-04-28 11:47:57,074 - ERROR - \U0001f6a8 Error processing GT3: No connection adapters were found for "'https://www.autotrader.com/rest/lsc/crawl/modelyears?endYear=2024&firstRecord=0&marketExtension=include&numRecords=100&searchRadius=0&sortBy=derivedpriceASC&startYear=2004&zip=32216&makeCode=POR&modelCode=911&trimCode=911%7CGT3&city=Jacksonville&state=FL&location=%5Bobject+Object%5D&dma=%5Bobject+Object%5D&listingType=USED'"
Traceback (most recent call last):
  File "C:\Users\derek\Dropbox (Personal)\Cars\Price Puller Used Cars\Price_Puller.py", line 47, in get_avg_price
    response = session.get(url, headers=headers)
  File "C:\Users\derek\AppData\Local\Programs\Python\Python39\lib\site-packages\requests\sessions.py", line 555, in get
    return self.request('GET', url, **kwargs)
  File "C:\Users\derek\AppData\Local\Programs\Python\Python39\lib\site-packages\requests\sessions.py", line 542, in request
    resp = self.send(prep, **send_kwargs)
  File "C:\Users\derek\AppData\Local\Programs\Python\Python39\lib\site-packages\requests\sessions.py", line 649, in send
    adapter = self.get_adapter(url=request.url)
  File "C:\Users\derek\AppData\Local\Programs\Python\Python39\lib\site-packages\requests\sessions.py", line 742, in get_adapter
    raise InvalidSchema("No connection adapters were found for {!r}".format(url))
requests.exceptions.InvalidSchema: No connection adapters were found for "'https://www.autotrader.com/rest/lsc/crawl/modelyears?endYear=2024&firstRecord=0&marketExtension=include&numRecords=100&searchRadius=0&sortBy=derivedpriceASC&startYear=2004&zip=32216&makeCode=POR&modelCode=911&trimCode=911%7CGT3&city=Jacksonville&state=FL&location=%5Bobject+Object%5D&dma=%5Bobject+Object%5D&listingType=USED'"
2025-04-28 11:47:57,075 - ERROR - \U0001f6a8 Error processing GT3RS: No connection adapters were found for "'https://www.autotrader.com/rest/lsc/crawl/modelyears?searchRadius=0&zip=32216&allListingType=all-cars&makeCode=POR&modelCode=911&trimCode=911%7CGT3+RS&city=Jacksonville&state=FL&location=%5Bobject+Object%5D&dma=%5Bobject+Object%5D'"
Traceback (most recent call last):
  File "C:\Users\derek\Dropbox (Personal)\Cars\Price Puller Used Cars\Price_Puller.py", line 47, in get_avg_price
    response = session.get(url, headers=headers)
  File "C:\Users\derek\AppData\Local\Programs\Python\Python39\lib\site-packages\requests\sessions.py", line 555, in get
    return self.request('GET', url, **kwargs)
  File "C:\Users\derek\AppData\Local\Programs\Python\Python39\lib\site-packages\requests\sessions.py", line 542, in request
    resp = self.send(prep, **send_kwargs)
  File "C:\Users\derek\AppData\Local\Programs\Python\Python39\lib\site-packages\requests\sessions.py", line 649, in send
    adapter = self.get_adapter(url=request.url)
  File "C:\Users\derek\AppData\Local\Programs\Python\Python39\lib\site-packages\requests\sessions.py", line 742, in get_adapter
    raise InvalidSchema("No connection adapters were found for {!r}".format(url))
requests.exceptions.InvalidSchema: No connection adapters were found for "'https://www.autotrader.com/rest/lsc/crawl/modelyears?searchRadius=0&zip=32216&allListingType=all-cars&makeCode=POR&modelCode=911&trimCode=911%7CGT3+RS&city=Jacksonville&state=FL&location=%5Bobject+Object%5D&dma=%5Bobject+Object%5D'"
2025-04-28 11:47:57,075 - ERROR - \U0001f6a8 Error processing GT4: No connection adapters were found for "'https://www.autotrader.com/rest/lsc/crawl/modelyears?searchRadius=0&zip=32216&allListingType=all-cars&makeCode=POR&modelCode=POR718CAY&trimCode=POR718CAY%7CGT4&city=Jacksonville&state=FL&location=%5Bobject+Object%5D&dma=%5Bobject+Object%5D'"
Traceback (most recent call last):
  File "C:\Users\derek\Dropbox (Personal)\Cars\Price Puller Used Cars\Price_Puller.py", line 47, in get_avg_price
    response = session.get(url, headers=headers)
  File "C:\Users\derek\AppData\Local\Programs\Python\Python39\lib\site-packages\requests\sessions.py", line 555, in get
    return self.request('GET', url, **kwargs)
  File "C:\Users\derek\AppData\Local\Programs\Python\Python39\lib\site-packages\requests\sessions.py", line 542, in request
    resp = self.send(prep, **send_kwargs)
  File "C:\Users\derek\AppData\Local\Programs\Python\Python39\lib\site-packages\requests\sessions.py", line 649, in send
    adapter = self.get_adapter(url=request.url)
  File "C:\Users\derek\AppData\Local\Programs\Python\Python39\lib\site-packages\requests\sessions.py", line 742, in get_adapter
    raise InvalidSchema("No connection adapters were found for {!r}".format(url))
requests.exceptions.InvalidSchema: No connection adapters were found for "'https://www.autotrader.com/rest/lsc/crawl/modelyears?searchRadius=0&zip=32216&allListingType=all-cars&makeCode=POR&modelCode=POR718CAY&trimCode=POR718CAY%7CGT4&city=Jacksonville&state=FL&location=%5Bobject+Object%5D&dma=%5Bobject+Object%5D'"
2025-04-28 11:47:57,076 - ERROR - \U0001f6a8 Error processing GT4RS: No connection adapters were found for "'https://www.autotrader.com/rest/lsc/crawl/modelyears?searchRadius=0&zip=32216&allListingType=all-cars&makeCode=POR&modelCode=POR718CAY&trimCode=POR718CAY%7CGT4+RS&city=Jacksonville&state=FL&location=%5Bobject+Object%5D&dma=%5Bobject+Object%5D'"
Traceback (most recent call last):
  File "C:\Users\derek\Dropbox (Personal)\Cars\Price Puller Used Cars\Price_Puller.py", line 47, in get_avg_price
    response = session.get(url, headers=headers)
  File "C:\Users\derek\AppData\Local\Programs\Python\Python39\lib\site-packages\requests\sessions.py", line 555, in get
    return self.request('GET', url, **kwargs)
  File "C:\Users\derek\AppData\Local\Programs\Python\Python39\lib\site-packages\requests\sessions.py", line 542, in request
    resp = self.send(prep, **send_kwargs)
  File "C:\Users\derek\AppData\Local\Programs\Python\Python39\lib\site-packages\requests\sessions.py", line 649, in send
    adapter = self.get_adapter(url=request.url)
  File "C:\Users\derek\AppData\Local\Programs\Python\Python39\lib\site-packages\requests\sessions.py", line 742, in get_adapter
    raise InvalidSchema("No connection adapters were found for {!r}".format(url))
requests.exceptions.InvalidSchema: No connection adapters were found for "'https://www.autotrader.com/rest/lsc/crawl/modelyears?searchRadius=0&zip=32216&allListingType=all-cars&makeCode=POR&modelCode=POR718CAY&trimCode=POR718CAY%7CGT4+RS&city=Jacksonville&state=FL&location=%5Bobject+Object%5D&dma=%5Bobject+Object%5D'"
2025-04-28 11:47:57,076 - ERROR - \U0001f6a8 Error processing Cayenne: No connection adapters were found for "'https://www.autotrader.com/rest/lsc/crawl/modelyears?searchRadius=0&zip=32216&allListingType=all-cars&makeCode=POR&modelCode=CAYENNE&city=Jacksonville&state=FL&location=%5Bobject+Object%5D&dma=%5Bobject+Object%5D'"
Traceback (most recent call last):
  File "C:\Users\derek\Dropbox (Personal)\Cars\Price Puller Used Cars\Price_Puller.py", line 47, in get_avg_price
    response = session.get(url, headers=headers)
  File "C:\Users\derek\AppData\Local\Programs\Python\Python39\lib\site-packages\requests\sessions.py", line 555, in get
    return self.request('GET', url, **kwargs)
  File "C:\Users\derek\AppData\Local\Programs\Python\Python39\lib\site-packages\requests\sessions.py", line 542, in request
    resp = self.send(prep, **send_kwargs)
  File "C:\Users\derek\AppData\Local\Programs\Python\Python39\lib\site-packages\requests\sessions.py", line 649, in send
    adapter = self.get_adapter(url=request.url)
  File "C:\Users\derek\AppData\Local\Programs\Python\Python39\lib\site-packages\requests\sessions.py", line 742, in get_adapter
    raise InvalidSchema("No connection adapters were found for {!r}".format(url))
requests.exceptions.InvalidSchema: No connection adapters were found for "'https://www.autotrader.com/rest/lsc/crawl/modelyears?searchRadius=0&zip=32216&allListingType=all-cars&makeCode=POR&modelCode=CAYENNE&city=Jacksonville&state=FL&location=%5Bobject+Object%5D&dma=%5Bobject+Object%5D'"
2025-04-28 11:47:57,077 - ERROR - \U0001f6a8 Error processing Macan: No connection adapters were found for "'https://www.autotrader.com/rest/lsc/crawl/modelyears?searchRadius=0&zip=32216&allListingType=all-cars&engineCode=6CLDR&makeCode=POR&modelCode=PORMACAN&city=Jacksonville&state=FL&location=%5Bobject+Object%5D&dma=%5Bobject+Object%5D'"
Traceback (most recent call last):
  File "C:\Users\derek\Dropbox (Personal)\Cars\Price Puller Used Cars\Price_Puller.py", line 47, in get_avg_price
    response = session.get(url, headers=headers)
  File "C:\Users\derek\AppData\Local\Programs\Python\Python39\lib\site-packages\requests\sessions.py", line 555, in get
    return self.request('GET', url, **kwargs)
  File "C:\Users\derek\AppData\Local\Programs\Python\Python39\lib\site-packages\requests\sessions.py", line 542, in request
    resp = self.send(prep, **send_kwargs)
  File "C:\Users\derek\AppData\Local\Programs\Python\Python39\lib\site-packages\requests\sessions.py", line 649, in send
    adapter = self.get_adapter(url=request.url)
  File "C:\Users\derek\AppData\Local\Programs\Python\Python39\lib\site-packages\requests\sessions.py", line 742, in get_adapter
    raise InvalidSchema("No connection adapters were found for {!r}".format(url))
requests.exceptions.InvalidSchema: No connection adapters were found for "'https://www.autotrader.com/rest/lsc/crawl/modelyears?searchRadius=0&zip=32216&allListingType=all-cars&engineCode=6CLDR&makeCode=POR&modelCode=PORMACAN&city=Jacksonville&state=FL&location=%5Bobject+Object%5D&dma=%5Bobject+Object%5D'"
2025-04-28 11:47:57,077 - ERROR - \U0001f6a8 Error processing Taycan: No connection adapters were found for "'https://www.autotrader.com/rest/lsc/crawl/modelyears?searchRadius=0&zip=32216&allListingType=all-cars&makeCode=POR&modelCode=PORTAYCAN&trimCode=PORTAYCAN%7CTurbo+S&city=Jacksonville&state=FL&location=%5Bobject+Object%5D&dma=%5Bobject+Object%5D'"
Traceback (most recent call last):
  File "C:\Users\derek\Dropbox (Personal)\Cars\Price Puller Used Cars\Price_Puller.py", line 47, in get_avg_price
    response = session.get(url, headers=headers)
  File "C:\Users\derek\AppData\Local\Programs\Python\Python39\lib\site-packages\requests\sessions.py", line 555, in get
    return self.request('GET', url, **kwargs)
  File "C:\Users\derek\AppData\Local\Programs\Python\Python39\lib\site-packages\requests\sessions.py", line 542, in request
    resp = self.send(prep, **send_kwargs)
  File "C:\Users\derek\AppData\Local\Programs\Python\Python39\lib\site-packages\requests\sessions.py", line 649, in send
    adapter = self.get_adapter(url=request.url)
  File "C:\Users\derek\AppData\Local\Programs\Python\Python39\lib\site-packages\requests\sessions.py", line 742, in get_adapter
    raise InvalidSchema("No connection adapters were found for {!r}".format(url))
requests.exceptions.InvalidSchema: No connection adapters were found for "'https://www.autotrader.com/rest/lsc/crawl/modelyears?searchRadius=0&zip=32216&allListingType=all-cars&makeCode=POR&modelCode=PORTAYCAN&trimCode=PORTAYCAN%7CTurbo+S&city=Jacksonville&state=FL&location=%5Bobject+Object%5D&dma=%5Bobject+Object%5D'"
2025-04-28 11:47:57,078 - ERROR - \U0001f6a8 Error processing BRZ: No connection adapters were found for "'https://www.autotrader.com/rest/lsc/crawl/modelyears?searchRadius=0&sortBy=derivedpriceASC&zip=32216&allListingType=all-cars&makeCode=SUB&modelCode=SUBBRZ&city=Jacksonville&state=FL&location=%5Bobject+Object%5D&dma=%5Bobject+Object%5D'"
Traceback (most recent call last):
  File "C:\Users\derek\Dropbox (Personal)\Cars\Price Puller Used Cars\Price_Puller.py", line 47, in get_avg_price
    response = session.get(url, headers=headers)
  File "C:\Users\derek\AppData\Local\Programs\Python\Python39\lib\site-packages\requests\sessions.py", line 555, in get
    return self.request('GET', url, **kwargs)
  File "C:\Users\derek\AppData\Local\Programs\Python\Python39\lib\site-packages\requests\sessions.py", line 542, in request
    resp = self.send(prep, **send_kwargs)
  File "C:\Users\derek\AppData\Local\Programs\Python\Python39\lib\site-packages\requests\sessions.py", line 649, in send
    adapter = self.get_adapter(url=request.url)
  File "C:\Users\derek\AppData\Local\Programs\Python\Python39\lib\site-packages\requests\sessions.py", line 742, in get_adapter
    raise InvalidSchema("No connection adapters were found for {!r}".format(url))
requests.exceptions.InvalidSchema: No connection adapters were found for "'https://www.autotrader.com/rest/lsc/crawl/modelyears?searchRadius=0&sortBy=derivedpriceASC&zip=32216&allListingType=all-cars&makeCode=SUB&modelCode=SUBBRZ&city=Jacksonville&state=FL&location=%5Bobject+Object%5D&dma=%5Bobject+Object%5D'"
2025-04-28 11:47:57,078 - ERROR - \U0001f6a8 Error processing CyberTruck: No connection adapters were found for "'https://www.autotrader.com/rest/lsc/crawl/modelyears?searchRadius=0&zip=32216&allListingType=all-cars&makeCode=TESLA&modelCode=TESCYBERTR&city=Jacksonville&state=FL&location=%5Bobject+Object%5D&dma=%5Bobject+Object%5D'"
Traceback (most recent call last):
  File "C:\Users\derek\Dropbox (Personal)\Cars\Price Puller Used Cars\Price_Puller.py", line 47, in get_avg_price
    response = session.get(url, headers=headers)
  File "C:\Users\derek\AppData\Local\Programs\Python\Python39\lib\site-packages\requests\sessions.py", line 555, in get
    return self.request('GET', url, **kwargs)
  File "C:\Users\derek\AppData\Local\Programs\Python\Python39\lib\site-packages\requests\sessions.py", line 542, in request
    resp = self.send(prep, **send_kwargs)
  File "C:\Users\derek\AppData\Local\Programs\Python\Python39\lib\site-packages\requests\sessions.py", line 649, in send
    adapter = self.get_adapter(url=request.url)
  File "C:\Users\derek\AppData\Local\Programs\Python\Python39\lib\site-packages\requests\sessions.py", line 742, in get_adapter
    raise InvalidSchema("No connection adapters were found for {!r}".format(url))
requests.exceptions.InvalidSchema: No connection adapters were found for "'https://www.autotrader.com/rest/lsc/crawl/modelyears?searchRadius=0&zip=32216&allListingType=all-cars&makeCode=TESLA&modelCode=TESCYBERTR&city=Jacksonville&state=FL&location=%5Bobject+Object%5D&dma=%5Bobject+Object%5D'"
2025-04-28 11:47:57,078 - ERROR - \U0001f6a8 Error processing Model 3: No connection adapters were found for "'https://www.autotrader.com/rest/lsc/crawl/modelyears?searchRadius=0&sortBy=derivedpriceASC&zip=02861&allListingType=all-cars&makeCode=TESLA&modelCode=TESMOD3&trimCode=TESMOD3%7CPerformance&city=Pawtucket&state=RI&location=%5Bobject+Object%5D&dma=%5Bobject+Object%5D'"
Traceback (most recent call last):
  File "C:\Users\derek\Dropbox (Personal)\Cars\Price Puller Used Cars\Price_Puller.py", line 47, in get_avg_price
    response = session.get(url, headers=headers)
  File "C:\Users\derek\AppData\Local\Programs\Python\Python39\lib\site-packages\requests\sessions.py", line 555, in get
    return self.request('GET', url, **kwargs)
  File "C:\Users\derek\AppData\Local\Programs\Python\Python39\lib\site-packages\requests\sessions.py", line 542, in request
    resp = self.send(prep, **send_kwargs)
  File "C:\Users\derek\AppData\Local\Programs\Python\Python39\lib\site-packages\requests\sessions.py", line 649, in send
    adapter = self.get_adapter(url=request.url)
  File "C:\Users\derek\AppData\Local\Programs\Python\Python39\lib\site-packages\requests\sessions.py", line 742, in get_adapter
    raise InvalidSchema("No connection adapters were found for {!r}".format(url))
requests.exceptions.InvalidSchema: No connection adapters were found for "'https://www.autotrader.com/rest/lsc/crawl/modelyears?searchRadius=0&sortBy=derivedpriceASC&zip=02861&allListingType=all-cars&makeCode=TESLA&modelCode=TESMOD3&trimCode=TESMOD3%7CPerformance&city=Pawtucket&state=RI&location=%5Bobject+Object%5D&dma=%5Bobject+Object%5D'"
2025-04-28 11:47:57,079 - ERROR - \U0001f6a8 Error processing Model X: No connection adapters were found for "'https://www.autotrader.com/rest/lsc/crawl/modelyears?searchRadius=0&sortBy=derivedpriceASC&zip=02861&allListingType=all-cars&makeCode=TESLA&modelCode=TESMODX&trimCode=TESMODX%7CP100D&city=Pawtucket&state=RI&location=%5Bobject+Object%5D&dma=%5Bobject+Object%5D'"
Traceback (most recent call last):
  File "C:\Users\derek\Dropbox (Personal)\Cars\Price Puller Used Cars\Price_Puller.py", line 47, in get_avg_price
    response = session.get(url, headers=headers)
  File "C:\Users\derek\AppData\Local\Programs\Python\Python39\lib\site-packages\requests\sessions.py", line 555, in get
    return self.request('GET', url, **kwargs)
  File "C:\Users\derek\AppData\Local\Programs\Python\Python39\lib\site-packages\requests\sessions.py", line 542, in request
    resp = self.send(prep, **send_kwargs)
  File "C:\Users\derek\AppData\Local\Programs\Python\Python39\lib\site-packages\requests\sessions.py", line 649, in send
    adapter = self.get_adapter(url=request.url)
  File "C:\Users\derek\AppData\Local\Programs\Python\Python39\lib\site-packages\requests\sessions.py", line 742, in get_adapter
    raise InvalidSchema("No connection adapters were found for {!r}".format(url))
requests.exceptions.InvalidSchema: No connection adapters were found for "'https://www.autotrader.com/rest/lsc/crawl/modelyears?searchRadius=0&sortBy=derivedpriceASC&zip=02861&allListingType=all-cars&makeCode=TESLA&modelCode=TESMODX&trimCode=TESMODX%7CP100D&city=Pawtucket&state=RI&location=%5Bobject+Object%5D&dma=%5Bobject+Object%5D'"
2025-04-28 11:47:57,079 - ERROR - \U0001f6a8 Error processing Model Y: No connection adapters were found for "'https://www.autotrader.com/rest/lsc/crawl/modelyears?searchRadius=0&zip=32216&allListingType=all-cars&makeCode=TESLA&modelCode=TESMODY&city=Jacksonville&state=FL&location=%5Bobject+Object%5D&dma=%5Bobject+Object%5D'"
Traceback (most recent call last):
  File "C:\Users\derek\Dropbox (Personal)\Cars\Price Puller Used Cars\Price_Puller.py", line 47, in get_avg_price
    response = session.get(url, headers=headers)
  File "C:\Users\derek\AppData\Local\Programs\Python\Python39\lib\site-packages\requests\sessions.py", line 555, in get
    return self.request('GET', url, **kwargs)
  File "C:\Users\derek\AppData\Local\Programs\Python\Python39\lib\site-packages\requests\sessions.py", line 542, in request
    resp = self.send(prep, **send_kwargs)
  File "C:\Users\derek\AppData\Local\Programs\Python\Python39\lib\site-packages\requests\sessions.py", line 649, in send
    adapter = self.get_adapter(url=request.url)
  File "C:\Users\derek\AppData\Local\Programs\Python\Python39\lib\site-packages\requests\sessions.py", line 742, in get_adapter
    raise InvalidSchema("No connection adapters were found for {!r}".format(url))
requests.exceptions.InvalidSchema: No connection adapters were found for "'https://www.autotrader.com/rest/lsc/crawl/modelyears?searchRadius=0&zip=32216&allListingType=all-cars&makeCode=TESLA&modelCode=TESMODY&city=Jacksonville&state=FL&location=%5Bobject+Object%5D&dma=%5Bobject+Object%5D'"
2025-04-28 11:47:57,080 - ERROR - \U0001f6a8 Error processing Model S: No connection adapters were found for "'https://www.autotrader.com/rest/lsc/crawl/modelyears?searchRadius=0&zip=32216&allListingType=all-cars&makeCode=POR&modelCode=PORTAYCAN&trimCode=PORTAYCAN%7CTurbo+S&city=Jacksonville&state=FL&location=%5Bobject+Object%5D&dma=%5Bobject+Object%5D'"
Traceback (most recent call last):
  File "C:\Users\derek\Dropbox (Personal)\Cars\Price Puller Used Cars\Price_Puller.py", line 47, in get_avg_price
    response = session.get(url, headers=headers)
  File "C:\Users\derek\AppData\Local\Programs\Python\Python39\lib\site-packages\requests\sessions.py", line 555, in get
    return self.request('GET', url, **kwargs)
  File "C:\Users\derek\AppData\Local\Programs\Python\Python39\lib\site-packages\requests\sessions.py", line 542, in request
    resp = self.send(prep, **send_kwargs)
  File "C:\Users\derek\AppData\Local\Programs\Python\Python39\lib\site-packages\requests\sessions.py", line 649, in send
    adapter = self.get_adapter(url=request.url)
  File "C:\Users\derek\AppData\Local\Programs\Python\Python39\lib\site-packages\requests\sessions.py", line 742, in get_adapter
    raise InvalidSchema("No connection adapters were found for {!r}".format(url))
requests.exceptions.InvalidSchema: No connection adapters were found for "'https://www.autotrader.com/rest/lsc/crawl/modelyears?searchRadius=0&zip=32216&allListingType=all-cars&makeCode=POR&modelCode=PORTAYCAN&trimCode=PORTAYCAN%7CTurbo+S&city=Jacksonville&state=FL&location=%5Bobject+Object%5D&dma=%5Bobject+Object%5D'"
2025-04-28 11:52:33,623 - INFO - \u2705 Loaded 36 URLs from car_urls.txt
2025-04-28 11:52:33,625 - ERROR - \U0001f6a8 Error processing R8: No connection adapters were found for "'https://www.autotrader.com/rest/lsc/crawl/modelyears?searchRadius=0&sortBy=derivedpriceASC&zip=32216&allListingType=all-cars&vehicleStyleCode=COUPE&engineCode=10CLDR&makeCode=AUDI&modelCode=R8&city=Jacksonville&state=FL&location=%5Bobject+Object%5D&dma=%5Bobject+Object%5D'"
Traceback (most recent call last):
  File "C:\Users\derek\Dropbox (Personal)\Cars\Price Puller Used Cars\Price_Puller.py", line 46, in get_avg_price
    response = session.get(url, headers=headers)
  File "C:\Users\derek\AppData\Local\Programs\Python\Python39\lib\site-packages\requests\sessions.py", line 555, in get
    return self.request('GET', url, **kwargs)
  File "C:\Users\derek\AppData\Local\Programs\Python\Python39\lib\site-packages\requests\sessions.py", line 542, in request
    resp = self.send(prep, **send_kwargs)
  File "C:\Users\derek\AppData\Local\Programs\Python\Python39\lib\site-packages\requests\sessions.py", line 649, in send
    adapter = self.get_adapter(url=request.url)
  File "C:\Users\derek\AppData\Local\Programs\Python\Python39\lib\site-packages\requests\sessions.py", line 742, in get_adapter
    raise InvalidSchema("No connection adapters were found for {!r}".format(url))
requests.exceptions.InvalidSchema: No connection adapters were found for "'https://www.autotrader.com/rest/lsc/crawl/modelyears?searchRadius=0&sortBy=derivedpriceASC&zip=32216&allListingType=all-cars&vehicleStyleCode=COUPE&engineCode=10CLDR&makeCode=AUDI&modelCode=R8&city=Jacksonville&state=FL&location=%5Bobject+Object%5D&dma=%5Bobject+Object%5D'"
2025-04-28 11:52:33,626 - ERROR - \U0001f6a8 Error processing RS4: No connection adapters were found for "'https://www.autotrader.com/rest/lsc/crawl/modelyears?marketExtension=include&numRecords=24&searchRadius=0&showAccelerateBanner=false&sortBy=derivedpriceASC&zip=32216&allListingType=all-cars&makeCode=AUDI&modelCode=RS4&city=Jacksonville&state=FL&location=%5Bobject+Object%5D&dma=%5Bobject+Object%5D'"
Traceback (most recent call last):
  File "C:\Users\derek\Dropbox (Personal)\Cars\Price Puller Used Cars\Price_Puller.py", line 46, in get_avg_price
    response = session.get(url, headers=headers)
  File "C:\Users\derek\AppData\Local\Programs\Python\Python39\lib\site-packages\requests\sessions.py", line 555, in get
    return self.request('GET', url, **kwargs)
  File "C:\Users\derek\AppData\Local\Programs\Python\Python39\lib\site-packages\requests\sessions.py", line 542, in request
    resp = self.send(prep, **send_kwargs)
  File "C:\Users\derek\AppData\Local\Programs\Python\Python39\lib\site-packages\requests\sessions.py", line 649, in send
    adapter = self.get_adapter(url=request.url)
  File "C:\Users\derek\AppData\Local\Programs\Python\Python39\lib\site-packages\requests\sessions.py", line 742, in get_adapter
    raise InvalidSchema("No connection adapters were found for {!r}".format(url))
requests.exceptions.InvalidSchema: No connection adapters were found for "'https://www.autotrader.com/rest/lsc/crawl/modelyears?marketExtension=include&numRecords=24&searchRadius=0&showAccelerateBanner=false&sortBy=derivedpriceASC&zip=32216&allListingType=all-cars&makeCode=AUDI&modelCode=RS4&city=Jacksonville&state=FL&location=%5Bobject+Object%5D&dma=%5Bobject+Object%5D'"
2025-04-28 11:52:33,627 - ERROR - \U0001f6a8 Error processing S4: No connection adapters were found for "'https://www.autotrader.com/rest/lsc/crawl/modelyears?marketExtension=include&numRecords=24&searchRadius=500&showAccelerateBanner=false&sortBy=derivedpriceASC&startYear=2013&zip=32216&allListingType=all-cars&makeCode=AUDI&modelCode=S4&city=Jacksonville&state=FL&location=%5Bobject+Object%5D&dma=%5Bobject+Object%5D'"
Traceback (most recent call last):
  File "C:\Users\derek\Dropbox (Personal)\Cars\Price Puller Used Cars\Price_Puller.py", line 46, in get_avg_price
    response = session.get(url, headers=headers)
  File "C:\Users\derek\AppData\Local\Programs\Python\Python39\lib\site-packages\requests\sessions.py", line 555, in get
    return self.request('GET', url, **kwargs)
  File "C:\Users\derek\AppData\Local\Programs\Python\Python39\lib\site-packages\requests\sessions.py", line 542, in request
    resp = self.send(prep, **send_kwargs)
  File "C:\Users\derek\AppData\Local\Programs\Python\Python39\lib\site-packages\requests\sessions.py", line 649, in send
    adapter = self.get_adapter(url=request.url)
  File "C:\Users\derek\AppData\Local\Programs\Python\Python39\lib\site-packages\requests\sessions.py", line 742, in get_adapter
    raise InvalidSchema("No connection adapters were found for {!r}".format(url))
requests.exceptions.InvalidSchema: No connection adapters were found for "'https://www.autotrader.com/rest/lsc/crawl/modelyears?marketExtension=include&numRecords=24&searchRadius=500&showAccelerateBanner=false&sortBy=derivedpriceASC&startYear=2013&zip=32216&allListingType=all-cars&makeCode=AUDI&modelCode=S4&city=Jacksonville&state=FL&location=%5Bobject+Object%5D&dma=%5Bobject+Object%5D'"
2025-04-28 11:52:33,628 - ERROR - \U0001f6a8 Error processing Q5: No connection adapters were found for "'https://www.autotrader.com/rest/lsc/crawl/modelyears?mileage=75000&searchRadius=0&sortBy=derivedpriceASC&zip=32216&allListingType=all-cars&makeCode=AUDI&modelCode=Q5&city=Jacksonville&state=FL&location=%5Bobject+Object%5D&dma=%5Bobject+Object%5D'"
Traceback (most recent call last):
  File "C:\Users\derek\Dropbox (Personal)\Cars\Price Puller Used Cars\Price_Puller.py", line 46, in get_avg_price
    response = session.get(url, headers=headers)
  File "C:\Users\derek\AppData\Local\Programs\Python\Python39\lib\site-packages\requests\sessions.py", line 555, in get
    return self.request('GET', url, **kwargs)
  File "C:\Users\derek\AppData\Local\Programs\Python\Python39\lib\site-packages\requests\sessions.py", line 542, in request
    resp = self.send(prep, **send_kwargs)
  File "C:\Users\derek\AppData\Local\Programs\Python\Python39\lib\site-packages\requests\sessions.py", line 649, in send
    adapter = self.get_adapter(url=request.url)
  File "C:\Users\derek\AppData\Local\Programs\Python\Python39\lib\site-packages\requests\sessions.py", line 742, in get_adapter
    raise InvalidSchema("No connection adapters were found for {!r}".format(url))
requests.exceptions.InvalidSchema: No connection adapters were found for "'https://www.autotrader.com/rest/lsc/crawl/modelyears?mileage=75000&searchRadius=0&sortBy=derivedpriceASC&zip=32216&allListingType=all-cars&makeCode=AUDI&modelCode=Q5&city=Jacksonville&state=FL&location=%5Bobject+Object%5D&dma=%5Bobject+Object%5D'"
2025-04-28 11:52:33,628 - ERROR - \U0001f6a8 Error processing RS7: No connection adapters were found for "'https://www.autotrader.com/rest/lsc/crawl/modelyears?marketExtension=include&mileage=75000&numRecords=24&searchRadius=0&sortBy=derivedpriceASC&zip=02861&allListingType=all-cars&makeCode=AUDI&modelCode=AUDIRS7&city=Pawtucket&state=RI&location=%5Bobject+Object%5D&dma=%5Bobject+Object%5D&facetMinCount=3&channel=ATC'"
Traceback (most recent call last):
  File "C:\Users\derek\Dropbox (Personal)\Cars\Price Puller Used Cars\Price_Puller.py", line 46, in get_avg_price
    response = session.get(url, headers=headers)
  File "C:\Users\derek\AppData\Local\Programs\Python\Python39\lib\site-packages\requests\sessions.py", line 555, in get
    return self.request('GET', url, **kwargs)
  File "C:\Users\derek\AppData\Local\Programs\Python\Python39\lib\site-packages\requests\sessions.py", line 542, in request
    resp = self.send(prep, **send_kwargs)
  File "C:\Users\derek\AppData\Local\Programs\Python\Python39\lib\site-packages\requests\sessions.py", line 649, in send
    adapter = self.get_adapter(url=request.url)
  File "C:\Users\derek\AppData\Local\Programs\Python\Python39\lib\site-packages\requests\sessions.py", line 742, in get_adapter
    raise InvalidSchema("No connection adapters were found for {!r}".format(url))
requests.exceptions.InvalidSchema: No connection adapters were found for "'https://www.autotrader.com/rest/lsc/crawl/modelyears?marketExtension=include&mileage=75000&numRecords=24&searchRadius=0&sortBy=derivedpriceASC&zip=02861&allListingType=all-cars&makeCode=AUDI&modelCode=AUDIRS7&city=Pawtucket&state=RI&location=%5Bobject+Object%5D&dma=%5Bobject+Object%5D&facetMinCount=3&channel=ATC'"
2025-04-28 11:52:33,629 - ERROR - \U0001f6a8 Error processing Etron: No connection adapters were found for "'https://www.autotrader.com/rest/lsc/crawl/modelyears?searchRadius=0&sortBy=derivedpriceASC&zip=32216&allListingType=all-cars&makeCode=AUDI&modelCode=AUDRSETRON&city=Jacksonville&state=FL&location=%5Bobject+Object%5D&dma=%5Bobject+Object%5D'"
Traceback (most recent call last):
  File "C:\Users\derek\Dropbox (Personal)\Cars\Price Puller Used Cars\Price_Puller.py", line 46, in get_avg_price
    response = session.get(url, headers=headers)
  File "C:\Users\derek\AppData\Local\Programs\Python\Python39\lib\site-packages\requests\sessions.py", line 555, in get
    return self.request('GET', url, **kwargs)
  File "C:\Users\derek\AppData\Local\Programs\Python\Python39\lib\site-packages\requests\sessions.py", line 542, in request
    resp = self.send(prep, **send_kwargs)
  File "C:\Users\derek\AppData\Local\Programs\Python\Python39\lib\site-packages\requests\sessions.py", line 649, in send
    adapter = self.get_adapter(url=request.url)
  File "C:\Users\derek\AppData\Local\Programs\Python\Python39\lib\site-packages\requests\sessions.py", line 742, in get_adapter
    raise InvalidSchema("No connection adapters were found for {!r}".format(url))
requests.exceptions.InvalidSchema: No connection adapters were found for "'https://www.autotrader.com/rest/lsc/crawl/modelyears?searchRadius=0&sortBy=derivedpriceASC&zip=32216&allListingType=all-cars&makeCode=AUDI&modelCode=AUDRSETRON&city=Jacksonville&state=FL&location=%5Bobject+Object%5D&dma=%5Bobject+Object%5D'"
2025-04-28 11:52:33,629 - ERROR - \U0001f6a8 Error processing M3: No connection adapters were found for "'https://www.autotrader.com/rest/lsc/crawl/modelyears?marketExtension=include&numRecords=24&searchRadius=0&sortBy=derivedpriceASC&transmissionCode=MAN&zip=32216&allListingType=all-cars&vehicleStyleCode=COUPE&engineCode=8CLDR&makeCode=BMW&modelCode=M3&city=Jacksonville&state=FL&location=%5Bobject+Object%5D&dma=%5Bobject+Object%5D'"
Traceback (most recent call last):
  File "C:\Users\derek\Dropbox (Personal)\Cars\Price Puller Used Cars\Price_Puller.py", line 46, in get_avg_price
    response = session.get(url, headers=headers)
  File "C:\Users\derek\AppData\Local\Programs\Python\Python39\lib\site-packages\requests\sessions.py", line 555, in get
    return self.request('GET', url, **kwargs)
  File "C:\Users\derek\AppData\Local\Programs\Python\Python39\lib\site-packages\requests\sessions.py", line 542, in request
    resp = self.send(prep, **send_kwargs)
  File "C:\Users\derek\AppData\Local\Programs\Python\Python39\lib\site-packages\requests\sessions.py", line 649, in send
    adapter = self.get_adapter(url=request.url)
  File "C:\Users\derek\AppData\Local\Programs\Python\Python39\lib\site-packages\requests\sessions.py", line 742, in get_adapter
    raise InvalidSchema("No connection adapters were found for {!r}".format(url))
requests.exceptions.InvalidSchema: No connection adapters were found for "'https://www.autotrader.com/rest/lsc/crawl/modelyears?marketExtension=include&numRecords=24&searchRadius=0&sortBy=derivedpriceASC&transmissionCode=MAN&zip=32216&allListingType=all-cars&vehicleStyleCode=COUPE&engineCode=8CLDR&makeCode=BMW&modelCode=M3&city=Jacksonville&state=FL&location=%5Bobject+Object%5D&dma=%5Bobject+Object%5D'"
2025-04-28 11:52:33,630 - ERROR - \U0001f6a8 Error processing M5: No connection adapters were found for "'https://www.autotrader.com/rest/lsc/crawl/modelyears?endYear=2003&marketExtension=include&numRecords=24&searchRadius=0&sortBy=derivedpriceASC&startYear=2000&zip=32216&allListingType=all-cars&extColorSimple=SILVER&makeCode=BMW&modelCode=M5&city=Jacksonville&state=FL&location=%5Bobject+Object%5D&dma=%5Bobject+Object%5D&facetMinCount=3&channel=ATC'"
Traceback (most recent call last):
  File "C:\Users\derek\Dropbox (Personal)\Cars\Price Puller Used Cars\Price_Puller.py", line 46, in get_avg_price
    response = session.get(url, headers=headers)
  File "C:\Users\derek\AppData\Local\Programs\Python\Python39\lib\site-packages\requests\sessions.py", line 555, in get
    return self.request('GET', url, **kwargs)
  File "C:\Users\derek\AppData\Local\Programs\Python\Python39\lib\site-packages\requests\sessions.py", line 542, in request
    resp = self.send(prep, **send_kwargs)
  File "C:\Users\derek\AppData\Local\Programs\Python\Python39\lib\site-packages\requests\sessions.py", line 649, in send
    adapter = self.get_adapter(url=request.url)
  File "C:\Users\derek\AppData\Local\Programs\Python\Python39\lib\site-packages\requests\sessions.py", line 742, in get_adapter
    raise InvalidSchema("No connection adapters were found for {!r}".format(url))
requests.exceptions.InvalidSchema: No connection adapters were found for "'https://www.autotrader.com/rest/lsc/crawl/modelyears?endYear=2003&marketExtension=include&numRecords=24&searchRadius=0&sortBy=derivedpriceASC&startYear=2000&zip=32216&allListingType=all-cars&extColorSimple=SILVER&makeCode=BMW&modelCode=M5&city=Jacksonville&state=FL&location=%5Bobject+Object%5D&dma=%5Bobject+Object%5D&facetMinCount=3&channel=ATC'"
2025-04-28 11:52:33,631 - ERROR - \U0001f6a8 Error processing Corvette Z06: No connection adapters were found for "'https://www.autotrader.com/rest/lsc/crawl/modelyears?zip=32216&allListingType=all-cars&makeCode=CHEV&modelCode=CORV&city=Jacksonville&state=FL&location=%5Bobject+Object%5D&dma=%5Bobject+Object%5D&searchRadius=50'"
Traceback (most recent call last):
  File "C:\Users\derek\Dropbox (Personal)\Cars\Price Puller Used Cars\Price_Puller.py", line 46, in get_avg_price
    response = session.get(url, headers=headers)
  File "C:\Users\derek\AppData\Local\Programs\Python\Python39\lib\site-packages\requests\sessions.py", line 555, in get
    return self.request('GET', url, **kwargs)
  File "C:\Users\derek\AppData\Local\Programs\Python\Python39\lib\site-packages\requests\sessions.py", line 542, in request
    resp = self.send(prep, **send_kwargs)
  File "C:\Users\derek\AppData\Local\Programs\Python\Python39\lib\site-packages\requests\sessions.py", line 649, in send
    adapter = self.get_adapter(url=request.url)
  File "C:\Users\derek\AppData\Local\Programs\Python\Python39\lib\site-packages\requests\sessions.py", line 742, in get_adapter
    raise InvalidSchema("No connection adapters were found for {!r}".format(url))
requests.exceptions.InvalidSchema: No connection adapters were found for "'https://www.autotrader.com/rest/lsc/crawl/modelyears?zip=32216&allListingType=all-cars&makeCode=CHEV&modelCode=CORV&city=Jacksonville&state=FL&location=%5Bobject+Object%5D&dma=%5Bobject+Object%5D&searchRadius=50'"
2025-04-28 11:52:33,631 - ERROR - \U0001f6a8 Error processing Corvette ZR1: No connection adapters were found for "'https://www.autotrader.com/rest/lsc/crawl/modelyears?searchRadius=0&zip=32216&allListingType=all-cars&makeCode=CHEV&modelCode=CORV&trimCode=CORV%7CZR1&city=Jacksonville&state=FL&location=%5Bobject+Object%5D&dma=%5Bobject+Object%5D'"
Traceback (most recent call last):
  File "C:\Users\derek\Dropbox (Personal)\Cars\Price Puller Used Cars\Price_Puller.py", line 46, in get_avg_price
    response = session.get(url, headers=headers)
  File "C:\Users\derek\AppData\Local\Programs\Python\Python39\lib\site-packages\requests\sessions.py", line 555, in get
    return self.request('GET', url, **kwargs)
  File "C:\Users\derek\AppData\Local\Programs\Python\Python39\lib\site-packages\requests\sessions.py", line 542, in request
    resp = self.send(prep, **send_kwargs)
  File "C:\Users\derek\AppData\Local\Programs\Python\Python39\lib\site-packages\requests\sessions.py", line 649, in send
    adapter = self.get_adapter(url=request.url)
  File "C:\Users\derek\AppData\Local\Programs\Python\Python39\lib\site-packages\requests\sessions.py", line 742, in get_adapter
    raise InvalidSchema("No connection adapters were found for {!r}".format(url))
requests.exceptions.InvalidSchema: No connection adapters were found for "'https://www.autotrader.com/rest/lsc/crawl/modelyears?searchRadius=0&zip=32216&allListingType=all-cars&makeCode=CHEV&modelCode=CORV&trimCode=CORV%7CZR1&city=Jacksonville&state=FL&location=%5Bobject+Object%5D&dma=%5Bobject+Object%5D'"
2025-04-28 11:52:33,632 - ERROR - \U0001f6a8 Error processing 458 Italia: No connection adapters were found for "'https://www.autotrader.com/rest/lsc/crawl/modelyears?searchRadius=0&zip=32216&allListingType=all-cars&vehicleStyleCode=COUPE&makeCode=FER&modelCode=458ITALIA&city=Jacksonville&state=FL&location=%5Bobject+Object%5D&dma=%5Bobject+Object%5D'"
Traceback (most recent call last):
  File "C:\Users\derek\Dropbox (Personal)\Cars\Price Puller Used Cars\Price_Puller.py", line 46, in get_avg_price
    response = session.get(url, headers=headers)
  File "C:\Users\derek\AppData\Local\Programs\Python\Python39\lib\site-packages\requests\sessions.py", line 555, in get
    return self.request('GET', url, **kwargs)
  File "C:\Users\derek\AppData\Local\Programs\Python\Python39\lib\site-packages\requests\sessions.py", line 542, in request
    resp = self.send(prep, **send_kwargs)
  File "C:\Users\derek\AppData\Local\Programs\Python\Python39\lib\site-packages\requests\sessions.py", line 649, in send
    adapter = self.get_adapter(url=request.url)
  File "C:\Users\derek\AppData\Local\Programs\Python\Python39\lib\site-packages\requests\sessions.py", line 742, in get_adapter
    raise InvalidSchema("No connection adapters were found for {!r}".format(url))
requests.exceptions.InvalidSchema: No connection adapters were found for "'https://www.autotrader.com/rest/lsc/crawl/modelyears?searchRadius=0&zip=32216&allListingType=all-cars&vehicleStyleCode=COUPE&makeCode=FER&modelCode=458ITALIA&city=Jacksonville&state=FL&location=%5Bobject+Object%5D&dma=%5Bobject+Object%5D'"
2025-04-28 11:52:33,633 - ERROR - \U0001f6a8 Error processing F250: No connection adapters were found for "'https://www.autotrader.com/rest/lsc/crawl/modelyears?searchRadius=0&zip=32216&allListingType=all-cars&makeCode=FORD&modelCode=F250&city=Jacksonville&state=FL&location=%5Bobject+Object%5D&dma=%5Bobject+Object%5D&facetMinCount=3&channel=ATC'"
Traceback (most recent call last):
  File "C:\Users\derek\Dropbox (Personal)\Cars\Price Puller Used Cars\Price_Puller.py", line 46, in get_avg_price
    response = session.get(url, headers=headers)
  File "C:\Users\derek\AppData\Local\Programs\Python\Python39\lib\site-packages\requests\sessions.py", line 555, in get
    return self.request('GET', url, **kwargs)
  File "C:\Users\derek\AppData\Local\Programs\Python\Python39\lib\site-packages\requests\sessions.py", line 542, in request
    resp = self.send(prep, **send_kwargs)
  File "C:\Users\derek\AppData\Local\Programs\Python\Python39\lib\site-packages\requests\sessions.py", line 649, in send
    adapter = self.get_adapter(url=request.url)
  File "C:\Users\derek\AppData\Local\Programs\Python\Python39\lib\site-packages\requests\sessions.py", line 742, in get_adapter
    raise InvalidSchema("No connection adapters were found for {!r}".format(url))
requests.exceptions.InvalidSchema: No connection adapters were found for "'https://www.autotrader.com/rest/lsc/crawl/modelyears?searchRadius=0&zip=32216&allListingType=all-cars&makeCode=FORD&modelCode=F250&city=Jacksonville&state=FL&location=%5Bobject+Object%5D&dma=%5Bobject+Object%5D&facetMinCount=3&channel=ATC'"
2025-04-28 11:52:33,633 - ERROR - \U0001f6a8 Error processing GT: No connection adapters were found for "'https://www.autotrader.com/rest/lsc/crawl/modelyears?searchRadius=0&zip=32216&allListingType=all-cars&makeCode=FORD&modelCode=GT&city=Jacksonville&state=FL&location=%5Bobject+Object%5D&dma=%5Bobject+Object%5D'"
Traceback (most recent call last):
  File "C:\Users\derek\Dropbox (Personal)\Cars\Price Puller Used Cars\Price_Puller.py", line 46, in get_avg_price
    response = session.get(url, headers=headers)
  File "C:\Users\derek\AppData\Local\Programs\Python\Python39\lib\site-packages\requests\sessions.py", line 555, in get
    return self.request('GET', url, **kwargs)
  File "C:\Users\derek\AppData\Local\Programs\Python\Python39\lib\site-packages\requests\sessions.py", line 542, in request
    resp = self.send(prep, **send_kwargs)
  File "C:\Users\derek\AppData\Local\Programs\Python\Python39\lib\site-packages\requests\sessions.py", line 649, in send
    adapter = self.get_adapter(url=request.url)
  File "C:\Users\derek\AppData\Local\Programs\Python\Python39\lib\site-packages\requests\sessions.py", line 742, in get_adapter
    raise InvalidSchema("No connection adapters were found for {!r}".format(url))
requests.exceptions.InvalidSchema: No connection adapters were found for "'https://www.autotrader.com/rest/lsc/crawl/modelyears?searchRadius=0&zip=32216&allListingType=all-cars&makeCode=FORD&modelCode=GT&city=Jacksonville&state=FL&location=%5Bobject+Object%5D&dma=%5Bobject+Object%5D'"
2025-04-28 11:52:33,634 - ERROR - \U0001f6a8 Error processing S2000: No connection adapters were found for "'https://www.autotrader.com/rest/lsc/crawl/modelyears?searchRadius=0&zip=32216&allListingType=all-cars&makeCode=HONDA&modelCode=S2000&city=Jacksonville&state=FL&location=%5Bobject+Object%5D&dma=%5Bobject+Object%5D&facetMinCount=3&channel=ATC'"
Traceback (most recent call last):
  File "C:\Users\derek\Dropbox (Personal)\Cars\Price Puller Used Cars\Price_Puller.py", line 46, in get_avg_price
    response = session.get(url, headers=headers)
  File "C:\Users\derek\AppData\Local\Programs\Python\Python39\lib\site-packages\requests\sessions.py", line 555, in get
    return self.request('GET', url, **kwargs)
  File "C:\Users\derek\AppData\Local\Programs\Python\Python39\lib\site-packages\requests\sessions.py", line 542, in request
    resp = self.send(prep, **send_kwargs)
  File "C:\Users\derek\AppData\Local\Programs\Python\Python39\lib\site-packages\requests\sessions.py", line 649, in send
    adapter = self.get_adapter(url=request.url)
  File "C:\Users\derek\AppData\Local\Programs\Python\Python39\lib\site-packages\requests\sessions.py", line 742, in get_adapter
    raise InvalidSchema("No connection adapters were found for {!r}".format(url))
requests.exceptions.InvalidSchema: No connection adapters were found for "'https://www.autotrader.com/rest/lsc/crawl/modelyears?searchRadius=0&zip=32216&allListingType=all-cars&makeCode=HONDA&modelCode=S2000&city=Jacksonville&state=FL&location=%5Bobject+Object%5D&dma=%5Bobject+Object%5D&facetMinCount=3&channel=ATC'"
2025-04-28 11:52:33,635 - ERROR - \U0001f6a8 Error processing Wrangler: No connection adapters were found for "'https://www.autotrader.com/rest/lsc/crawl/modelyears?searchRadius=0&zip=32216&allListingType=all-cars&makeCode=JEEP&modelCode=WRANGLER&city=Jacksonville&state=FL&location=%5Bobject+Object%5D&dma=%5Bobject+Object%5D&facetMinCount=3&channel=ATC'"
Traceback (most recent call last):
  File "C:\Users\derek\Dropbox (Personal)\Cars\Price Puller Used Cars\Price_Puller.py", line 46, in get_avg_price
    response = session.get(url, headers=headers)
  File "C:\Users\derek\AppData\Local\Programs\Python\Python39\lib\site-packages\requests\sessions.py", line 555, in get
    return self.request('GET', url, **kwargs)
  File "C:\Users\derek\AppData\Local\Programs\Python\Python39\lib\site-packages\requests\sessions.py", line 542, in request
    resp = self.send(prep, **send_kwargs)
  File "C:\Users\derek\AppData\Local\Programs\Python\Python39\lib\site-packages\requests\sessions.py", line 649, in send
    adapter = self.get_adapter(url=request.url)
  File "C:\Users\derek\AppData\Local\Programs\Python\Python39\lib\site-packages\requests\sessions.py", line 742, in get_adapter
    raise InvalidSchema("No connection adapters were found for {!r}".format(url))
requests.exceptions.InvalidSchema: No connection adapters were found for "'https://www.autotrader.com/rest/lsc/crawl/modelyears?searchRadius=0&zip=32216&allListingType=all-cars&makeCode=JEEP&modelCode=WRANGLER&city=Jacksonville&state=FL&location=%5Bobject+Object%5D&dma=%5Bobject+Object%5D&facetMinCount=3&channel=ATC'"
2025-04-28 11:52:33,635 - ERROR - \U0001f6a8 Error processing Aventador: No connection adapters were found for "'https://www.autotrader.com/rest/lsc/crawl/modelyears?searchRadius=0&zip=32216&allListingType=all-cars&makeCode=LAM&modelCode=AVENT&city=Jacksonville&state=FL&location=%5Bobject+Object%5D&dma=%5Bobject+Object%5D'"
Traceback (most recent call last):
  File "C:\Users\derek\Dropbox (Personal)\Cars\Price Puller Used Cars\Price_Puller.py", line 46, in get_avg_price
    response = session.get(url, headers=headers)
  File "C:\Users\derek\AppData\Local\Programs\Python\Python39\lib\site-packages\requests\sessions.py", line 555, in get
    return self.request('GET', url, **kwargs)
  File "C:\Users\derek\AppData\Local\Programs\Python\Python39\lib\site-packages\requests\sessions.py", line 542, in request
    resp = self.send(prep, **send_kwargs)
  File "C:\Users\derek\AppData\Local\Programs\Python\Python39\lib\site-packages\requests\sessions.py", line 649, in send
    adapter = self.get_adapter(url=request.url)
  File "C:\Users\derek\AppData\Local\Programs\Python\Python39\lib\site-packages\requests\sessions.py", line 742, in get_adapter
    raise InvalidSchema("No connection adapters were found for {!r}".format(url))
requests.exceptions.InvalidSchema: No connection adapters were found for "'https://www.autotrader.com/rest/lsc/crawl/modelyears?searchRadius=0&zip=32216&allListingType=all-cars&makeCode=LAM&modelCode=AVENT&city=Jacksonville&state=FL&location=%5Bobject+Object%5D&dma=%5Bobject+Object%5D'"
2025-04-28 11:52:33,636 - ERROR - \U0001f6a8 Error processing Gallardo: No connection adapters were found for "'https://www.autotrader.com/rest/lsc/crawl/modelyears?searchRadius=0&sortBy=derivedpriceASC&zip=32216&allListingType=all-cars&vehicleStyleCode=COUPE&makeCode=LAM&modelCode=GALLARDO&city=Jacksonville&state=FL&location=%5Bobject+Object%5D&dma=%5Bobject+Object%5D'"
Traceback (most recent call last):
  File "C:\Users\derek\Dropbox (Personal)\Cars\Price Puller Used Cars\Price_Puller.py", line 46, in get_avg_price
    response = session.get(url, headers=headers)
  File "C:\Users\derek\AppData\Local\Programs\Python\Python39\lib\site-packages\requests\sessions.py", line 555, in get
    return self.request('GET', url, **kwargs)
  File "C:\Users\derek\AppData\Local\Programs\Python\Python39\lib\site-packages\requests\sessions.py", line 542, in request
    resp = self.send(prep, **send_kwargs)
  File "C:\Users\derek\AppData\Local\Programs\Python\Python39\lib\site-packages\requests\sessions.py", line 649, in send
    adapter = self.get_adapter(url=request.url)
  File "C:\Users\derek\AppData\Local\Programs\Python\Python39\lib\site-packages\requests\sessions.py", line 742, in get_adapter
    raise InvalidSchema("No connection adapters were found for {!r}".format(url))
requests.exceptions.InvalidSchema: No connection adapters were found for "'https://www.autotrader.com/rest/lsc/crawl/modelyears?searchRadius=0&sortBy=derivedpriceASC&zip=32216&allListingType=all-cars&vehicleStyleCode=COUPE&makeCode=LAM&modelCode=GALLARDO&city=Jacksonville&state=FL&location=%5Bobject+Object%5D&dma=%5Bobject+Object%5D'"
2025-04-28 11:52:33,636 - ERROR - \U0001f6a8 Error processing Huracan: No connection adapters were found for "'https://www.autotrader.com/rest/lsc/crawl/modelyears?searchRadius=0&zip=32216&allListingType=all-cars&makeCode=LAM&modelCode=LAMHURACAN&city=Jacksonville&state=FL&location=%5Bobject+Object%5D&dma=%5Bobject+Object%5D&facetMinCount=3&channel=ATC'"
Traceback (most recent call last):
  File "C:\Users\derek\Dropbox (Personal)\Cars\Price Puller Used Cars\Price_Puller.py", line 46, in get_avg_price
    response = session.get(url, headers=headers)
  File "C:\Users\derek\AppData\Local\Programs\Python\Python39\lib\site-packages\requests\sessions.py", line 555, in get
    return self.request('GET', url, **kwargs)
  File "C:\Users\derek\AppData\Local\Programs\Python\Python39\lib\site-packages\requests\sessions.py", line 542, in request
    resp = self.send(prep, **send_kwargs)
  File "C:\Users\derek\AppData\Local\Programs\Python\Python39\lib\site-packages\requests\sessions.py", line 649, in send
    adapter = self.get_adapter(url=request.url)
  File "C:\Users\derek\AppData\Local\Programs\Python\Python39\lib\site-packages\requests\sessions.py", line 742, in get_adapter
    raise InvalidSchema("No connection adapters were found for {!r}".format(url))
requests.exceptions.InvalidSchema: No connection adapters were found for "'https://www.autotrader.com/rest/lsc/crawl/modelyears?searchRadius=0&zip=32216&allListingType=all-cars&makeCode=LAM&modelCode=LAMHURACAN&city=Jacksonville&state=FL&location=%5Bobject+Object%5D&dma=%5Bobject+Object%5D&facetMinCount=3&channel=ATC'"
2025-04-28 11:52:33,637 - ERROR - \U0001f6a8 Error processing Murcielago: No connection adapters were found for "'https://www.autotrader.com/rest/lsc/crawl/modelyears?searchRadius=0&sortBy=derivedpriceASC&startYear=2007&zip=32216&allListingType=all-cars&makeCode=LAM&modelCode=MURCIELAGO&city=Jacksonville&state=FL&location=%5Bobject+Object%5D&dma=%5Bobject+Object%5D'"
Traceback (most recent call last):
  File "C:\Users\derek\Dropbox (Personal)\Cars\Price Puller Used Cars\Price_Puller.py", line 46, in get_avg_price
    response = session.get(url, headers=headers)
  File "C:\Users\derek\AppData\Local\Programs\Python\Python39\lib\site-packages\requests\sessions.py", line 555, in get
    return self.request('GET', url, **kwargs)
  File "C:\Users\derek\AppData\Local\Programs\Python\Python39\lib\site-packages\requests\sessions.py", line 542, in request
    resp = self.send(prep, **send_kwargs)
  File "C:\Users\derek\AppData\Local\Programs\Python\Python39\lib\site-packages\requests\sessions.py", line 649, in send
    adapter = self.get_adapter(url=request.url)
  File "C:\Users\derek\AppData\Local\Programs\Python\Python39\lib\site-packages\requests\sessions.py", line 742, in get_adapter
    raise InvalidSchema("No connection adapters were found for {!r}".format(url))
requests.exceptions.InvalidSchema: No connection adapters were found for "'https://www.autotrader.com/rest/lsc/crawl/modelyears?searchRadius=0&sortBy=derivedpriceASC&startYear=2007&zip=32216&allListingType=all-cars&makeCode=LAM&modelCode=MURCIELAGO&city=Jacksonville&state=FL&location=%5Bobject+Object%5D&dma=%5Bobject+Object%5D'"
2025-04-28 11:52:33,637 - ERROR - \U0001f6a8 Error processing Urus: No connection adapters were found for "'https://www.autotrader.com/rest/lsc/crawl/modelyears?searchRadius=0&zip=32216&allListingType=all-cars&makeCode=LAM&modelCode=LAMURUS&city=Jacksonville&state=FL&location=%5Bobject+Object%5D&dma=%5Bobject+Object%5D'"
Traceback (most recent call last):
  File "C:\Users\derek\Dropbox (Personal)\Cars\Price Puller Used Cars\Price_Puller.py", line 46, in get_avg_price
    response = session.get(url, headers=headers)
  File "C:\Users\derek\AppData\Local\Programs\Python\Python39\lib\site-packages\requests\sessions.py", line 555, in get
    return self.request('GET', url, **kwargs)
  File "C:\Users\derek\AppData\Local\Programs\Python\Python39\lib\site-packages\requests\sessions.py", line 542, in request
    resp = self.send(prep, **send_kwargs)
  File "C:\Users\derek\AppData\Local\Programs\Python\Python39\lib\site-packages\requests\sessions.py", line 649, in send
    adapter = self.get_adapter(url=request.url)
  File "C:\Users\derek\AppData\Local\Programs\Python\Python39\lib\site-packages\requests\sessions.py", line 742, in get_adapter
    raise InvalidSchema("No connection adapters were found for {!r}".format(url))
requests.exceptions.InvalidSchema: No connection adapters were found for "'https://www.autotrader.com/rest/lsc/crawl/modelyears?searchRadius=0&zip=32216&allListingType=all-cars&makeCode=LAM&modelCode=LAMURUS&city=Jacksonville&state=FL&location=%5Bobject+Object%5D&dma=%5Bobject+Object%5D'"
2025-04-28 11:52:33,637 - ERROR - \U0001f6a8 Error processing AMG: No connection adapters were found for "'https://www.autotrader.com/rest/lsc/crawl/modelyears?searchRadius=0&zip=32216&allListingType=all-cars&vehicleStyleCode=COUPE&makeCode=MB&modelCode=MBAMGGT&city=Jacksonville&state=FL&location=%5Bobject+Object%5D&dma=%5Bobject+Object%5D'"
Traceback (most recent call last):
  File "C:\Users\derek\Dropbox (Personal)\Cars\Price Puller Used Cars\Price_Puller.py", line 46, in get_avg_price
    response = session.get(url, headers=headers)
  File "C:\Users\derek\AppData\Local\Programs\Python\Python39\lib\site-packages\requests\sessions.py", line 555, in get
    return self.request('GET', url, **kwargs)
  File "C:\Users\derek\AppData\Local\Programs\Python\Python39\lib\site-packages\requests\sessions.py", line 542, in request
    resp = self.send(prep, **send_kwargs)
  File "C:\Users\derek\AppData\Local\Programs\Python\Python39\lib\site-packages\requests\sessions.py", line 649, in send
    adapter = self.get_adapter(url=request.url)
  File "C:\Users\derek\AppData\Local\Programs\Python\Python39\lib\site-packages\requests\sessions.py", line 742, in get_adapter
    raise InvalidSchema("No connection adapters were found for {!r}".format(url))
requests.exceptions.InvalidSchema: No connection adapters were found for "'https://www.autotrader.com/rest/lsc/crawl/modelyears?searchRadius=0&zip=32216&allListingType=all-cars&vehicleStyleCode=COUPE&makeCode=MB&modelCode=MBAMGGT&city=Jacksonville&state=FL&location=%5Bobject+Object%5D&dma=%5Bobject+Object%5D'"
2025-04-28 11:52:33,638 - ERROR - \U0001f6a8 Error processing C63 AMG: No connection adapters were found for "'https://www.autotrader.com/rest/lsc/crawl/modelyears?searchRadius=0&zip=32216&allListingType=all-cars&makeCode=MB&seriesCode=C_CLASS&modelCode=C63AMG&city=Jacksonville&state=FL&location=%5Bobject+Object%5D&dma=%5Bobject+Object%5D'"
Traceback (most recent call last):
  File "C:\Users\derek\Dropbox (Personal)\Cars\Price Puller Used Cars\Price_Puller.py", line 46, in get_avg_price
    response = session.get(url, headers=headers)
  File "C:\Users\derek\AppData\Local\Programs\Python\Python39\lib\site-packages\requests\sessions.py", line 555, in get
    return self.request('GET', url, **kwargs)
  File "C:\Users\derek\AppData\Local\Programs\Python\Python39\lib\site-packages\requests\sessions.py", line 542, in request
    resp = self.send(prep, **send_kwargs)
  File "C:\Users\derek\AppData\Local\Programs\Python\Python39\lib\site-packages\requests\sessions.py", line 649, in send
    adapter = self.get_adapter(url=request.url)
  File "C:\Users\derek\AppData\Local\Programs\Python\Python39\lib\site-packages\requests\sessions.py", line 742, in get_adapter
    raise InvalidSchema("No connection adapters were found for {!r}".format(url))
requests.exceptions.InvalidSchema: No connection adapters were found for "'https://www.autotrader.com/rest/lsc/crawl/modelyears?searchRadius=0&zip=32216&allListingType=all-cars&makeCode=MB&seriesCode=C_CLASS&modelCode=C63AMG&city=Jacksonville&state=FL&location=%5Bobject+Object%5D&dma=%5Bobject+Object%5D'"
2025-04-28 11:52:33,638 - ERROR - \U0001f6a8 Error processing Carrera S: No connection adapters were found for "'https://www.autotrader.com/rest/lsc/crawl/modelyears?marketExtension=include&mileage=75000&numRecords=24&searchRadius=0&sortBy=derivedpriceASC&startYear=2006&transmissionCode=MAN&zip=32216&allListingType=all-cars&vehicleStyleCode=COUPE&makeCode=POR&modelCode=911&trimCode=911%7CCarrera+S&city=Jacksonville&state=FL&location=%5Bobject+Object%5D&dma=%5Bobject+Object%5D'"
Traceback (most recent call last):
  File "C:\Users\derek\Dropbox (Personal)\Cars\Price Puller Used Cars\Price_Puller.py", line 46, in get_avg_price
    response = session.get(url, headers=headers)
  File "C:\Users\derek\AppData\Local\Programs\Python\Python39\lib\site-packages\requests\sessions.py", line 555, in get
    return self.request('GET', url, **kwargs)
  File "C:\Users\derek\AppData\Local\Programs\Python\Python39\lib\site-packages\requests\sessions.py", line 542, in request
    resp = self.send(prep, **send_kwargs)
  File "C:\Users\derek\AppData\Local\Programs\Python\Python39\lib\site-packages\requests\sessions.py", line 649, in send
    adapter = self.get_adapter(url=request.url)
  File "C:\Users\derek\AppData\Local\Programs\Python\Python39\lib\site-packages\requests\sessions.py", line 742, in get_adapter
    raise InvalidSchema("No connection adapters were found for {!r}".format(url))
requests.exceptions.InvalidSchema: No connection adapters were found for "'https://www.autotrader.com/rest/lsc/crawl/modelyears?marketExtension=include&mileage=75000&numRecords=24&searchRadius=0&sortBy=derivedpriceASC&startYear=2006&transmissionCode=MAN&zip=32216&allListingType=all-cars&vehicleStyleCode=COUPE&makeCode=POR&modelCode=911&trimCode=911%7CCarrera+S&city=Jacksonville&state=FL&location=%5Bobject+Object%5D&dma=%5Bobject+Object%5D'"
2025-04-28 11:52:33,639 - ERROR - \U0001f6a8 Error processing GT3: No connection adapters were found for "'https://www.autotrader.com/rest/lsc/crawl/modelyears?endYear=2024&firstRecord=0&marketExtension=include&numRecords=100&searchRadius=0&sortBy=derivedpriceASC&startYear=2004&zip=32216&makeCode=POR&modelCode=911&trimCode=911%7CGT3&city=Jacksonville&state=FL&location=%5Bobject+Object%5D&dma=%5Bobject+Object%5D&listingType=USED'"
Traceback (most recent call last):
  File "C:\Users\derek\Dropbox (Personal)\Cars\Price Puller Used Cars\Price_Puller.py", line 46, in get_avg_price
    response = session.get(url, headers=headers)
  File "C:\Users\derek\AppData\Local\Programs\Python\Python39\lib\site-packages\requests\sessions.py", line 555, in get
    return self.request('GET', url, **kwargs)
  File "C:\Users\derek\AppData\Local\Programs\Python\Python39\lib\site-packages\requests\sessions.py", line 542, in request
    resp = self.send(prep, **send_kwargs)
  File "C:\Users\derek\AppData\Local\Programs\Python\Python39\lib\site-packages\requests\sessions.py", line 649, in send
    adapter = self.get_adapter(url=request.url)
  File "C:\Users\derek\AppData\Local\Programs\Python\Python39\lib\site-packages\requests\sessions.py", line 742, in get_adapter
    raise InvalidSchema("No connection adapters were found for {!r}".format(url))
requests.exceptions.InvalidSchema: No connection adapters were found for "'https://www.autotrader.com/rest/lsc/crawl/modelyears?endYear=2024&firstRecord=0&marketExtension=include&numRecords=100&searchRadius=0&sortBy=derivedpriceASC&startYear=2004&zip=32216&makeCode=POR&modelCode=911&trimCode=911%7CGT3&city=Jacksonville&state=FL&location=%5Bobject+Object%5D&dma=%5Bobject+Object%5D&listingType=USED'"
2025-04-28 11:52:33,639 - ERROR - \U0001f6a8 Error processing GT3RS: No connection adapters were found for "'https://www.autotrader.com/rest/lsc/crawl/modelyears?searchRadius=0&zip=32216&allListingType=all-cars&makeCode=POR&modelCode=911&trimCode=911%7CGT3+RS&city=Jacksonville&state=FL&location=%5Bobject+Object%5D&dma=%5Bobject+Object%5D'"
Traceback (most recent call last):
  File "C:\Users\derek\Dropbox (Personal)\Cars\Price Puller Used Cars\Price_Puller.py", line 46, in get_avg_price
    response = session.get(url, headers=headers)
  File "C:\Users\derek\AppData\Local\Programs\Python\Python39\lib\site-packages\requests\sessions.py", line 555, in get
    return self.request('GET', url, **kwargs)
  File "C:\Users\derek\AppData\Local\Programs\Python\Python39\lib\site-packages\requests\sessions.py", line 542, in request
    resp = self.send(prep, **send_kwargs)
  File "C:\Users\derek\AppData\Local\Programs\Python\Python39\lib\site-packages\requests\sessions.py", line 649, in send
    adapter = self.get_adapter(url=request.url)
  File "C:\Users\derek\AppData\Local\Programs\Python\Python39\lib\site-packages\requests\sessions.py", line 742, in get_adapter
    raise InvalidSchema("No connection adapters were found for {!r}".format(url))
requests.exceptions.InvalidSchema: No connection adapters were found for "'https://www.autotrader.com/rest/lsc/crawl/modelyears?searchRadius=0&zip=32216&allListingType=all-cars&makeCode=POR&modelCode=911&trimCode=911%7CGT3+RS&city=Jacksonville&state=FL&location=%5Bobject+Object%5D&dma=%5Bobject+Object%5D'"
2025-04-28 11:52:33,640 - ERROR - \U0001f6a8 Error processing GT4: No connection adapters were found for "'https://www.autotrader.com/rest/lsc/crawl/modelyears?searchRadius=0&zip=32216&allListingType=all-cars&makeCode=POR&modelCode=POR718CAY&trimCode=POR718CAY%7CGT4&city=Jacksonville&state=FL&location=%5Bobject+Object%5D&dma=%5Bobject+Object%5D'"
Traceback (most recent call last):
  File "C:\Users\derek\Dropbox (Personal)\Cars\Price Puller Used Cars\Price_Puller.py", line 46, in get_avg_price
    response = session.get(url, headers=headers)
  File "C:\Users\derek\AppData\Local\Programs\Python\Python39\lib\site-packages\requests\sessions.py", line 555, in get
    return self.request('GET', url, **kwargs)
  File "C:\Users\derek\AppData\Local\Programs\Python\Python39\lib\site-packages\requests\sessions.py", line 542, in request
    resp = self.send(prep, **send_kwargs)
  File "C:\Users\derek\AppData\Local\Programs\Python\Python39\lib\site-packages\requests\sessions.py", line 649, in send
    adapter = self.get_adapter(url=request.url)
  File "C:\Users\derek\AppData\Local\Programs\Python\Python39\lib\site-packages\requests\sessions.py", line 742, in get_adapter
    raise InvalidSchema("No connection adapters were found for {!r}".format(url))
requests.exceptions.InvalidSchema: No connection adapters were found for "'https://www.autotrader.com/rest/lsc/crawl/modelyears?searchRadius=0&zip=32216&allListingType=all-cars&makeCode=POR&modelCode=POR718CAY&trimCode=POR718CAY%7CGT4&city=Jacksonville&state=FL&location=%5Bobject+Object%5D&dma=%5Bobject+Object%5D'"
2025-04-28 11:52:33,640 - ERROR - \U0001f6a8 Error processing GT4RS: No connection adapters were found for "'https://www.autotrader.com/rest/lsc/crawl/modelyears?searchRadius=0&zip=32216&allListingType=all-cars&makeCode=POR&modelCode=POR718CAY&trimCode=POR718CAY%7CGT4+RS&city=Jacksonville&state=FL&location=%5Bobject+Object%5D&dma=%5Bobject+Object%5D'"
Traceback (most recent call last):
  File "C:\Users\derek\Dropbox (Personal)\Cars\Price Puller Used Cars\Price_Puller.py", line 46, in get_avg_price
    response = session.get(url, headers=headers)
  File "C:\Users\derek\AppData\Local\Programs\Python\Python39\lib\site-packages\requests\sessions.py", line 555, in get
    return self.request('GET', url, **kwargs)
  File "C:\Users\derek\AppData\Local\Programs\Python\Python39\lib\site-packages\requests\sessions.py", line 542, in request
    resp = self.send(prep, **send_kwargs)
  File "C:\Users\derek\AppData\Local\Programs\Python\Python39\lib\site-packages\requests\sessions.py", line 649, in send
    adapter = self.get_adapter(url=request.url)
  File "C:\Users\derek\AppData\Local\Programs\Python\Python39\lib\site-packages\requests\sessions.py", line 742, in get_adapter
    raise InvalidSchema("No connection adapters were found for {!r}".format(url))
requests.exceptions.InvalidSchema: No connection adapters were found for "'https://www.autotrader.com/rest/lsc/crawl/modelyears?searchRadius=0&zip=32216&allListingType=all-cars&makeCode=POR&modelCode=POR718CAY&trimCode=POR718CAY%7CGT4+RS&city=Jacksonville&state=FL&location=%5Bobject+Object%5D&dma=%5Bobject+Object%5D'"
2025-04-28 11:52:33,641 - ERROR - \U0001f6a8 Error processing Cayenne: No connection adapters were found for "'https://www.autotrader.com/rest/lsc/crawl/modelyears?searchRadius=0&zip=32216&allListingType=all-cars&makeCode=POR&modelCode=CAYENNE&city=Jacksonville&state=FL&location=%5Bobject+Object%5D&dma=%5Bobject+Object%5D'"
Traceback (most recent call last):
  File "C:\Users\derek\Dropbox (Personal)\Cars\Price Puller Used Cars\Price_Puller.py", line 46, in get_avg_price
    response = session.get(url, headers=headers)
  File "C:\Users\derek\AppData\Local\Programs\Python\Python39\lib\site-packages\requests\sessions.py", line 555, in get
    return self.request('GET', url, **kwargs)
  File "C:\Users\derek\AppData\Local\Programs\Python\Python39\lib\site-packages\requests\sessions.py", line 542, in request
    resp = self.send(prep, **send_kwargs)
  File "C:\Users\derek\AppData\Local\Programs\Python\Python39\lib\site-packages\requests\sessions.py", line 649, in send
    adapter = self.get_adapter(url=request.url)
  File "C:\Users\derek\AppData\Local\Programs\Python\Python39\lib\site-packages\requests\sessions.py", line 742, in get_adapter
    raise InvalidSchema("No connection adapters were found for {!r}".format(url))
requests.exceptions.InvalidSchema: No connection adapters were found for "'https://www.autotrader.com/rest/lsc/crawl/modelyears?searchRadius=0&zip=32216&allListingType=all-cars&makeCode=POR&modelCode=CAYENNE&city=Jacksonville&state=FL&location=%5Bobject+Object%5D&dma=%5Bobject+Object%5D'"
2025-04-28 11:52:33,641 - ERROR - \U0001f6a8 Error processing Macan: No connection adapters were found for "'https://www.autotrader.com/rest/lsc/crawl/modelyears?searchRadius=0&zip=32216&allListingType=all-cars&engineCode=6CLDR&makeCode=POR&modelCode=PORMACAN&city=Jacksonville&state=FL&location=%5Bobject+Object%5D&dma=%5Bobject+Object%5D'"
Traceback (most recent call last):
  File "C:\Users\derek\Dropbox (Personal)\Cars\Price Puller Used Cars\Price_Puller.py", line 46, in get_avg_price
    response = session.get(url, headers=headers)
  File "C:\Users\derek\AppData\Local\Programs\Python\Python39\lib\site-packages\requests\sessions.py", line 555, in get
    return self.request('GET', url, **kwargs)
  File "C:\Users\derek\AppData\Local\Programs\Python\Python39\lib\site-packages\requests\sessions.py", line 542, in request
    resp = self.send(prep, **send_kwargs)
  File "C:\Users\derek\AppData\Local\Programs\Python\Python39\lib\site-packages\requests\sessions.py", line 649, in send
    adapter = self.get_adapter(url=request.url)
  File "C:\Users\derek\AppData\Local\Programs\Python\Python39\lib\site-packages\requests\sessions.py", line 742, in get_adapter
    raise InvalidSchema("No connection adapters were found for {!r}".format(url))
requests.exceptions.InvalidSchema: No connection adapters were found for "'https://www.autotrader.com/rest/lsc/crawl/modelyears?searchRadius=0&zip=32216&allListingType=all-cars&engineCode=6CLDR&makeCode=POR&modelCode=PORMACAN&city=Jacksonville&state=FL&location=%5Bobject+Object%5D&dma=%5Bobject+Object%5D'"
2025-04-28 11:52:33,642 - ERROR - \U0001f6a8 Error processing Taycan: No connection adapters were found for "'https://www.autotrader.com/rest/lsc/crawl/modelyears?searchRadius=0&zip=32216&allListingType=all-cars&makeCode=POR&modelCode=PORTAYCAN&trimCode=PORTAYCAN%7CTurbo+S&city=Jacksonville&state=FL&location=%5Bobject+Object%5D&dma=%5Bobject+Object%5D'"
Traceback (most recent call last):
  File "C:\Users\derek\Dropbox (Personal)\Cars\Price Puller Used Cars\Price_Puller.py", line 46, in get_avg_price
    response = session.get(url, headers=headers)
  File "C:\Users\derek\AppData\Local\Programs\Python\Python39\lib\site-packages\requests\sessions.py", line 555, in get
    return self.request('GET', url, **kwargs)
  File "C:\Users\derek\AppData\Local\Programs\Python\Python39\lib\site-packages\requests\sessions.py", line 542, in request
    resp = self.send(prep, **send_kwargs)
  File "C:\Users\derek\AppData\Local\Programs\Python\Python39\lib\site-packages\requests\sessions.py", line 649, in send
    adapter = self.get_adapter(url=request.url)
  File "C:\Users\derek\AppData\Local\Programs\Python\Python39\lib\site-packages\requests\sessions.py", line 742, in get_adapter
    raise InvalidSchema("No connection adapters were found for {!r}".format(url))
requests.exceptions.InvalidSchema: No connection adapters were found for "'https://www.autotrader.com/rest/lsc/crawl/modelyears?searchRadius=0&zip=32216&allListingType=all-cars&makeCode=POR&modelCode=PORTAYCAN&trimCode=PORTAYCAN%7CTurbo+S&city=Jacksonville&state=FL&location=%5Bobject+Object%5D&dma=%5Bobject+Object%5D'"
2025-04-28 11:52:33,642 - ERROR - \U0001f6a8 Error processing BRZ: No connection adapters were found for "'https://www.autotrader.com/rest/lsc/crawl/modelyears?searchRadius=0&sortBy=derivedpriceASC&zip=32216&allListingType=all-cars&makeCode=SUB&modelCode=SUBBRZ&city=Jacksonville&state=FL&location=%5Bobject+Object%5D&dma=%5Bobject+Object%5D'"
Traceback (most recent call last):
  File "C:\Users\derek\Dropbox (Personal)\Cars\Price Puller Used Cars\Price_Puller.py", line 46, in get_avg_price
    response = session.get(url, headers=headers)
  File "C:\Users\derek\AppData\Local\Programs\Python\Python39\lib\site-packages\requests\sessions.py", line 555, in get
    return self.request('GET', url, **kwargs)
  File "C:\Users\derek\AppData\Local\Programs\Python\Python39\lib\site-packages\requests\sessions.py", line 542, in request
    resp = self.send(prep, **send_kwargs)
  File "C:\Users\derek\AppData\Local\Programs\Python\Python39\lib\site-packages\requests\sessions.py", line 649, in send
    adapter = self.get_adapter(url=request.url)
  File "C:\Users\derek\AppData\Local\Programs\Python\Python39\lib\site-packages\requests\sessions.py", line 742, in get_adapter
    raise InvalidSchema("No connection adapters were found for {!r}".format(url))
requests.exceptions.InvalidSchema: No connection adapters were found for "'https://www.autotrader.com/rest/lsc/crawl/modelyears?searchRadius=0&sortBy=derivedpriceASC&zip=32216&allListingType=all-cars&makeCode=SUB&modelCode=SUBBRZ&city=Jacksonville&state=FL&location=%5Bobject+Object%5D&dma=%5Bobject+Object%5D'"
2025-04-28 11:52:33,643 - ERROR - \U0001f6a8 Error processing CyberTruck: No connection adapters were found for "'https://www.autotrader.com/rest/lsc/crawl/modelyears?searchRadius=0&zip=32216&allListingType=all-cars&makeCode=TESLA&modelCode=TESCYBERTR&city=Jacksonville&state=FL&location=%5Bobject+Object%5D&dma=%5Bobject+Object%5D'"
Traceback (most recent call last):
  File "C:\Users\derek\Dropbox (Personal)\Cars\Price Puller Used Cars\Price_Puller.py", line 46, in get_avg_price
    response = session.get(url, headers=headers)
  File "C:\Users\derek\AppData\Local\Programs\Python\Python39\lib\site-packages\requests\sessions.py", line 555, in get
    return self.request('GET', url, **kwargs)
  File "C:\Users\derek\AppData\Local\Programs\Python\Python39\lib\site-packages\requests\sessions.py", line 542, in request
    resp = self.send(prep, **send_kwargs)
  File "C:\Users\derek\AppData\Local\Programs\Python\Python39\lib\site-packages\requests\sessions.py", line 649, in send
    adapter = self.get_adapter(url=request.url)
  File "C:\Users\derek\AppData\Local\Programs\Python\Python39\lib\site-packages\requests\sessions.py", line 742, in get_adapter
    raise InvalidSchema("No connection adapters were found for {!r}".format(url))
requests.exceptions.InvalidSchema: No connection adapters were found for "'https://www.autotrader.com/rest/lsc/crawl/modelyears?searchRadius=0&zip=32216&allListingType=all-cars&makeCode=TESLA&modelCode=TESCYBERTR&city=Jacksonville&state=FL&location=%5Bobject+Object%5D&dma=%5Bobject+Object%5D'"
2025-04-28 11:52:33,643 - ERROR - \U0001f6a8 Error processing Model 3: No connection adapters were found for "'https://www.autotrader.com/rest/lsc/crawl/modelyears?searchRadius=0&sortBy=derivedpriceASC&zip=02861&allListingType=all-cars&makeCode=TESLA&modelCode=TESMOD3&trimCode=TESMOD3%7CPerformance&city=Pawtucket&state=RI&location=%5Bobject+Object%5D&dma=%5Bobject+Object%5D'"
Traceback (most recent call last):
  File "C:\Users\derek\Dropbox (Personal)\Cars\Price Puller Used Cars\Price_Puller.py", line 46, in get_avg_price
    response = session.get(url, headers=headers)
  File "C:\Users\derek\AppData\Local\Programs\Python\Python39\lib\site-packages\requests\sessions.py", line 555, in get
    return self.request('GET', url, **kwargs)
  File "C:\Users\derek\AppData\Local\Programs\Python\Python39\lib\site-packages\requests\sessions.py", line 542, in request
    resp = self.send(prep, **send_kwargs)
  File "C:\Users\derek\AppData\Local\Programs\Python\Python39\lib\site-packages\requests\sessions.py", line 649, in send
    adapter = self.get_adapter(url=request.url)
  File "C:\Users\derek\AppData\Local\Programs\Python\Python39\lib\site-packages\requests\sessions.py", line 742, in get_adapter
    raise InvalidSchema("No connection adapters were found for {!r}".format(url))
requests.exceptions.InvalidSchema: No connection adapters were found for "'https://www.autotrader.com/rest/lsc/crawl/modelyears?searchRadius=0&sortBy=derivedpriceASC&zip=02861&allListingType=all-cars&makeCode=TESLA&modelCode=TESMOD3&trimCode=TESMOD3%7CPerformance&city=Pawtucket&state=RI&location=%5Bobject+Object%5D&dma=%5Bobject+Object%5D'"
2025-04-28 11:52:33,644 - ERROR - \U0001f6a8 Error processing Model X: No connection adapters were found for "'https://www.autotrader.com/rest/lsc/crawl/modelyears?searchRadius=0&sortBy=derivedpriceASC&zip=02861&allListingType=all-cars&makeCode=TESLA&modelCode=TESMODX&trimCode=TESMODX%7CP100D&city=Pawtucket&state=RI&location=%5Bobject+Object%5D&dma=%5Bobject+Object%5D'"
Traceback (most recent call last):
  File "C:\Users\derek\Dropbox (Personal)\Cars\Price Puller Used Cars\Price_Puller.py", line 46, in get_avg_price
    response = session.get(url, headers=headers)
  File "C:\Users\derek\AppData\Local\Programs\Python\Python39\lib\site-packages\requests\sessions.py", line 555, in get
    return self.request('GET', url, **kwargs)
  File "C:\Users\derek\AppData\Local\Programs\Python\Python39\lib\site-packages\requests\sessions.py", line 542, in request
    resp = self.send(prep, **send_kwargs)
  File "C:\Users\derek\AppData\Local\Programs\Python\Python39\lib\site-packages\requests\sessions.py", line 649, in send
    adapter = self.get_adapter(url=request.url)
  File "C:\Users\derek\AppData\Local\Programs\Python\Python39\lib\site-packages\requests\sessions.py", line 742, in get_adapter
    raise InvalidSchema("No connection adapters were found for {!r}".format(url))
requests.exceptions.InvalidSchema: No connection adapters were found for "'https://www.autotrader.com/rest/lsc/crawl/modelyears?searchRadius=0&sortBy=derivedpriceASC&zip=02861&allListingType=all-cars&makeCode=TESLA&modelCode=TESMODX&trimCode=TESMODX%7CP100D&city=Pawtucket&state=RI&location=%5Bobject+Object%5D&dma=%5Bobject+Object%5D'"
2025-04-28 11:52:33,644 - ERROR - \U0001f6a8 Error processing Model Y: No connection adapters were found for "'https://www.autotrader.com/rest/lsc/crawl/modelyears?searchRadius=0&zip=32216&allListingType=all-cars&makeCode=TESLA&modelCode=TESMODY&city=Jacksonville&state=FL&location=%5Bobject+Object%5D&dma=%5Bobject+Object%5D'"
Traceback (most recent call last):
  File "C:\Users\derek\Dropbox (Personal)\Cars\Price Puller Used Cars\Price_Puller.py", line 46, in get_avg_price
    response = session.get(url, headers=headers)
  File "C:\Users\derek\AppData\Local\Programs\Python\Python39\lib\site-packages\requests\sessions.py", line 555, in get
    return self.request('GET', url, **kwargs)
  File "C:\Users\derek\AppData\Local\Programs\Python\Python39\lib\site-packages\requests\sessions.py", line 542, in request
    resp = self.send(prep, **send_kwargs)
  File "C:\Users\derek\AppData\Local\Programs\Python\Python39\lib\site-packages\requests\sessions.py", line 649, in send
    adapter = self.get_adapter(url=request.url)
  File "C:\Users\derek\AppData\Local\Programs\Python\Python39\lib\site-packages\requests\sessions.py", line 742, in get_adapter
    raise InvalidSchema("No connection adapters were found for {!r}".format(url))
requests.exceptions.InvalidSchema: No connection adapters were found for "'https://www.autotrader.com/rest/lsc/crawl/modelyears?searchRadius=0&zip=32216&allListingType=all-cars&makeCode=TESLA&modelCode=TESMODY&city=Jacksonville&state=FL&location=%5Bobject+Object%5D&dma=%5Bobject+Object%5D'"
2025-04-28 11:52:33,645 - ERROR - \U0001f6a8 Error processing Model S: No connection adapters were found for "'https://www.autotrader.com/rest/lsc/crawl/modelyears?searchRadius=0&zip=32216&allListingType=all-cars&makeCode=POR&modelCode=PORTAYCAN&trimCode=PORTAYCAN%7CTurbo+S&city=Jacksonville&state=FL&location=%5Bobject+Object%5D&dma=%5Bobject+Object%5D'"
Traceback (most recent call last):
  File "C:\Users\derek\Dropbox (Personal)\Cars\Price Puller Used Cars\Price_Puller.py", line 46, in get_avg_price
    response = session.get(url, headers=headers)
  File "C:\Users\derek\AppData\Local\Programs\Python\Python39\lib\site-packages\requests\sessions.py", line 555, in get
    return self.request('GET', url, **kwargs)
  File "C:\Users\derek\AppData\Local\Programs\Python\Python39\lib\site-packages\requests\sessions.py", line 542, in request
    resp = self.send(prep, **send_kwargs)
  File "C:\Users\derek\AppData\Local\Programs\Python\Python39\lib\site-packages\requests\sessions.py", line 649, in send
    adapter = self.get_adapter(url=request.url)
  File "C:\Users\derek\AppData\Local\Programs\Python\Python39\lib\site-packages\requests\sessions.py", line 742, in get_adapter
    raise InvalidSchema("No connection adapters were found for {!r}".format(url))
requests.exceptions.InvalidSchema: No connection adapters were found for "'https://www.autotrader.com/rest/lsc/crawl/modelyears?searchRadius=0&zip=32216&allListingType=all-cars&makeCode=POR&modelCode=PORTAYCAN&trimCode=PORTAYCAN%7CTurbo+S&city=Jacksonville&state=FL&location=%5Bobject+Object%5D&dma=%5Bobject+Object%5D'"
2025-04-28 11:56:47,471 - INFO - \u2705 Loaded 36 URLs from car_urls.txt
2025-04-28 11:56:47,952 - INFO - \u2705 Successfully updated and saved sheet 'R8' for 28APR2025
2025-04-28 11:56:48,231 - INFO - \u2705 Successfully updated and saved sheet 'RS4' for 28APR2025
2025-04-28 11:56:48,563 - INFO - \u2705 Successfully updated and saved sheet 'S4' for 28APR2025
2025-04-28 11:56:48,831 - INFO - \u2705 Successfully updated and saved sheet 'Q5' for 28APR2025
2025-04-28 11:56:49,112 - INFO - \u2705 Successfully updated and saved sheet 'RS7' for 28APR2025
2025-04-28 11:56:49,405 - INFO - \u2705 Successfully updated and saved sheet 'Etron' for 28APR2025
2025-04-28 11:56:49,750 - INFO - \u2705 Successfully updated and saved sheet 'M3' for 28APR2025
2025-04-28 11:56:50,095 - INFO - \u2705 Successfully updated and saved sheet 'M5' for 28APR2025
2025-04-28 11:56:50,393 - INFO - \u2705 Successfully updated and saved sheet 'Corvette Z06' for 28APR2025
2025-04-28 11:56:50,658 - INFO - \u2705 Successfully updated and saved sheet 'Corvette ZR1' for 28APR2025
2025-04-28 11:56:50,924 - INFO - \u2705 Successfully updated and saved sheet '458 Italia' for 28APR2025
2025-04-28 11:56:51,219 - INFO - \u2705 Successfully updated and saved sheet 'F250' for 28APR2025
2025-04-28 11:56:51,503 - INFO - \u2705 Successfully updated and saved sheet 'GT' for 28APR2025
2025-04-28 11:56:51,769 - INFO - \u2705 Successfully updated and saved sheet 'S2000' for 28APR2025
2025-04-28 11:56:52,097 - INFO - \u2705 Successfully updated and saved sheet 'Wrangler' for 28APR2025
2025-04-28 11:56:52,392 - INFO - \u2705 Successfully updated and saved sheet 'Aventador' for 28APR2025
2025-04-28 11:56:52,687 - INFO - \u2705 Successfully updated and saved sheet 'Gallardo' for 28APR2025
2025-04-28 11:56:52,958 - INFO - \u2705 Successfully updated and saved sheet 'Huracan' for 28APR2025
2025-04-28 11:56:53,288 - INFO - \u2705 Successfully updated and saved sheet 'Murcielago' for 28APR2025
2025-04-28 11:56:53,552 - INFO - \u2705 Successfully updated and saved sheet 'Urus' for 28APR2025
2025-04-28 11:56:53,864 - INFO - \u2705 Successfully updated and saved sheet 'AMG' for 28APR2025
2025-04-28 11:56:54,159 - INFO - \u2705 Successfully updated and saved sheet 'C63 AMG' for 28APR2025
2025-04-28 11:56:54,435 - INFO - \u2705 Successfully updated and saved sheet 'Carrera S' for 28APR2025
2025-04-28 11:56:54,726 - INFO - \u2705 Successfully updated and saved sheet 'GT3' for 28APR2025
2025-04-28 11:56:54,991 - INFO - \u2705 Successfully updated and saved sheet 'GT3RS' for 28APR2025
2025-04-28 11:56:55,253 - INFO - \u2705 Successfully updated and saved sheet 'GT4' for 28APR2025
2025-04-28 11:56:55,524 - INFO - \u2705 Successfully updated and saved sheet 'GT4RS' for 28APR2025
2025-04-28 11:56:55,977 - INFO - \u2705 Successfully updated and saved sheet 'Cayenne' for 28APR2025
2025-04-28 11:56:56,302 - INFO - \u2705 Successfully updated and saved sheet 'Macan' for 28APR2025
2025-04-28 11:56:56,618 - INFO - \u2705 Successfully updated and saved sheet 'Taycan' for 28APR2025
2025-04-28 11:56:56,978 - INFO - \u2705 Successfully updated and saved sheet 'BRZ' for 28APR2025
2025-04-28 11:56:57,270 - INFO - \u2705 Successfully updated and saved sheet 'CyberTruck' for 28APR2025
2025-04-28 11:56:57,551 - INFO - \u2705 Successfully updated and saved sheet 'Model 3' for 28APR2025
2025-04-28 11:56:57,864 - INFO - \u2705 Successfully updated and saved sheet 'Model X' for 28APR2025
2025-04-28 11:56:58,163 - INFO - \u2705 Successfully updated and saved sheet 'Model Y' for 28APR2025
2025-04-28 11:56:58,444 - INFO - \u2705 Successfully updated and saved sheet 'Model S' for 28APR2025
2025-04-28 11:58:40,179 - INFO - \u2705 Loaded 36 URLs from car_urls.txt
2025-04-28 11:58:40,503 - INFO - \u2705 Successfully updated and saved sheet 'R8' for 28APR2025
2025-04-28 11:58:40,785 - INFO - \u2705 Successfully updated and saved sheet 'RS4' for 28APR2025
2025-04-28 11:58:41,098 - INFO - \u2705 Successfully updated and saved sheet 'S4' for 28APR2025
2025-04-28 11:58:41,385 - INFO - \u2705 Successfully updated and saved sheet 'Q5' for 28APR2025
2025-04-28 11:58:41,692 - INFO - \u2705 Successfully updated and saved sheet 'RS7' for 28APR2025
2025-04-28 11:58:41,989 - INFO - \u2705 Successfully updated and saved sheet 'Etron' for 28APR2025
2025-04-28 11:58:42,245 - INFO - \u2705 Successfully updated and saved sheet 'M3' for 28APR2025
2025-04-28 11:58:42,620 - INFO - \u2705 Successfully updated and saved sheet 'M5' for 28APR2025
2025-04-28 11:58:42,954 - INFO - \u2705 Successfully updated and saved sheet 'Corvette Z06' for 28APR2025
2025-04-28 11:58:43,217 - INFO - \u2705 Successfully updated and saved sheet 'Corvette ZR1' for 28APR2025
2025-04-28 11:58:43,522 - INFO - \u2705 Successfully updated and saved sheet '458 Italia' for 28APR2025
2025-04-28 11:58:43,865 - INFO - \u2705 Successfully updated and saved sheet 'F250' for 28APR2025
2025-04-28 11:58:44,132 - INFO - \u2705 Successfully updated and saved sheet 'GT' for 28APR2025
2025-04-28 11:58:44,445 - INFO - \u2705 Successfully updated and saved sheet 'S2000' for 28APR2025
2025-04-28 11:58:44,742 - INFO - \u2705 Successfully updated and saved sheet 'Wrangler' for 28APR2025
2025-04-28 11:58:45,055 - INFO - \u2705 Successfully updated and saved sheet 'Aventador' for 28APR2025
2025-04-28 11:58:45,380 - INFO - \u2705 Successfully updated and saved sheet 'Gallardo' for 28APR2025
2025-04-28 11:58:45,805 - INFO - \u2705 Successfully updated and saved sheet 'Huracan' for 28APR2025
2025-04-28 11:58:46,138 - INFO - \u2705 Successfully updated and saved sheet 'Murcielago' for 28APR2025
2025-04-28 11:58:46,466 - INFO - \u2705 Successfully updated and saved sheet 'Urus' for 28APR2025
2025-04-28 11:58:46,853 - INFO - \u2705 Successfully updated and saved sheet 'AMG' for 28APR2025
2025-04-28 11:58:47,188 - INFO - \u2705 Successfully updated and saved sheet 'C63 AMG' for 28APR2025
2025-04-28 11:58:47,573 - INFO - \u2705 Successfully updated and saved sheet 'Carrera S' for 28APR2025
2025-04-28 11:58:47,901 - INFO - \u2705 Successfully updated and saved sheet 'GT3' for 28APR2025
2025-04-28 11:58:48,250 - INFO - \u2705 Successfully updated and saved sheet 'GT3RS' for 28APR2025
2025-04-28 11:58:48,542 - INFO - \u2705 Successfully updated and saved sheet 'GT4' for 28APR2025
2025-04-28 11:58:48,855 - INFO - \u2705 Successfully updated and saved sheet 'GT4RS' for 28APR2025
2025-04-28 11:58:49,237 - INFO - \u2705 Successfully updated and saved sheet 'Cayenne' for 28APR2025
2025-04-28 11:58:49,591 - INFO - \u2705 Successfully updated and saved sheet 'Macan' for 28APR2025
2025-04-28 11:58:49,888 - INFO - \u2705 Successfully updated and saved sheet 'Taycan' for 28APR2025
2025-04-28 11:58:50,237 - INFO - \u2705 Successfully updated and saved sheet 'BRZ' for 28APR2025
2025-04-28 11:58:50,550 - INFO - \u2705 Successfully updated and saved sheet 'CyberTruck' for 28APR2025
2025-04-28 11:58:50,890 - INFO - \u2705 Successfully updated and saved sheet 'Model 3' for 28APR2025
2025-04-28 11:58:51,239 - INFO - \u2705 Successfully updated and saved sheet 'Model X' for 28APR2025
2025-04-28 11:58:51,603 - INFO - \u2705 Successfully updated and saved sheet 'Model Y' for 28APR2025
2025-04-28 11:58:51,889 - INFO - \u2705 Successfully updated and saved sheet 'Model S' for 28APR2025
2025-04-28 12:00:25,667 - INFO - \u2705 Loaded 37 URLs from car_urls.txt
2025-04-28 12:00:26,103 - INFO - \u2705 Successfully updated and saved sheet 'R8' for 28APR2025
2025-04-28 12:00:26,470 - INFO - \u2705 Successfully updated and saved sheet 'RS4' for 28APR2025
2025-04-28 12:00:26,791 - INFO - \u2705 Successfully updated and saved sheet 'S4' for 28APR2025
2025-04-28 12:00:27,123 - INFO - \u2705 Successfully updated and saved sheet 'Q5' for 28APR2025
2025-04-28 12:00:27,450 - INFO - \u2705 Successfully updated and saved sheet 'RS7' for 28APR2025
2025-04-28 12:00:27,835 - INFO - \u2705 Successfully updated and saved sheet 'Etron' for 28APR2025
2025-04-28 12:00:28,166 - INFO - \u2705 Successfully updated and saved sheet 'M3' for 28APR2025
2025-04-28 12:00:28,525 - INFO - \u2705 Successfully updated and saved sheet 'M5' for 28APR2025
2025-04-28 12:00:28,873 - INFO - \u2705 Successfully updated and saved sheet 'Corvette Z06' for 28APR2025
2025-04-28 12:00:29,184 - INFO - \u2705 Successfully updated and saved sheet 'Corvette ZR1' for 28APR2025
2025-04-28 12:00:29,496 - INFO - \u2705 Successfully updated and saved sheet '458 Italia' for 28APR2025
2025-04-28 12:00:29,841 - INFO - \u2705 Successfully updated and saved sheet 'F250' for 28APR2025
2025-04-28 12:00:30,186 - INFO - \u2705 Successfully updated and saved sheet 'GT' for 28APR2025
2025-04-28 12:00:30,498 - INFO - \u2705 Successfully updated and saved sheet 'S2000' for 28APR2025
2025-04-28 12:00:30,922 - INFO - \u2705 Successfully updated and saved sheet 'Wrangler' for 28APR2025
2025-04-28 12:00:31,249 - INFO - \u2705 Successfully updated and saved sheet 'Aventador' for 28APR2025
2025-04-28 12:00:31,593 - INFO - \u2705 Successfully updated and saved sheet 'Gallardo' for 28APR2025
2025-04-28 12:00:31,955 - INFO - \u2705 Successfully updated and saved sheet 'Huracan' for 28APR2025
2025-04-28 12:00:32,281 - INFO - \u2705 Successfully updated and saved sheet 'Murcielago' for 28APR2025
2025-04-28 12:00:32,609 - INFO - \u2705 Successfully updated and saved sheet 'Urus' for 28APR2025
2025-04-28 12:00:32,940 - INFO - \u2705 Successfully updated and saved sheet 'AMG' for 28APR2025
2025-04-28 12:00:33,267 - INFO - \u2705 Successfully updated and saved sheet 'C63 AMG' for 28APR2025
2025-04-28 12:00:33,580 - INFO - \u2705 Successfully updated and saved sheet 'Carrera S' for 28APR2025
2025-04-28 12:00:33,910 - INFO - \u2705 Successfully updated and saved sheet 'GT3' for 28APR2025
2025-04-28 12:00:34,236 - INFO - \u2705 Successfully updated and saved sheet 'GT3RS' for 28APR2025
2025-04-28 12:00:34,548 - INFO - \u2705 Successfully updated and saved sheet 'GT4' for 28APR2025
2025-04-28 12:00:34,888 - INFO - \u2705 Successfully updated and saved sheet 'GT4RS' for 28APR2025
2025-04-28 12:00:35,225 - INFO - \u2705 Successfully updated and saved sheet 'Cayenne' for 28APR2025
2025-04-28 12:00:35,534 - INFO - \u2705 Successfully updated and saved sheet 'Macan' for 28APR2025
2025-04-28 12:00:35,928 - INFO - \u2705 Successfully updated and saved sheet 'Taycan' for 28APR2025
2025-04-28 12:00:36,247 - INFO - \u2705 Successfully updated and saved sheet 'BRZ' for 28APR2025
2025-04-28 12:00:36,613 - INFO - \u2705 Successfully updated and saved sheet 'CyberTruck' for 28APR2025
2025-04-28 12:00:36,960 - INFO - \u2705 Successfully updated and saved sheet 'Model 3' for 28APR2025
2025-04-28 12:00:37,283 - INFO - \u2705 Successfully updated and saved sheet 'Model X' for 28APR2025
2025-04-28 12:00:37,614 - INFO - \u2705 Successfully updated and saved sheet 'Model Y' for 28APR2025
2025-04-28 12:00:37,929 - INFO - \u2705 Successfully updated and saved sheet 'Model S' for 28APR2025
2025-04-28 12:00:38,287 - INFO - \u2705 Successfully updated and saved sheet 'RAV4' for 28APR2025
2025-04-28 12:54:46,661 - INFO - \u2705 Loaded 38 URLs from car_urls.txt
2025-04-28 12:54:47,385 - INFO - \u2705 Successfully updated and saved sheet 'R8' for 28APR2025
2025-04-28 12:54:48,074 - INFO - \u2705 Successfully updated and saved sheet 'RS4' for 28APR2025
2025-04-28 12:54:48,776 - INFO - \u2705 Successfully updated and saved sheet 'S4' for 28APR2025
2025-04-28 12:54:49,533 - INFO - \u2705 Successfully updated and saved sheet 'Q5' for 28APR2025
2025-04-28 12:54:50,215 - INFO - \u2705 Successfully updated and saved sheet 'RS7' for 28APR2025
2025-04-28 12:54:50,970 - INFO - \u2705 Successfully updated and saved sheet 'Etron' for 28APR2025
2025-04-28 12:54:51,725 - INFO - \u2705 Successfully updated and saved sheet 'M3' for 28APR2025
2025-04-28 12:54:52,689 - INFO - \u2705 Successfully updated and saved sheet 'M5' for 28APR2025
2025-04-28 12:54:53,475 - INFO - \u2705 Successfully updated and saved sheet 'Corvette Z06' for 28APR2025
2025-04-28 12:54:54,154 - INFO - \u2705 Successfully updated and saved sheet 'Corvette ZR1' for 28APR2025
2025-04-28 12:54:54,801 - INFO - \u2705 Successfully updated and saved sheet '458 Italia' for 28APR2025
2025-04-28 12:54:55,612 - INFO - \u2705 Successfully updated and saved sheet 'F250' for 28APR2025
2025-04-28 12:54:56,328 - INFO - \u2705 Successfully updated and saved sheet 'GT' for 28APR2025
2025-04-28 12:54:57,163 - INFO - \u2705 Successfully updated and saved sheet 'Accord' for 28APR2025
2025-04-28 12:54:57,986 - INFO - \u2705 Successfully updated and saved sheet 'S2000' for 28APR2025
2025-04-28 12:54:58,726 - INFO - \u2705 Successfully updated and saved sheet 'Wrangler' for 28APR2025
2025-04-28 12:54:59,631 - INFO - \u2705 Successfully updated and saved sheet 'Aventador' for 28APR2025
2025-04-28 12:55:00,382 - INFO - \u2705 Successfully updated and saved sheet 'Gallardo' for 28APR2025
2025-04-28 12:55:01,133 - INFO - \u2705 Successfully updated and saved sheet 'Huracan' for 28APR2025
2025-04-28 12:55:01,821 - INFO - \u2705 Successfully updated and saved sheet 'Murcielago' for 28APR2025
2025-04-28 12:55:02,562 - INFO - \u2705 Successfully updated and saved sheet 'Urus' for 28APR2025
2025-04-28 12:55:03,264 - INFO - \u2705 Successfully updated and saved sheet 'AMG' for 28APR2025
2025-04-28 12:55:04,051 - INFO - \u2705 Successfully updated and saved sheet 'C63 AMG' for 28APR2025
2025-04-28 12:55:04,825 - INFO - \u2705 Successfully updated and saved sheet 'Carrera S' for 28APR2025
2025-04-28 12:55:05,573 - INFO - \u2705 Successfully updated and saved sheet 'GT3' for 28APR2025
2025-04-28 12:55:06,439 - INFO - \u2705 Successfully updated and saved sheet 'GT3RS' for 28APR2025
2025-04-28 12:55:07,186 - INFO - \u2705 Successfully updated and saved sheet 'GT4' for 28APR2025
2025-04-28 12:55:08,329 - INFO - \u2705 Successfully updated and saved sheet 'GT4RS' for 28APR2025
2025-04-28 12:55:09,138 - INFO - \u2705 Successfully updated and saved sheet 'Cayenne' for 28APR2025
2025-04-28 12:55:09,901 - INFO - \u2705 Successfully updated and saved sheet 'Macan' for 28APR2025
2025-04-28 12:55:11,078 - INFO - \u2705 Successfully updated and saved sheet 'Taycan' for 28APR2025
2025-04-28 12:55:11,762 - INFO - \u2705 Successfully updated and saved sheet 'BRZ' for 28APR2025
2025-04-28 12:55:12,391 - INFO - \u2705 Successfully updated and saved sheet 'CyberTruck' for 28APR2025
2025-04-28 12:55:13,106 - INFO - \u2705 Successfully updated and saved sheet 'Model 3' for 28APR2025
2025-04-28 12:55:13,754 - INFO - \u2705 Successfully updated and saved sheet 'Model X' for 28APR2025
2025-04-28 12:55:14,610 - INFO - \u2705 Successfully updated and saved sheet 'Model Y' for 28APR2025
2025-04-28 12:55:15,275 - INFO - \u2705 Successfully updated and saved sheet 'Model S' for 28APR2025
2025-04-28 12:55:16,022 - INFO - \u2705 Successfully updated and saved sheet 'RAV4' for 28APR2025
2025-04-28 13:10:03,533 - INFO - \u2705 Loaded 38 URLs from car_urls.txt
2025-04-28 13:10:04,246 - INFO - \u2705 Successfully updated sheet 'R8' for 28APR2025
2025-04-28 13:10:04,898 - INFO - \u2705 Successfully updated sheet 'RS4' for 28APR2025
2025-04-28 13:10:05,537 - INFO - \u2705 Successfully updated sheet 'S4' for 28APR2025
2025-04-28 13:10:06,201 - INFO - \u2705 Successfully updated sheet 'Q5' for 28APR2025
2025-04-28 13:10:06,801 - INFO - \u2705 Successfully updated sheet 'RS7' for 28APR2025
2025-04-28 13:10:07,445 - INFO - \u2705 Successfully updated sheet 'Etron' for 28APR2025
2025-04-28 13:10:08,049 - INFO - \u2705 Successfully updated sheet 'M3' for 28APR2025
2025-04-28 13:10:08,719 - INFO - \u2705 Successfully updated sheet 'M5' for 28APR2025
2025-04-28 13:10:09,350 - INFO - \u2705 Successfully updated sheet 'Corvette Z06' for 28APR2025
2025-04-28 13:10:09,953 - INFO - \u2705 Successfully updated sheet 'Corvette ZR1' for 28APR2025
2025-04-28 13:10:10,660 - INFO - \u2705 Successfully updated sheet '458 Italia' for 28APR2025
2025-04-28 13:10:11,318 - INFO - \u2705 Successfully updated sheet 'F250' for 28APR2025
2025-04-28 13:10:11,960 - INFO - \u2705 Successfully updated sheet 'GT' for 28APR2025
2025-04-28 13:10:12,614 - INFO - \u2705 Successfully updated sheet 'Accord' for 28APR2025
2025-04-28 13:10:13,232 - INFO - \u2705 Successfully updated sheet 'S2000' for 28APR2025
2025-04-28 13:10:13,908 - INFO - \u2705 Successfully updated sheet 'Wrangler' for 28APR2025
2025-04-28 13:10:14,571 - INFO - \u2705 Successfully updated sheet 'Aventador' for 28APR2025
2025-04-28 13:10:15,467 - INFO - \u2705 Successfully updated sheet 'Gallardo' for 28APR2025
2025-04-28 13:10:16,092 - INFO - \u2705 Successfully updated sheet 'Huracan' for 28APR2025
2025-04-28 13:10:16,717 - INFO - \u2705 Successfully updated sheet 'Murcielago' for 28APR2025
2025-04-28 13:10:17,318 - INFO - \u2705 Successfully updated sheet 'Urus' for 28APR2025
2025-04-28 13:10:17,960 - INFO - \u2705 Successfully updated sheet 'AMG' for 28APR2025
2025-04-28 13:10:18,750 - INFO - \u2705 Successfully updated sheet 'C63 AMG' for 28APR2025
2025-04-28 13:10:19,450 - INFO - \u2705 Successfully updated sheet 'Carrera S' for 28APR2025
2025-04-28 13:10:20,301 - INFO - \u2705 Successfully updated sheet 'GT3' for 28APR2025
2025-04-28 13:10:21,085 - INFO - \u2705 Successfully updated sheet 'GT3RS' for 28APR2025
2025-04-28 13:10:21,859 - INFO - \u2705 Successfully updated sheet 'GT4' for 28APR2025
2025-04-28 13:10:22,638 - INFO - \u2705 Successfully updated sheet 'GT4RS' for 28APR2025
2025-04-28 13:10:23,360 - INFO - \u2705 Successfully updated sheet 'Cayenne' for 28APR2025
2025-04-28 13:10:24,038 - INFO - \u2705 Successfully updated sheet 'Macan' for 28APR2025
2025-04-28 13:10:24,739 - INFO - \u2705 Successfully updated sheet 'Taycan' for 28APR2025
2025-04-28 13:10:25,389 - INFO - \u2705 Successfully updated sheet 'BRZ' for 28APR2025
2025-04-28 13:10:26,056 - INFO - \u2705 Successfully updated sheet 'CyberTruck' for 28APR2025
2025-04-28 13:10:26,747 - INFO - \u2705 Successfully updated sheet 'Model 3' for 28APR2025
2025-04-28 13:10:27,474 - INFO - \u2705 Successfully updated sheet 'Model X' for 28APR2025
2025-04-28 13:10:28,171 - INFO - \u2705 Successfully updated sheet 'Model Y' for 28APR2025
2025-04-28 13:10:28,869 - INFO - \u2705 Successfully updated sheet 'Model S' for 28APR2025
2025-04-28 13:10:29,554 - INFO - \u2705 Successfully updated sheet 'RAV4' for 28APR2025
2025-04-28 13:16:55,972 - INFO - \u2705 Loaded 38 URLs from car_urls.txt
2025-04-28 13:16:56,351 - ERROR - \U0001f6a8 Error processing R8: [Errno 13] Permission denied: 'Price_Puller.xlsx'
Traceback (most recent call last):
  File "C:\Users\derek\Dropbox (Personal)\Cars\Price Puller Used Cars\Price_Puller.py", line 135, in get_avg_price
    wb.save(output_file)
  File "C:\Users\derek\AppData\Local\Programs\Python\Python39\lib\site-packages\openpyxl\workbook\workbook.py", line 386, in save
    save_workbook(self, filename)
  File "C:\Users\derek\AppData\Local\Programs\Python\Python39\lib\site-packages\openpyxl\writer\excel.py", line 291, in save_workbook
    archive = ZipFile(filename, 'w', ZIP_DEFLATED, allowZip64=True)
  File "C:\Users\derek\AppData\Local\Programs\Python\Python39\lib\zipfile.py", line 1239, in __init__
    self.fp = io.open(file, filemode)
PermissionError: [Errno 13] Permission denied: 'Price_Puller.xlsx'
2025-04-28 13:16:56,690 - ERROR - \U0001f6a8 Error processing RS4: [Errno 13] Permission denied: 'Price_Puller.xlsx'
Traceback (most recent call last):
  File "C:\Users\derek\Dropbox (Personal)\Cars\Price Puller Used Cars\Price_Puller.py", line 135, in get_avg_price
    wb.save(output_file)
  File "C:\Users\derek\AppData\Local\Programs\Python\Python39\lib\site-packages\openpyxl\workbook\workbook.py", line 386, in save
    save_workbook(self, filename)
  File "C:\Users\derek\AppData\Local\Programs\Python\Python39\lib\site-packages\openpyxl\writer\excel.py", line 291, in save_workbook
    archive = ZipFile(filename, 'w', ZIP_DEFLATED, allowZip64=True)
  File "C:\Users\derek\AppData\Local\Programs\Python\Python39\lib\zipfile.py", line 1239, in __init__
    self.fp = io.open(file, filemode)
PermissionError: [Errno 13] Permission denied: 'Price_Puller.xlsx'
2025-04-28 13:16:57,005 - ERROR - \U0001f6a8 Error processing S4: [Errno 13] Permission denied: 'Price_Puller.xlsx'
Traceback (most recent call last):
  File "C:\Users\derek\Dropbox (Personal)\Cars\Price Puller Used Cars\Price_Puller.py", line 135, in get_avg_price
    wb.save(output_file)
  File "C:\Users\derek\AppData\Local\Programs\Python\Python39\lib\site-packages\openpyxl\workbook\workbook.py", line 386, in save
    save_workbook(self, filename)
  File "C:\Users\derek\AppData\Local\Programs\Python\Python39\lib\site-packages\openpyxl\writer\excel.py", line 291, in save_workbook
    archive = ZipFile(filename, 'w', ZIP_DEFLATED, allowZip64=True)
  File "C:\Users\derek\AppData\Local\Programs\Python\Python39\lib\zipfile.py", line 1239, in __init__
    self.fp = io.open(file, filemode)
PermissionError: [Errno 13] Permission denied: 'Price_Puller.xlsx'
2025-04-28 13:16:57,384 - ERROR - \U0001f6a8 Error processing Q5: [Errno 13] Permission denied: 'Price_Puller.xlsx'
Traceback (most recent call last):
  File "C:\Users\derek\Dropbox (Personal)\Cars\Price Puller Used Cars\Price_Puller.py", line 135, in get_avg_price
    wb.save(output_file)
  File "C:\Users\derek\AppData\Local\Programs\Python\Python39\lib\site-packages\openpyxl\workbook\workbook.py", line 386, in save
    save_workbook(self, filename)
  File "C:\Users\derek\AppData\Local\Programs\Python\Python39\lib\site-packages\openpyxl\writer\excel.py", line 291, in save_workbook
    archive = ZipFile(filename, 'w', ZIP_DEFLATED, allowZip64=True)
  File "C:\Users\derek\AppData\Local\Programs\Python\Python39\lib\zipfile.py", line 1239, in __init__
    self.fp = io.open(file, filemode)
PermissionError: [Errno 13] Permission denied: 'Price_Puller.xlsx'
2025-04-28 13:16:57,738 - ERROR - \U0001f6a8 Error processing RS7: [Errno 13] Permission denied: 'Price_Puller.xlsx'
Traceback (most recent call last):
  File "C:\Users\derek\Dropbox (Personal)\Cars\Price Puller Used Cars\Price_Puller.py", line 135, in get_avg_price
    wb.save(output_file)
  File "C:\Users\derek\AppData\Local\Programs\Python\Python39\lib\site-packages\openpyxl\workbook\workbook.py", line 386, in save
    save_workbook(self, filename)
  File "C:\Users\derek\AppData\Local\Programs\Python\Python39\lib\site-packages\openpyxl\writer\excel.py", line 291, in save_workbook
    archive = ZipFile(filename, 'w', ZIP_DEFLATED, allowZip64=True)
  File "C:\Users\derek\AppData\Local\Programs\Python\Python39\lib\zipfile.py", line 1239, in __init__
    self.fp = io.open(file, filemode)
PermissionError: [Errno 13] Permission denied: 'Price_Puller.xlsx'
2025-04-28 13:16:58,036 - ERROR - \U0001f6a8 Error processing Etron: [Errno 13] Permission denied: 'Price_Puller.xlsx'
Traceback (most recent call last):
  File "C:\Users\derek\Dropbox (Personal)\Cars\Price Puller Used Cars\Price_Puller.py", line 135, in get_avg_price
    wb.save(output_file)
  File "C:\Users\derek\AppData\Local\Programs\Python\Python39\lib\site-packages\openpyxl\workbook\workbook.py", line 386, in save
    save_workbook(self, filename)
  File "C:\Users\derek\AppData\Local\Programs\Python\Python39\lib\site-packages\openpyxl\writer\excel.py", line 291, in save_workbook
    archive = ZipFile(filename, 'w', ZIP_DEFLATED, allowZip64=True)
  File "C:\Users\derek\AppData\Local\Programs\Python\Python39\lib\zipfile.py", line 1239, in __init__
    self.fp = io.open(file, filemode)
PermissionError: [Errno 13] Permission denied: 'Price_Puller.xlsx'
2025-04-28 13:16:58,414 - ERROR - \U0001f6a8 Error processing M3: [Errno 13] Permission denied: 'Price_Puller.xlsx'
Traceback (most recent call last):
  File "C:\Users\derek\Dropbox (Personal)\Cars\Price Puller Used Cars\Price_Puller.py", line 135, in get_avg_price
    wb.save(output_file)
  File "C:\Users\derek\AppData\Local\Programs\Python\Python39\lib\site-packages\openpyxl\workbook\workbook.py", line 386, in save
    save_workbook(self, filename)
  File "C:\Users\derek\AppData\Local\Programs\Python\Python39\lib\site-packages\openpyxl\writer\excel.py", line 291, in save_workbook
    archive = ZipFile(filename, 'w', ZIP_DEFLATED, allowZip64=True)
  File "C:\Users\derek\AppData\Local\Programs\Python\Python39\lib\zipfile.py", line 1239, in __init__
    self.fp = io.open(file, filemode)
PermissionError: [Errno 13] Permission denied: 'Price_Puller.xlsx'
2025-04-28 13:16:58,877 - ERROR - \U0001f6a8 Error processing M5: [Errno 13] Permission denied: 'Price_Puller.xlsx'
Traceback (most recent call last):
  File "C:\Users\derek\Dropbox (Personal)\Cars\Price Puller Used Cars\Price_Puller.py", line 135, in get_avg_price
    wb.save(output_file)
  File "C:\Users\derek\AppData\Local\Programs\Python\Python39\lib\site-packages\openpyxl\workbook\workbook.py", line 386, in save
    save_workbook(self, filename)
  File "C:\Users\derek\AppData\Local\Programs\Python\Python39\lib\site-packages\openpyxl\writer\excel.py", line 291, in save_workbook
    archive = ZipFile(filename, 'w', ZIP_DEFLATED, allowZip64=True)
  File "C:\Users\derek\AppData\Local\Programs\Python\Python39\lib\zipfile.py", line 1239, in __init__
    self.fp = io.open(file, filemode)
PermissionError: [Errno 13] Permission denied: 'Price_Puller.xlsx'
2025-04-28 13:16:59,278 - ERROR - \U0001f6a8 Error processing Corvette Z06: [Errno 13] Permission denied: 'Price_Puller.xlsx'
Traceback (most recent call last):
  File "C:\Users\derek\Dropbox (Personal)\Cars\Price Puller Used Cars\Price_Puller.py", line 135, in get_avg_price
    wb.save(output_file)
  File "C:\Users\derek\AppData\Local\Programs\Python\Python39\lib\site-packages\openpyxl\workbook\workbook.py", line 386, in save
    save_workbook(self, filename)
  File "C:\Users\derek\AppData\Local\Programs\Python\Python39\lib\site-packages\openpyxl\writer\excel.py", line 291, in save_workbook
    archive = ZipFile(filename, 'w', ZIP_DEFLATED, allowZip64=True)
  File "C:\Users\derek\AppData\Local\Programs\Python\Python39\lib\zipfile.py", line 1239, in __init__
    self.fp = io.open(file, filemode)
PermissionError: [Errno 13] Permission denied: 'Price_Puller.xlsx'
2025-04-28 13:16:59,584 - ERROR - \U0001f6a8 Error processing Corvette ZR1: [Errno 13] Permission denied: 'Price_Puller.xlsx'
Traceback (most recent call last):
  File "C:\Users\derek\Dropbox (Personal)\Cars\Price Puller Used Cars\Price_Puller.py", line 135, in get_avg_price
    wb.save(output_file)
  File "C:\Users\derek\AppData\Local\Programs\Python\Python39\lib\site-packages\openpyxl\workbook\workbook.py", line 386, in save
    save_workbook(self, filename)
  File "C:\Users\derek\AppData\Local\Programs\Python\Python39\lib\site-packages\openpyxl\writer\excel.py", line 291, in save_workbook
    archive = ZipFile(filename, 'w', ZIP_DEFLATED, allowZip64=True)
  File "C:\Users\derek\AppData\Local\Programs\Python\Python39\lib\zipfile.py", line 1239, in __init__
    self.fp = io.open(file, filemode)
PermissionError: [Errno 13] Permission denied: 'Price_Puller.xlsx'
2025-04-28 13:16:59,896 - ERROR - \U0001f6a8 Error processing 458 Italia: [Errno 13] Permission denied: 'Price_Puller.xlsx'
Traceback (most recent call last):
  File "C:\Users\derek\Dropbox (Personal)\Cars\Price Puller Used Cars\Price_Puller.py", line 135, in get_avg_price
    wb.save(output_file)
  File "C:\Users\derek\AppData\Local\Programs\Python\Python39\lib\site-packages\openpyxl\workbook\workbook.py", line 386, in save
    save_workbook(self, filename)
  File "C:\Users\derek\AppData\Local\Programs\Python\Python39\lib\site-packages\openpyxl\writer\excel.py", line 291, in save_workbook
    archive = ZipFile(filename, 'w', ZIP_DEFLATED, allowZip64=True)
  File "C:\Users\derek\AppData\Local\Programs\Python\Python39\lib\zipfile.py", line 1239, in __init__
    self.fp = io.open(file, filemode)
PermissionError: [Errno 13] Permission denied: 'Price_Puller.xlsx'
2025-04-28 13:17:00,342 - ERROR - \U0001f6a8 Error processing F250: [Errno 13] Permission denied: 'Price_Puller.xlsx'
Traceback (most recent call last):
  File "C:\Users\derek\Dropbox (Personal)\Cars\Price Puller Used Cars\Price_Puller.py", line 135, in get_avg_price
    wb.save(output_file)
  File "C:\Users\derek\AppData\Local\Programs\Python\Python39\lib\site-packages\openpyxl\workbook\workbook.py", line 386, in save
    save_workbook(self, filename)
  File "C:\Users\derek\AppData\Local\Programs\Python\Python39\lib\site-packages\openpyxl\writer\excel.py", line 291, in save_workbook
    archive = ZipFile(filename, 'w', ZIP_DEFLATED, allowZip64=True)
  File "C:\Users\derek\AppData\Local\Programs\Python\Python39\lib\zipfile.py", line 1239, in __init__
    self.fp = io.open(file, filemode)
PermissionError: [Errno 13] Permission denied: 'Price_Puller.xlsx'
2025-04-28 13:17:00,664 - ERROR - \U0001f6a8 Error processing GT: [Errno 13] Permission denied: 'Price_Puller.xlsx'
Traceback (most recent call last):
  File "C:\Users\derek\Dropbox (Personal)\Cars\Price Puller Used Cars\Price_Puller.py", line 135, in get_avg_price
    wb.save(output_file)
  File "C:\Users\derek\AppData\Local\Programs\Python\Python39\lib\site-packages\openpyxl\workbook\workbook.py", line 386, in save
    save_workbook(self, filename)
  File "C:\Users\derek\AppData\Local\Programs\Python\Python39\lib\site-packages\openpyxl\writer\excel.py", line 291, in save_workbook
    archive = ZipFile(filename, 'w', ZIP_DEFLATED, allowZip64=True)
  File "C:\Users\derek\AppData\Local\Programs\Python\Python39\lib\zipfile.py", line 1239, in __init__
    self.fp = io.open(file, filemode)
PermissionError: [Errno 13] Permission denied: 'Price_Puller.xlsx'
2025-04-28 13:17:01,008 - ERROR - \U0001f6a8 Error processing Accord: [Errno 13] Permission denied: 'Price_Puller.xlsx'
Traceback (most recent call last):
  File "C:\Users\derek\Dropbox (Personal)\Cars\Price Puller Used Cars\Price_Puller.py", line 135, in get_avg_price
    wb.save(output_file)
  File "C:\Users\derek\AppData\Local\Programs\Python\Python39\lib\site-packages\openpyxl\workbook\workbook.py", line 386, in save
    save_workbook(self, filename)
  File "C:\Users\derek\AppData\Local\Programs\Python\Python39\lib\site-packages\openpyxl\writer\excel.py", line 291, in save_workbook
    archive = ZipFile(filename, 'w', ZIP_DEFLATED, allowZip64=True)
  File "C:\Users\derek\AppData\Local\Programs\Python\Python39\lib\zipfile.py", line 1239, in __init__
    self.fp = io.open(file, filemode)
PermissionError: [Errno 13] Permission denied: 'Price_Puller.xlsx'
2025-04-28 13:17:01,296 - ERROR - \U0001f6a8 Error processing S2000: [Errno 13] Permission denied: 'Price_Puller.xlsx'
Traceback (most recent call last):
  File "C:\Users\derek\Dropbox (Personal)\Cars\Price Puller Used Cars\Price_Puller.py", line 135, in get_avg_price
    wb.save(output_file)
  File "C:\Users\derek\AppData\Local\Programs\Python\Python39\lib\site-packages\openpyxl\workbook\workbook.py", line 386, in save
    save_workbook(self, filename)
  File "C:\Users\derek\AppData\Local\Programs\Python\Python39\lib\site-packages\openpyxl\writer\excel.py", line 291, in save_workbook
    archive = ZipFile(filename, 'w', ZIP_DEFLATED, allowZip64=True)
  File "C:\Users\derek\AppData\Local\Programs\Python\Python39\lib\zipfile.py", line 1239, in __init__
    self.fp = io.open(file, filemode)
PermissionError: [Errno 13] Permission denied: 'Price_Puller.xlsx'
2025-04-28 13:17:01,617 - ERROR - \U0001f6a8 Error processing Wrangler: [Errno 13] Permission denied: 'Price_Puller.xlsx'
Traceback (most recent call last):
  File "C:\Users\derek\Dropbox (Personal)\Cars\Price Puller Used Cars\Price_Puller.py", line 135, in get_avg_price
    wb.save(output_file)
  File "C:\Users\derek\AppData\Local\Programs\Python\Python39\lib\site-packages\openpyxl\workbook\workbook.py", line 386, in save
    save_workbook(self, filename)
  File "C:\Users\derek\AppData\Local\Programs\Python\Python39\lib\site-packages\openpyxl\writer\excel.py", line 291, in save_workbook
    archive = ZipFile(filename, 'w', ZIP_DEFLATED, allowZip64=True)
  File "C:\Users\derek\AppData\Local\Programs\Python\Python39\lib\zipfile.py", line 1239, in __init__
    self.fp = io.open(file, filemode)
PermissionError: [Errno 13] Permission denied: 'Price_Puller.xlsx'
2025-04-28 13:17:01,945 - ERROR - \U0001f6a8 Error processing Aventador: [Errno 13] Permission denied: 'Price_Puller.xlsx'
Traceback (most recent call last):
  File "C:\Users\derek\Dropbox (Personal)\Cars\Price Puller Used Cars\Price_Puller.py", line 135, in get_avg_price
    wb.save(output_file)
  File "C:\Users\derek\AppData\Local\Programs\Python\Python39\lib\site-packages\openpyxl\workbook\workbook.py", line 386, in save
    save_workbook(self, filename)
  File "C:\Users\derek\AppData\Local\Programs\Python\Python39\lib\site-packages\openpyxl\writer\excel.py", line 291, in save_workbook
    archive = ZipFile(filename, 'w', ZIP_DEFLATED, allowZip64=True)
  File "C:\Users\derek\AppData\Local\Programs\Python\Python39\lib\zipfile.py", line 1239, in __init__
    self.fp = io.open(file, filemode)
PermissionError: [Errno 13] Permission denied: 'Price_Puller.xlsx'
2025-04-28 13:17:02,235 - ERROR - \U0001f6a8 Error processing Gallardo: [Errno 13] Permission denied: 'Price_Puller.xlsx'
Traceback (most recent call last):
  File "C:\Users\derek\Dropbox (Personal)\Cars\Price Puller Used Cars\Price_Puller.py", line 135, in get_avg_price
    wb.save(output_file)
  File "C:\Users\derek\AppData\Local\Programs\Python\Python39\lib\site-packages\openpyxl\workbook\workbook.py", line 386, in save
    save_workbook(self, filename)
  File "C:\Users\derek\AppData\Local\Programs\Python\Python39\lib\site-packages\openpyxl\writer\excel.py", line 291, in save_workbook
    archive = ZipFile(filename, 'w', ZIP_DEFLATED, allowZip64=True)
  File "C:\Users\derek\AppData\Local\Programs\Python\Python39\lib\zipfile.py", line 1239, in __init__
    self.fp = io.open(file, filemode)
PermissionError: [Errno 13] Permission denied: 'Price_Puller.xlsx'
2025-04-28 13:17:02,595 - ERROR - \U0001f6a8 Error processing Huracan: [Errno 13] Permission denied: 'Price_Puller.xlsx'
Traceback (most recent call last):
  File "C:\Users\derek\Dropbox (Personal)\Cars\Price Puller Used Cars\Price_Puller.py", line 135, in get_avg_price
    wb.save(output_file)
  File "C:\Users\derek\AppData\Local\Programs\Python\Python39\lib\site-packages\openpyxl\workbook\workbook.py", line 386, in save
    save_workbook(self, filename)
  File "C:\Users\derek\AppData\Local\Programs\Python\Python39\lib\site-packages\openpyxl\writer\excel.py", line 291, in save_workbook
    archive = ZipFile(filename, 'w', ZIP_DEFLATED, allowZip64=True)
  File "C:\Users\derek\AppData\Local\Programs\Python\Python39\lib\zipfile.py", line 1239, in __init__
    self.fp = io.open(file, filemode)
PermissionError: [Errno 13] Permission denied: 'Price_Puller.xlsx'
2025-04-28 13:17:02,837 - ERROR - \U0001f6a8 Error processing Murcielago: [Errno 13] Permission denied: 'Price_Puller.xlsx'
Traceback (most recent call last):
  File "C:\Users\derek\Dropbox (Personal)\Cars\Price Puller Used Cars\Price_Puller.py", line 135, in get_avg_price
    wb.save(output_file)
  File "C:\Users\derek\AppData\Local\Programs\Python\Python39\lib\site-packages\openpyxl\workbook\workbook.py", line 386, in save
    save_workbook(self, filename)
  File "C:\Users\derek\AppData\Local\Programs\Python\Python39\lib\site-packages\openpyxl\writer\excel.py", line 291, in save_workbook
    archive = ZipFile(filename, 'w', ZIP_DEFLATED, allowZip64=True)
  File "C:\Users\derek\AppData\Local\Programs\Python\Python39\lib\zipfile.py", line 1239, in __init__
    self.fp = io.open(file, filemode)
PermissionError: [Errno 13] Permission denied: 'Price_Puller.xlsx'
2025-04-28 13:17:03,119 - ERROR - \U0001f6a8 Error processing Urus: [Errno 13] Permission denied: 'Price_Puller.xlsx'
Traceback (most recent call last):
  File "C:\Users\derek\Dropbox (Personal)\Cars\Price Puller Used Cars\Price_Puller.py", line 135, in get_avg_price
    wb.save(output_file)
  File "C:\Users\derek\AppData\Local\Programs\Python\Python39\lib\site-packages\openpyxl\workbook\workbook.py", line 386, in save
    save_workbook(self, filename)
  File "C:\Users\derek\AppData\Local\Programs\Python\Python39\lib\site-packages\openpyxl\writer\excel.py", line 291, in save_workbook
    archive = ZipFile(filename, 'w', ZIP_DEFLATED, allowZip64=True)
  File "C:\Users\derek\AppData\Local\Programs\Python\Python39\lib\zipfile.py", line 1239, in __init__
    self.fp = io.open(file, filemode)
PermissionError: [Errno 13] Permission denied: 'Price_Puller.xlsx'
2025-04-28 13:17:03,432 - ERROR - \U0001f6a8 Error processing AMG: [Errno 13] Permission denied: 'Price_Puller.xlsx'
Traceback (most recent call last):
  File "C:\Users\derek\Dropbox (Personal)\Cars\Price Puller Used Cars\Price_Puller.py", line 135, in get_avg_price
    wb.save(output_file)
  File "C:\Users\derek\AppData\Local\Programs\Python\Python39\lib\site-packages\openpyxl\workbook\workbook.py", line 386, in save
    save_workbook(self, filename)
  File "C:\Users\derek\AppData\Local\Programs\Python\Python39\lib\site-packages\openpyxl\writer\excel.py", line 291, in save_workbook
    archive = ZipFile(filename, 'w', ZIP_DEFLATED, allowZip64=True)
  File "C:\Users\derek\AppData\Local\Programs\Python\Python39\lib\zipfile.py", line 1239, in __init__
    self.fp = io.open(file, filemode)
PermissionError: [Errno 13] Permission denied: 'Price_Puller.xlsx'
2025-04-28 13:17:03,744 - ERROR - \U0001f6a8 Error processing C63 AMG: [Errno 13] Permission denied: 'Price_Puller.xlsx'
Traceback (most recent call last):
  File "C:\Users\derek\Dropbox (Personal)\Cars\Price Puller Used Cars\Price_Puller.py", line 135, in get_avg_price
    wb.save(output_file)
  File "C:\Users\derek\AppData\Local\Programs\Python\Python39\lib\site-packages\openpyxl\workbook\workbook.py", line 386, in save
    save_workbook(self, filename)
  File "C:\Users\derek\AppData\Local\Programs\Python\Python39\lib\site-packages\openpyxl\writer\excel.py", line 291, in save_workbook
    archive = ZipFile(filename, 'w', ZIP_DEFLATED, allowZip64=True)
  File "C:\Users\derek\AppData\Local\Programs\Python\Python39\lib\zipfile.py", line 1239, in __init__
    self.fp = io.open(file, filemode)
PermissionError: [Errno 13] Permission denied: 'Price_Puller.xlsx'
2025-04-28 13:17:04,072 - ERROR - \U0001f6a8 Error processing Carrera S: [Errno 13] Permission denied: 'Price_Puller.xlsx'
Traceback (most recent call last):
  File "C:\Users\derek\Dropbox (Personal)\Cars\Price Puller Used Cars\Price_Puller.py", line 135, in get_avg_price
    wb.save(output_file)
  File "C:\Users\derek\AppData\Local\Programs\Python\Python39\lib\site-packages\openpyxl\workbook\workbook.py", line 386, in save
    save_workbook(self, filename)
  File "C:\Users\derek\AppData\Local\Programs\Python\Python39\lib\site-packages\openpyxl\writer\excel.py", line 291, in save_workbook
    archive = ZipFile(filename, 'w', ZIP_DEFLATED, allowZip64=True)
  File "C:\Users\derek\AppData\Local\Programs\Python\Python39\lib\zipfile.py", line 1239, in __init__
    self.fp = io.open(file, filemode)
PermissionError: [Errno 13] Permission denied: 'Price_Puller.xlsx'
2025-04-28 13:17:04,417 - ERROR - \U0001f6a8 Error processing GT3: [Errno 13] Permission denied: 'Price_Puller.xlsx'
Traceback (most recent call last):
  File "C:\Users\derek\Dropbox (Personal)\Cars\Price Puller Used Cars\Price_Puller.py", line 135, in get_avg_price
    wb.save(output_file)
  File "C:\Users\derek\AppData\Local\Programs\Python\Python39\lib\site-packages\openpyxl\workbook\workbook.py", line 386, in save
    save_workbook(self, filename)
  File "C:\Users\derek\AppData\Local\Programs\Python\Python39\lib\site-packages\openpyxl\writer\excel.py", line 291, in save_workbook
    archive = ZipFile(filename, 'w', ZIP_DEFLATED, allowZip64=True)
  File "C:\Users\derek\AppData\Local\Programs\Python\Python39\lib\zipfile.py", line 1239, in __init__
    self.fp = io.open(file, filemode)
PermissionError: [Errno 13] Permission denied: 'Price_Puller.xlsx'
2025-04-28 13:17:04,682 - ERROR - \U0001f6a8 Error processing GT3RS: [Errno 13] Permission denied: 'Price_Puller.xlsx'
Traceback (most recent call last):
  File "C:\Users\derek\Dropbox (Personal)\Cars\Price Puller Used Cars\Price_Puller.py", line 135, in get_avg_price
    wb.save(output_file)
  File "C:\Users\derek\AppData\Local\Programs\Python\Python39\lib\site-packages\openpyxl\workbook\workbook.py", line 386, in save
    save_workbook(self, filename)
  File "C:\Users\derek\AppData\Local\Programs\Python\Python39\lib\site-packages\openpyxl\writer\excel.py", line 291, in save_workbook
    archive = ZipFile(filename, 'w', ZIP_DEFLATED, allowZip64=True)
  File "C:\Users\derek\AppData\Local\Programs\Python\Python39\lib\zipfile.py", line 1239, in __init__
    self.fp = io.open(file, filemode)
PermissionError: [Errno 13] Permission denied: 'Price_Puller.xlsx'
2025-04-28 13:17:04,979 - ERROR - \U0001f6a8 Error processing GT4: [Errno 13] Permission denied: 'Price_Puller.xlsx'
Traceback (most recent call last):
  File "C:\Users\derek\Dropbox (Personal)\Cars\Price Puller Used Cars\Price_Puller.py", line 135, in get_avg_price
    wb.save(output_file)
  File "C:\Users\derek\AppData\Local\Programs\Python\Python39\lib\site-packages\openpyxl\workbook\workbook.py", line 386, in save
    save_workbook(self, filename)
  File "C:\Users\derek\AppData\Local\Programs\Python\Python39\lib\site-packages\openpyxl\writer\excel.py", line 291, in save_workbook
    archive = ZipFile(filename, 'w', ZIP_DEFLATED, allowZip64=True)
  File "C:\Users\derek\AppData\Local\Programs\Python\Python39\lib\zipfile.py", line 1239, in __init__
    self.fp = io.open(file, filemode)
PermissionError: [Errno 13] Permission denied: 'Price_Puller.xlsx'
2025-04-28 13:17:05,246 - ERROR - \U0001f6a8 Error processing GT4RS: [Errno 13] Permission denied: 'Price_Puller.xlsx'
Traceback (most recent call last):
  File "C:\Users\derek\Dropbox (Personal)\Cars\Price Puller Used Cars\Price_Puller.py", line 135, in get_avg_price
    wb.save(output_file)
  File "C:\Users\derek\AppData\Local\Programs\Python\Python39\lib\site-packages\openpyxl\workbook\workbook.py", line 386, in save
    save_workbook(self, filename)
  File "C:\Users\derek\AppData\Local\Programs\Python\Python39\lib\site-packages\openpyxl\writer\excel.py", line 291, in save_workbook
    archive = ZipFile(filename, 'w', ZIP_DEFLATED, allowZip64=True)
  File "C:\Users\derek\AppData\Local\Programs\Python\Python39\lib\zipfile.py", line 1239, in __init__
    self.fp = io.open(file, filemode)
PermissionError: [Errno 13] Permission denied: 'Price_Puller.xlsx'
2025-04-28 13:17:05,605 - ERROR - \U0001f6a8 Error processing Cayenne: [Errno 13] Permission denied: 'Price_Puller.xlsx'
Traceback (most recent call last):
  File "C:\Users\derek\Dropbox (Personal)\Cars\Price Puller Used Cars\Price_Puller.py", line 135, in get_avg_price
    wb.save(output_file)
  File "C:\Users\derek\AppData\Local\Programs\Python\Python39\lib\site-packages\openpyxl\workbook\workbook.py", line 386, in save
    save_workbook(self, filename)
  File "C:\Users\derek\AppData\Local\Programs\Python\Python39\lib\site-packages\openpyxl\writer\excel.py", line 291, in save_workbook
    archive = ZipFile(filename, 'w', ZIP_DEFLATED, allowZip64=True)
  File "C:\Users\derek\AppData\Local\Programs\Python\Python39\lib\zipfile.py", line 1239, in __init__
    self.fp = io.open(file, filemode)
PermissionError: [Errno 13] Permission denied: 'Price_Puller.xlsx'
2025-04-28 13:17:05,919 - ERROR - \U0001f6a8 Error processing Macan: [Errno 13] Permission denied: 'Price_Puller.xlsx'
Traceback (most recent call last):
  File "C:\Users\derek\Dropbox (Personal)\Cars\Price Puller Used Cars\Price_Puller.py", line 135, in get_avg_price
    wb.save(output_file)
  File "C:\Users\derek\AppData\Local\Programs\Python\Python39\lib\site-packages\openpyxl\workbook\workbook.py", line 386, in save
    save_workbook(self, filename)
  File "C:\Users\derek\AppData\Local\Programs\Python\Python39\lib\site-packages\openpyxl\writer\excel.py", line 291, in save_workbook
    archive = ZipFile(filename, 'w', ZIP_DEFLATED, allowZip64=True)
  File "C:\Users\derek\AppData\Local\Programs\Python\Python39\lib\zipfile.py", line 1239, in __init__
    self.fp = io.open(file, filemode)
PermissionError: [Errno 13] Permission denied: 'Price_Puller.xlsx'
2025-04-28 13:17:06,216 - ERROR - \U0001f6a8 Error processing Taycan: [Errno 13] Permission denied: 'Price_Puller.xlsx'
Traceback (most recent call last):
  File "C:\Users\derek\Dropbox (Personal)\Cars\Price Puller Used Cars\Price_Puller.py", line 135, in get_avg_price
    wb.save(output_file)
  File "C:\Users\derek\AppData\Local\Programs\Python\Python39\lib\site-packages\openpyxl\workbook\workbook.py", line 386, in save
    save_workbook(self, filename)
  File "C:\Users\derek\AppData\Local\Programs\Python\Python39\lib\site-packages\openpyxl\writer\excel.py", line 291, in save_workbook
    archive = ZipFile(filename, 'w', ZIP_DEFLATED, allowZip64=True)
  File "C:\Users\derek\AppData\Local\Programs\Python\Python39\lib\zipfile.py", line 1239, in __init__
    self.fp = io.open(file, filemode)
PermissionError: [Errno 13] Permission denied: 'Price_Puller.xlsx'
2025-04-28 13:17:06,466 - ERROR - \U0001f6a8 Error processing BRZ: [Errno 13] Permission denied: 'Price_Puller.xlsx'
Traceback (most recent call last):
  File "C:\Users\derek\Dropbox (Personal)\Cars\Price Puller Used Cars\Price_Puller.py", line 135, in get_avg_price
    wb.save(output_file)
  File "C:\Users\derek\AppData\Local\Programs\Python\Python39\lib\site-packages\openpyxl\workbook\workbook.py", line 386, in save
    save_workbook(self, filename)
  File "C:\Users\derek\AppData\Local\Programs\Python\Python39\lib\site-packages\openpyxl\writer\excel.py", line 291, in save_workbook
    archive = ZipFile(filename, 'w', ZIP_DEFLATED, allowZip64=True)
  File "C:\Users\derek\AppData\Local\Programs\Python\Python39\lib\zipfile.py", line 1239, in __init__
    self.fp = io.open(file, filemode)
PermissionError: [Errno 13] Permission denied: 'Price_Puller.xlsx'
2025-04-28 13:17:06,810 - ERROR - \U0001f6a8 Error processing CyberTruck: [Errno 13] Permission denied: 'Price_Puller.xlsx'
Traceback (most recent call last):
  File "C:\Users\derek\Dropbox (Personal)\Cars\Price Puller Used Cars\Price_Puller.py", line 135, in get_avg_price
    wb.save(output_file)
  File "C:\Users\derek\AppData\Local\Programs\Python\Python39\lib\site-packages\openpyxl\workbook\workbook.py", line 386, in save
    save_workbook(self, filename)
  File "C:\Users\derek\AppData\Local\Programs\Python\Python39\lib\site-packages\openpyxl\writer\excel.py", line 291, in save_workbook
    archive = ZipFile(filename, 'w', ZIP_DEFLATED, allowZip64=True)
  File "C:\Users\derek\AppData\Local\Programs\Python\Python39\lib\zipfile.py", line 1239, in __init__
    self.fp = io.open(file, filemode)
PermissionError: [Errno 13] Permission denied: 'Price_Puller.xlsx'
2025-04-28 13:17:07,107 - ERROR - \U0001f6a8 Error processing Model 3: [Errno 13] Permission denied: 'Price_Puller.xlsx'
Traceback (most recent call last):
  File "C:\Users\derek\Dropbox (Personal)\Cars\Price Puller Used Cars\Price_Puller.py", line 135, in get_avg_price
    wb.save(output_file)
  File "C:\Users\derek\AppData\Local\Programs\Python\Python39\lib\site-packages\openpyxl\workbook\workbook.py", line 386, in save
    save_workbook(self, filename)
  File "C:\Users\derek\AppData\Local\Programs\Python\Python39\lib\site-packages\openpyxl\writer\excel.py", line 291, in save_workbook
    archive = ZipFile(filename, 'w', ZIP_DEFLATED, allowZip64=True)
  File "C:\Users\derek\AppData\Local\Programs\Python\Python39\lib\zipfile.py", line 1239, in __init__
    self.fp = io.open(file, filemode)
PermissionError: [Errno 13] Permission denied: 'Price_Puller.xlsx'
2025-04-28 13:17:07,443 - ERROR - \U0001f6a8 Error processing Model X: [Errno 13] Permission denied: 'Price_Puller.xlsx'
Traceback (most recent call last):
  File "C:\Users\derek\Dropbox (Personal)\Cars\Price Puller Used Cars\Price_Puller.py", line 135, in get_avg_price
    wb.save(output_file)
  File "C:\Users\derek\AppData\Local\Programs\Python\Python39\lib\site-packages\openpyxl\workbook\workbook.py", line 386, in save
    save_workbook(self, filename)
  File "C:\Users\derek\AppData\Local\Programs\Python\Python39\lib\site-packages\openpyxl\writer\excel.py", line 291, in save_workbook
    archive = ZipFile(filename, 'w', ZIP_DEFLATED, allowZip64=True)
  File "C:\Users\derek\AppData\Local\Programs\Python\Python39\lib\zipfile.py", line 1239, in __init__
    self.fp = io.open(file, filemode)
PermissionError: [Errno 13] Permission denied: 'Price_Puller.xlsx'
2025-04-28 13:17:07,709 - ERROR - \U0001f6a8 Error processing Model Y: [Errno 13] Permission denied: 'Price_Puller.xlsx'
Traceback (most recent call last):
  File "C:\Users\derek\Dropbox (Personal)\Cars\Price Puller Used Cars\Price_Puller.py", line 135, in get_avg_price
    wb.save(output_file)
  File "C:\Users\derek\AppData\Local\Programs\Python\Python39\lib\site-packages\openpyxl\workbook\workbook.py", line 386, in save
    save_workbook(self, filename)
  File "C:\Users\derek\AppData\Local\Programs\Python\Python39\lib\site-packages\openpyxl\writer\excel.py", line 291, in save_workbook
    archive = ZipFile(filename, 'w', ZIP_DEFLATED, allowZip64=True)
  File "C:\Users\derek\AppData\Local\Programs\Python\Python39\lib\zipfile.py", line 1239, in __init__
    self.fp = io.open(file, filemode)
PermissionError: [Errno 13] Permission denied: 'Price_Puller.xlsx'
2025-04-28 13:17:07,974 - ERROR - \U0001f6a8 Error processing Model S: [Errno 13] Permission denied: 'Price_Puller.xlsx'
Traceback (most recent call last):
  File "C:\Users\derek\Dropbox (Personal)\Cars\Price Puller Used Cars\Price_Puller.py", line 135, in get_avg_price
    wb.save(output_file)
  File "C:\Users\derek\AppData\Local\Programs\Python\Python39\lib\site-packages\openpyxl\workbook\workbook.py", line 386, in save
    save_workbook(self, filename)
  File "C:\Users\derek\AppData\Local\Programs\Python\Python39\lib\site-packages\openpyxl\writer\excel.py", line 291, in save_workbook
    archive = ZipFile(filename, 'w', ZIP_DEFLATED, allowZip64=True)
  File "C:\Users\derek\AppData\Local\Programs\Python\Python39\lib\zipfile.py", line 1239, in __init__
    self.fp = io.open(file, filemode)
PermissionError: [Errno 13] Permission denied: 'Price_Puller.xlsx'
2025-04-28 13:17:08,297 - ERROR - \U0001f6a8 Error processing RAV4: [Errno 13] Permission denied: 'Price_Puller.xlsx'
Traceback (most recent call last):
  File "C:\Users\derek\Dropbox (Personal)\Cars\Price Puller Used Cars\Price_Puller.py", line 135, in get_avg_price
    wb.save(output_file)
  File "C:\Users\derek\AppData\Local\Programs\Python\Python39\lib\site-packages\openpyxl\workbook\workbook.py", line 386, in save
    save_workbook(self, filename)
  File "C:\Users\derek\AppData\Local\Programs\Python\Python39\lib\site-packages\openpyxl\writer\excel.py", line 291, in save_workbook
    archive = ZipFile(filename, 'w', ZIP_DEFLATED, allowZip64=True)
  File "C:\Users\derek\AppData\Local\Programs\Python\Python39\lib\zipfile.py", line 1239, in __init__
    self.fp = io.open(file, filemode)
PermissionError: [Errno 13] Permission denied: 'Price_Puller.xlsx'
2025-04-28 13:18:22,399 - INFO - \u2705 Loaded 38 URLs from car_urls.txt
2025-04-28 13:18:23,140 - INFO - \u2705 Successfully updated sheet 'R8' for 28APR2025
2025-04-28 13:18:23,846 - INFO - \u2705 Successfully updated sheet 'RS4' for 28APR2025
2025-04-28 13:18:24,609 - INFO - \u2705 Successfully updated sheet 'S4' for 28APR2025
2025-04-28 13:18:25,242 - INFO - \u2705 Successfully updated sheet 'Q5' for 28APR2025
2025-04-28 13:18:25,950 - INFO - \u2705 Successfully updated sheet 'RS7' for 28APR2025
2025-04-28 13:18:26,702 - INFO - \u2705 Successfully updated sheet 'Etron' for 28APR2025
2025-04-28 13:18:27,450 - INFO - \u2705 Successfully updated sheet 'M3' for 28APR2025
2025-04-28 13:18:28,169 - INFO - \u2705 Successfully updated sheet 'M5' for 28APR2025
2025-04-28 13:18:28,867 - INFO - \u2705 Successfully updated sheet 'Corvette Z06' for 28APR2025
2025-04-28 13:18:29,553 - INFO - \u2705 Successfully updated sheet 'Corvette ZR1' for 28APR2025
2025-04-28 13:18:30,340 - INFO - \u2705 Successfully updated sheet '458 Italia' for 28APR2025
2025-04-28 13:18:31,093 - INFO - \u2705 Successfully updated sheet 'F250' for 28APR2025
2025-04-28 13:18:31,772 - INFO - \u2705 Successfully updated sheet 'GT' for 28APR2025
2025-04-28 13:18:32,519 - INFO - \u2705 Successfully updated sheet 'Accord' for 28APR2025
2025-04-28 13:18:33,225 - INFO - \u2705 Successfully updated sheet 'S2000' for 28APR2025
2025-04-28 13:18:34,123 - INFO - \u2705 Successfully updated sheet 'Wrangler' for 28APR2025
2025-04-28 13:18:35,196 - INFO - \u2705 Successfully updated sheet 'Aventador' for 28APR2025
2025-04-28 13:18:36,141 - INFO - \u2705 Successfully updated sheet 'Gallardo' for 28APR2025
2025-04-28 13:18:37,278 - INFO - \u2705 Successfully updated sheet 'Huracan' for 28APR2025
2025-04-28 13:18:38,459 - INFO - \u2705 Successfully updated sheet 'Murcielago' for 28APR2025
2025-04-28 13:18:39,473 - INFO - \u2705 Successfully updated sheet 'Urus' for 28APR2025
2025-04-28 13:18:40,464 - INFO - \u2705 Successfully updated sheet 'AMG' for 28APR2025
2025-04-28 13:18:41,284 - INFO - \u2705 Successfully updated sheet 'C63 AMG' for 28APR2025
2025-04-28 13:18:42,025 - INFO - \u2705 Successfully updated sheet 'Carrera S' for 28APR2025
2025-04-28 13:18:42,768 - INFO - \u2705 Successfully updated sheet 'GT3' for 28APR2025
2025-04-28 13:18:43,455 - INFO - \u2705 Successfully updated sheet 'GT3RS' for 28APR2025
2025-04-28 13:18:44,100 - INFO - \u2705 Successfully updated sheet 'GT4' for 28APR2025
2025-04-28 13:18:45,003 - INFO - \u2705 Successfully updated sheet 'GT4RS' for 28APR2025
2025-04-28 13:18:45,895 - INFO - \u2705 Successfully updated sheet 'Cayenne' for 28APR2025
2025-04-28 13:18:46,566 - INFO - \u2705 Successfully updated sheet 'Macan' for 28APR2025
2025-04-28 13:18:47,255 - INFO - \u2705 Successfully updated sheet 'Taycan' for 28APR2025
2025-04-28 13:18:47,883 - INFO - \u2705 Successfully updated sheet 'BRZ' for 28APR2025
2025-04-28 13:18:48,576 - INFO - \u2705 Successfully updated sheet 'CyberTruck' for 28APR2025
2025-04-28 13:18:49,295 - INFO - \u2705 Successfully updated sheet 'Model 3' for 28APR2025
2025-04-28 13:18:49,973 - INFO - \u2705 Successfully updated sheet 'Model X' for 28APR2025
2025-04-28 13:18:50,658 - INFO - \u2705 Successfully updated sheet 'Model Y' for 28APR2025
2025-04-28 13:18:51,341 - INFO - \u2705 Successfully updated sheet 'Model S' for 28APR2025
2025-04-28 13:18:52,040 - INFO - \u2705 Successfully updated sheet 'RAV4' for 28APR2025
2025-04-28 13:20:33,229 - INFO - \u2705 Loaded 39 URLs from car_urls.txt
2025-04-28 13:20:33,893 - INFO - \u2705 Successfully updated sheet 'R8' for 28APR2025
2025-04-28 13:20:34,525 - INFO - \u2705 Successfully updated sheet 'RS4' for 28APR2025
2025-04-28 13:20:35,283 - INFO - \u2705 Successfully updated sheet 'S4' for 28APR2025
2025-04-28 13:20:35,926 - INFO - \u2705 Successfully updated sheet 'Q5' for 28APR2025
2025-04-28 13:20:36,549 - INFO - \u2705 Successfully updated sheet 'RS7' for 28APR2025
2025-04-28 13:20:37,212 - INFO - \u2705 Successfully updated sheet 'Etron' for 28APR2025
2025-04-28 13:20:37,853 - INFO - \u2705 Successfully updated sheet 'M3' for 28APR2025
2025-04-28 13:20:38,610 - INFO - \u2705 Successfully updated sheet 'M5' for 28APR2025
2025-04-28 13:20:39,259 - INFO - \u2705 Successfully updated sheet 'Corvette Z06' for 28APR2025
2025-04-28 13:20:39,878 - INFO - \u2705 Successfully updated sheet 'Corvette ZR1' for 28APR2025
2025-04-28 13:20:40,557 - INFO - \u2705 Successfully updated sheet 'Charger' for 28APR2025
2025-04-28 13:20:41,203 - INFO - \u2705 Successfully updated sheet '458 Italia' for 28APR2025
2025-04-28 13:20:41,889 - INFO - \u2705 Successfully updated sheet 'F250' for 28APR2025
2025-04-28 13:20:42,630 - INFO - \u2705 Successfully updated sheet 'GT' for 28APR2025
2025-04-28 13:20:43,299 - INFO - \u2705 Successfully updated sheet 'Accord' for 28APR2025
2025-04-28 13:20:43,948 - INFO - \u2705 Successfully updated sheet 'S2000' for 28APR2025
2025-04-28 13:20:44,624 - INFO - \u2705 Successfully updated sheet 'Wrangler' for 28APR2025
2025-04-28 13:20:45,288 - INFO - \u2705 Successfully updated sheet 'Aventador' for 28APR2025
2025-04-28 13:20:45,903 - INFO - \u2705 Successfully updated sheet 'Gallardo' for 28APR2025
2025-04-28 13:20:46,576 - INFO - \u2705 Successfully updated sheet 'Huracan' for 28APR2025
2025-04-28 13:20:47,193 - INFO - \u2705 Successfully updated sheet 'Murcielago' for 28APR2025
2025-04-28 13:20:47,923 - INFO - \u2705 Successfully updated sheet 'Urus' for 28APR2025
2025-04-28 13:20:48,605 - INFO - \u2705 Successfully updated sheet 'AMG' for 28APR2025
2025-04-28 13:20:49,265 - INFO - \u2705 Successfully updated sheet 'C63 AMG' for 28APR2025
2025-04-28 13:20:49,955 - INFO - \u2705 Successfully updated sheet 'Carrera S' for 28APR2025
2025-04-28 13:20:50,625 - INFO - \u2705 Successfully updated sheet 'GT3' for 28APR2025
2025-04-28 13:20:51,260 - INFO - \u2705 Successfully updated sheet 'GT3RS' for 28APR2025
2025-04-28 13:20:51,928 - INFO - \u2705 Successfully updated sheet 'GT4' for 28APR2025
2025-04-28 13:20:52,574 - INFO - \u2705 Successfully updated sheet 'GT4RS' for 28APR2025
2025-04-28 13:20:53,230 - INFO - \u2705 Successfully updated sheet 'Cayenne' for 28APR2025
2025-04-28 13:20:53,958 - INFO - \u2705 Successfully updated sheet 'Macan' for 28APR2025
2025-04-28 13:20:54,632 - INFO - \u2705 Successfully updated sheet 'Taycan' for 28APR2025
2025-04-28 13:20:55,313 - INFO - \u2705 Successfully updated sheet 'BRZ' for 28APR2025
2025-04-28 13:20:55,993 - INFO - \u2705 Successfully updated sheet 'CyberTruck' for 28APR2025
2025-04-28 13:20:56,667 - INFO - \u2705 Successfully updated sheet 'Model 3' for 28APR2025
2025-04-28 13:20:57,320 - INFO - \u2705 Successfully updated sheet 'Model X' for 28APR2025
2025-04-28 13:20:57,987 - INFO - \u2705 Successfully updated sheet 'Model Y' for 28APR2025
2025-04-28 13:20:58,667 - INFO - \u2705 Successfully updated sheet 'Model S' for 28APR2025
2025-04-28 13:20:59,363 - INFO - \u2705 Successfully updated sheet 'RAV4' for 28APR2025
2025-04-28 13:26:41,859 - INFO - \u2705 Loaded 39 URLs from car_urls.txt
2025-04-28 13:26:42,646 - INFO - \u2705 Successfully updated sheet 'R8' for 28APR2025
2025-04-28 13:26:43,323 - INFO - \u2705 Successfully updated sheet 'RS4' for 28APR2025
2025-04-28 13:26:44,029 - INFO - \u2705 Successfully updated sheet 'S4' for 28APR2025
2025-04-28 13:26:44,748 - INFO - \u2705 Successfully updated sheet 'Q5' for 28APR2025
2025-04-28 13:26:45,434 - INFO - \u2705 Successfully updated sheet 'RS7' for 28APR2025
2025-04-28 13:26:46,115 - INFO - \u2705 Successfully updated sheet 'Etron' for 28APR2025
2025-04-28 13:26:46,828 - INFO - \u2705 Successfully updated sheet 'M3' for 28APR2025
2025-04-28 13:26:47,551 - INFO - \u2705 Successfully updated sheet 'M5' for 28APR2025
2025-04-28 13:26:48,277 - INFO - \u2705 Successfully updated sheet 'Corvette Z06' for 28APR2025
2025-04-28 13:26:49,109 - INFO - \u2705 Successfully updated sheet 'Corvette ZR1' for 28APR2025
2025-04-28 13:26:50,021 - INFO - \u2705 Successfully updated sheet 'Charger' for 28APR2025
2025-04-28 13:26:50,737 - INFO - \u2705 Successfully updated sheet '458 Italia' for 28APR2025
2025-04-28 13:26:51,493 - INFO - \u2705 Successfully updated sheet 'F250' for 28APR2025
2025-04-28 13:26:52,250 - INFO - \u2705 Successfully updated sheet 'GT' for 28APR2025
2025-04-28 13:26:53,047 - INFO - \u2705 Successfully updated sheet 'Accord' for 28APR2025
2025-04-28 13:26:53,754 - INFO - \u2705 Successfully updated sheet 'S2000' for 28APR2025
2025-04-28 13:26:54,527 - INFO - \u2705 Successfully updated sheet 'Wrangler' for 28APR2025
2025-04-28 13:26:55,229 - INFO - \u2705 Successfully updated sheet 'Aventador' for 28APR2025
2025-04-28 13:26:55,989 - INFO - \u2705 Successfully updated sheet 'Gallardo' for 28APR2025
2025-04-28 13:26:56,823 - INFO - \u2705 Successfully updated sheet 'Huracan' for 28APR2025
2025-04-28 13:26:57,692 - INFO - \u2705 Successfully updated sheet 'Murcielago' for 28APR2025
2025-04-28 13:26:58,467 - INFO - \u2705 Successfully updated sheet 'Urus' for 28APR2025
2025-04-28 13:26:59,193 - INFO - \u2705 Successfully updated sheet 'AMG' for 28APR2025
2025-04-28 13:26:59,870 - INFO - \u2705 Successfully updated sheet 'C63 AMG' for 28APR2025
2025-04-28 13:27:00,573 - INFO - \u2705 Successfully updated sheet 'Carrera S' for 28APR2025
2025-04-28 13:27:01,469 - INFO - \u2705 Successfully updated sheet 'GT3' for 28APR2025
2025-04-28 13:27:02,130 - INFO - \u2705 Successfully updated sheet 'GT3RS' for 28APR2025
2025-04-28 13:27:02,791 - INFO - \u2705 Successfully updated sheet 'GT4' for 28APR2025
2025-04-28 13:27:03,542 - INFO - \u2705 Successfully updated sheet 'GT4RS' for 28APR2025
2025-04-28 13:27:04,190 - INFO - \u2705 Successfully updated sheet 'Cayenne' for 28APR2025
2025-04-28 13:27:05,154 - INFO - \u2705 Successfully updated sheet 'Macan' for 28APR2025
2025-04-28 13:27:05,870 - INFO - \u2705 Successfully updated sheet 'Taycan' for 28APR2025
2025-04-28 13:27:06,620 - INFO - \u2705 Successfully updated sheet 'BRZ' for 28APR2025
2025-04-28 13:27:07,312 - INFO - \u2705 Successfully updated sheet 'CyberTruck' for 28APR2025
2025-04-28 13:27:08,085 - INFO - \u2705 Successfully updated sheet 'Model 3' for 28APR2025
2025-04-28 13:27:08,721 - INFO - \u2705 Successfully updated sheet 'Model X' for 28APR2025
2025-04-28 13:27:09,441 - INFO - \u2705 Successfully updated sheet 'Model Y' for 28APR2025
2025-04-28 13:27:10,208 - INFO - \u2705 Successfully updated sheet 'Model S' for 28APR2025
2025-04-28 13:27:10,955 - INFO - \u2705 Successfully updated sheet 'RAV4' for 28APR2025
